Workbook
Name LLP_Count: TransformData!$AO$3
Name TableRange: FinalData!$A$2:$U$60
Name Thrust_1: FinalData!$G$1
Name Thrust_2: FinalData!$J$1
Name Thrust_3: FinalData!$M$1
Name Thrust_4: FinalData!$P$1
Name Thrust_5: FinalData!$S$1
Name Total_No_Of_Thrust: TransformData!$AO$2

Sheet SFReportData

Sheet TransformData
A1: Unique Data | G1: Transpose Data Stage | J1: {=TRANSPOSE(D3:D7)} -> 0 | O1: {=TRANSPOSE(D3:D7)} -> 0 | T1: {=TRANSPOSE(D3:D7)} -> 0 | Y1: Final Formatted Data Stage | Z1: =J1 -> 0 | AC1: =K1 | AF1: =L1 | AI1: =M1 | AL1: =N1 | AO1: Total # Thrusts
A2: Component Description | B2: Part Number | C2: Serial Number | D2: Thrust Settings | E2: TSN | F2: CSN | H2: Module | I2: {=CELL("contents",A2)} -> Component Description | J2: Remaining Cycles | K2: Remaining Cycles | L2: Remaining Cycles | M2: Remaining Cycles | N2: Remaining Cycles | O2: Weighted Cycles Used | P2: Weighted Cycles Used | Q2: Weighted Cycles Used | R2: Weighted Cycles Used | S2: Weighted Cycles Used | T2: Cycles Limit | U2: Cycles Limit | V2: Cycles Limit | W2: Cycles Limit | X2: Cycles Limit | Z2: CSN | AA2: Total Life | AB2: Life Remaining | AC2: CSN | AD2: Total Life | AE2: Life Remaining | AF2: CSN | AG2: Total Life | AH2: Life Remaining | AI2: CSN | AJ2: Total Life | AK2: Life Remaining | AL2: CSN | AM2: Total Life | AN2: Life Remaining | AO2: =IF(OR((COUNTIF(D3:D20,">""")>5),(COUNTIF(D3:D20,">""")=0)), "LLP_Table",COUNTIF(D3:D20,">""")) -> LLP_Table
A3: {=IF(IFERROR(INDEX(SFReportData!$A$2:'SFReportData'!$A$500, MATCH(0, COUNTIF(TransformData!$A$2:'TransformData'!$A2, SFReportData!$A$2:'SFReportData'!$A$500), 0)),"") = 0,"", IFERROR(INDEX(SFReportData!$A$2:'SFReportData'!$A$500, MATCH(0, COUNTIF(TransformData!$A$2:'TransformData'!$A2, SFReportData!$A$2:'SFReportData'!$A$500), 0)),""))} | B3: =IFERROR(VLOOKUP(A3,SFReportData!$A$2:$B$500,2,0),"") | C3: =IFERROR(VLOOKUP(A3,SFReportData!$A$2:$C$500,3,0),"") | D3: {=IFERROR(INDEX(SFReportData!$D$2:'SFReportData'!$D$500, MATCH(0, COUNTIF(TransformData!$D$2:'TransformData'!$D2, SFReportData!$D$2:'SFReportData'!$D$500), 0)),"")} -> 0 | E3: =IFERROR(VLOOKUP(A3,SFReportData!$A$2:$J$500,10,0),"") | F3: =IFERROR(VLOOKUP(A3,SFReportData!$A$2:$K$500,11,0),"") | H3: =IFERROR(VLOOKUP(B3,SFReportData!B2:H500,7,0),"") | I3: {=CELL("contents",A3)} | J3: {=IFERROR(INDEX(SFReportData!$E$2:$E$500,MATCH(1,($I3=SFReportData!$A$2:$A$500)*(J$1=SFReportData!$D$2:'SFReportData'!$D$500),0)),"")} -> 0 | K3: {=IFERROR(INDEX(SFReportData!$E$2:$E$500,MATCH(1,($I3=SFReportData!$A$2:$A$500)*(K$1=SFReportData!$D$2:'SFReportData'!$D$500),0)),"")} -> 0 | L3: {=IFERROR(INDEX(SFReportData!$E$2:$E$500,MATCH(1,($I3=SFReportData!$A$2:$A$500)*(L$1=SFReportData!$D$2:'SFReportData'!$D$500),0)),"")} -> 0 | M3: {=IFERROR(INDEX(SFReportData!$E$2:$E$500,MATCH(1,($I3=SFReportData!$A$2:$A$500)*(M$1=SFReportData!$D$2:'SFReportData'!$D$500),0)),"")} -> 0 | N3: {=IFERROR(INDEX(SFReportData!$E$2:$E$500,MATCH(1,($I3=SFReportData!$A$2:$A$500)*(N$1=SFReportData!$D$2:'SFReportData'!$D$500),0)),"")} -> 0 | O3: {=IFERROR(INDEX(SFReportData!$F$2:$F$500,MATCH(1,($I3=SFReportData!$A$2:$A$500)*(O$1=SFReportData!$D$2:'SFReportData'!$D$500),0)),"")} -> 0 | P3: {=IFERROR(INDEX(SFReportData!$F$2:$F$500,MATCH(1,($I3=SFReportData!$A$2:$A$500)*(P$1=SFReportData!$D$2:'SFReportData'!$D$500),0)),"")} -> 0 | Q3: {=IFERROR(INDEX(SFReportData!$F$2:$F$500,MATCH(1,($I3=SFReportData!$A$2:$A$500)*(Q$1=SFReportData!$D$2:'SFReportData'!$D$500),0)),"")} -> 0 | R3: {=IFERROR(INDEX(SFReportData!$F$2:$F$500,MATCH(1,($I3=SFReportData!$A$2:$A$500)*(R$1=SFReportData!$D$2:'SFReportData'!$D$500),0)),"")} -> 0 | S3: {=IFERROR(INDEX(SFReportData!$F$2:$F$500,MATCH(1,($I3=SFReportData!$A$2:$A$500)*(S$1=SFReportData!$D$2:'SFReportData'!$D$500),0)),"")} -> 0 | T3: {=IFERROR(INDEX(SFReportData!$G$2:$G$500,MATCH(1,($I3=SFReportData!$A$2:$A$500)*(T$1=SFReportData!$D$2:'SFReportData'!$D$500),0)),"")} -> 0 | U3: {=IFERROR(INDEX(SFReportData!$G$2:$G$500,MATCH(1,($I3=SFReportData!$A$2:$A$500)*(U$1=SFReportData!$D$2:'SFReportData'!$D$500),0)),"")} -> 0 | V3: {=IFERROR(INDEX(SFReportData!$G$2:$G$500,MATCH(1,($I3=SFReportData!$A$2:$A$500)*(V$1=SFReportData!$D$2:'SFReportData'!$D$500),0)),"")} -> 0 | W3: {=IFERROR(INDEX(SFReportData!$G$2:$G$500,MATCH(1,($I3=SFReportData!$A$2:$A$500)*(W$1=SFReportData!$D$2:'SFReportData'!$D$500),0)),"")} -> 0 | X3: {=IFERROR(INDEX(SFReportData!$G$2:$G$500,MATCH(1,($I3=SFReportData!$A$2:$A$500)*(X$1=SFReportData!$D$2:'SFReportData'!$D$500),0)),"")} -> 0 | Z3: =O3 -> 0 | AA3: =T3 -> 0 | AB3: =J3 -> 0 | AC3: =P3 -> 0 | AD3: =U3 -> 0 | AE3: =K3 -> 0 | AF3: =Q3 -> 0 | AG3: =V3 -> 0 | AH3: =L3 -> 0 | AI3: =R3 -> 0 | AJ3: =W3 -> 0 | AK3: =M3 -> 0 | AL3: =S3 -> 0 | AM3: =X3 -> 0 | AN3: =N3 -> 0 | AO3: =IF(AND((COUNTIF(A3:A50,">""")=0),(COUNTIF(D3:D20,">""")=0)),"No_LLP","") -> No_LLP
A4: {=IF(IFERROR(INDEX(SFReportData!$A$2:'SFReportData'!$A$500, MATCH(0, COUNTIF(TransformData!$A$2:'TransformData'!$A3, SFReportData!$A$2:'SFReportData'!$A$500), 0)),"") = 0,"", IFERROR(INDEX(SFReportData!$A$2:'SFReportData'!$A$500, MATCH(0, COUNTIF(TransformData!$A$2:'TransformData'!$A3, SFReportData!$A$2:'SFReportData'!$A$500), 0)),""))} | B4: =IFERROR(VLOOKUP(A4,SFReportData!$A$2:$B$500,2,0),"") | C4: =IFERROR(VLOOKUP(A4,SFReportData!$A$2:$C$500,3,0),"") | D4: {=IFERROR(INDEX(SFReportData!$D$2:'SFReportData'!$D$500, MATCH(0, COUNTIF(TransformData!$D$2:'TransformData'!$D3, SFReportData!$D$2:'SFReportData'!$D$500), 0)),"")} | E4: =IFERROR(VLOOKUP(A4,SFReportData!$A$2:$J$500,10,0),"") | F4: =IFERROR(VLOOKUP(A4,SFReportData!$A$2:$K$500,11,0),"") | H4: =IFERROR(VLOOKUP(B4,SFReportData!B3:H501,7,0),"") | I4: {=CELL("contents",A4)} | J4: {=IFERROR(INDEX(SFReportData!$E$2:$E$500,MATCH(1,($I4=SFReportData!$A$2:$A$500)*(J$1=SFReportData!$D$2:'SFReportData'!$D$500),0)),"")} -> 0 | K4: {=IFERROR(INDEX(SFReportData!$E$2:$E$500,MATCH(1,($I4=SFReportData!$A$2:$A$500)*(K$1=SFReportData!$D$2:'SFReportData'!$D$500),0)),"")} -> 0 | L4: {=IFERROR(INDEX(SFReportData!$E$2:$E$500,MATCH(1,($I4=SFReportData!$A$2:$A$500)*(L$1=SFReportData!$D$2:'SFReportData'!$D$500),0)),"")} -> 0 | M4: {=IFERROR(INDEX(SFReportData!$E$2:$E$500,MATCH(1,($I4=SFReportData!$A$2:$A$500)*(M$1=SFReportData!$D$2:'SFReportData'!$D$500),0)),"")} -> 0 | N4: {=IFERROR(INDEX(SFReportData!$E$2:$E$500,MATCH(1,($I4=SFReportData!$A$2:$A$500)*(N$1=SFReportData!$D$2:'SFReportData'!$D$500),0)),"")} -> 0 | O4: {=IFERROR(INDEX(SFReportData!$F$2:$F$500,MATCH(1,($I4=SFReportData!$A$2:$A$500)*(O$1=SFReportData!$D$2:'SFReportData'!$D$500),0)),"")} -> 0 | P4: {=IFERROR(INDEX(SFReportData!$F$2:$F$500,MATCH(1,($I4=SFReportData!$A$2:$A$500)*(P$1=SFReportData!$D$2:'SFReportData'!$D$500),0)),"")} -> 0 | Q4: {=IFERROR(INDEX(SFReportData!$F$2:$F$500,MATCH(1,($I4=SFReportData!$A$2:$A$500)*(Q$1=SFReportData!$D$2:'SFReportData'!$D$500),0)),"")} -> 0 | R4: {=IFERROR(INDEX(SFReportData!$F$2:$F$500,MATCH(1,($I4=SFReportData!$A$2:$A$500)*(R$1=SFReportData!$D$2:'SFReportData'!$D$500),0)),"")} -> 0 | S4: {=IFERROR(INDEX(SFReportData!$F$2:$F$500,MATCH(1,($I4=SFReportData!$A$2:$A$500)*(S$1=SFReportData!$D$2:'SFReportData'!$D$500),0)),"")} -> 0 | T4: {=IFERROR(INDEX(SFReportData!$G$2:$G$500,MATCH(1,($I4=SFReportData!$A$2:$A$500)*(T$1=SFReportData!$D$2:'SFReportData'!$D$500),0)),"")} -> 0 | U4: {=IFERROR(INDEX(SFReportData!$G$2:$G$500,MATCH(1,($I4=SFReportData!$A$2:$A$500)*(U$1=SFReportData!$D$2:'SFReportData'!$D$500),0)),"")} -> 0 | V4: {=IFERROR(INDEX(SFReportData!$G$2:$G$500,MATCH(1,($I4=SFReportData!$A$2:$A$500)*(V$1=SFReportData!$D$2:'SFReportData'!$D$500),0)),"")} -> 0 | W4: {=IFERROR(INDEX(SFReportData!$G$2:$G$500,MATCH(1,($I4=SFReportData!$A$2:$A$500)*(W$1=SFReportData!$D$2:'SFReportData'!$D$500),0)),"")} -> 0 | X4: {=IFERROR(INDEX(SFReportData!$G$2:$G$500,MATCH(1,($I4=SFReportData!$A$2:$A$500)*(X$1=SFReportData!$D$2:'SFReportData'!$D$500),0)),"")} -> 0 | Z4: =O4 -> 0 | AA4: =T4 -> 0 | AB4: =J4 -> 0 | AC4: =P4 -> 0 | AD4: =U4 -> 0 | AE4: =K4 -> 0 | AF4: =Q4 -> 0 | AG4: =V4 -> 0 | AH4: =L4 -> 0 | AI4: =R4 -> 0 | AJ4: =W4 -> 0 | AK4: =M4 -> 0 | AL4: =S4 -> 0 | AM4: =X4 -> 0 | AN4: =N4 -> 0
A5: {=IF(IFERROR(INDEX(SFReportData!$A$2:'SFReportData'!$A$500, MATCH(0, COUNTIF(TransformData!$A$2:'TransformData'!$A4, SFReportData!$A$2:'SFReportData'!$A$500), 0)),"") = 0,"", IFERROR(INDEX(SFReportData!$A$2:'SFReportData'!$A$500, MATCH(0, COUNTIF(TransformData!$A$2:'TransformData'!$A4, SFReportData!$A$2:'SFReportData'!$A$500), 0)),""))} | B5: =IFERROR(VLOOKUP(A5,SFReportData!$A$2:$B$500,2,0),"") | C5: =IFERROR(VLOOKUP(A5,SFReportData!$A$2:$C$500,3,0),"") | D5: {=IFERROR(INDEX(SFReportData!$D$2:'SFReportData'!$D$500, MATCH(0, COUNTIF(TransformData!$D$2:'TransformData'!$D4, SFReportData!$D$2:'SFReportData'!$D$500), 0)),"")} | E5: =IFERROR(VLOOKUP(A5,SFReportData!$A$2:$J$500,10,0),"") | F5: =IFERROR(VLOOKUP(A5,SFReportData!$A$2:$K$500,11,0),"") | H5: =IFERROR(VLOOKUP(B5,SFReportData!B4:H502,7,0),"") | I5: {=CELL("contents",A5)} | J5: {=IFERROR(INDEX(SFReportData!$E$2:$E$500,MATCH(1,($I5=SFReportData!$A$2:$A$500)*(J$1=SFReportData!$D$2:'SFReportData'!$D$500),0)),"")} -> 0 | K5: {=IFERROR(INDEX(SFReportData!$E$2:$E$500,MATCH(1,($I5=SFReportData!$A$2:$A$500)*(K$1=SFReportData!$D$2:'SFReportData'!$D$500),0)),"")} -> 0 | L5: {=IFERROR(INDEX(SFReportData!$E$2:$E$500,MATCH(1,($I5=SFReportData!$A$2:$A$500)*(L$1=SFReportData!$D$2:'SFReportData'!$D$500),0)),"")} -> 0 | M5: {=IFERROR(INDEX(SFReportData!$E$2:$E$500,MATCH(1,($I5=SFReportData!$A$2:$A$500)*(M$1=SFReportData!$D$2:'SFReportData'!$D$500),0)),"")} -> 0 | N5: {=IFERROR(INDEX(SFReportData!$E$2:$E$500,MATCH(1,($I5=SFReportData!$A$2:$A$500)*(N$1=SFReportData!$D$2:'SFReportData'!$D$500),0)),"")} -> 0 | O5: {=IFERROR(INDEX(SFReportData!$F$2:$F$500,MATCH(1,($I5=SFReportData!$A$2:$A$500)*(O$1=SFReportData!$D$2:'SFReportData'!$D$500),0)),"")} -> 0 | P5: {=IFERROR(INDEX(SFReportData!$F$2:$F$500,MATCH(1,($I5=SFReportData!$A$2:$A$500)*(P$1=SFReportData!$D$2:'SFReportData'!$D$500),0)),"")} -> 0 | Q5: {=IFERROR(INDEX(SFReportData!$F$2:$F$500,MATCH(1,($I5=SFReportData!$A$2:$A$500)*(Q$1=SFReportData!$D$2:'SFReportData'!$D$500),0)),"")} -> 0 | R5: {=IFERROR(INDEX(SFReportData!$F$2:$F$500,MATCH(1,($I5=SFReportData!$A$2:$A$500)*(R$1=SFReportData!$D$2:'SFReportData'!$D$500),0)),"")} -> 0 | S5: {=IFERROR(INDEX(SFReportData!$F$2:$F$500,MATCH(1,($I5=SFReportData!$A$2:$A$500)*(S$1=SFReportData!$D$2:'SFReportData'!$D$500),0)),"")} -> 0 | T5: {=IFERROR(INDEX(SFReportData!$G$2:$G$500,MATCH(1,($I5=SFReportData!$A$2:$A$500)*(T$1=SFReportData!$D$2:'SFReportData'!$D$500),0)),"")} -> 0 | U5: {=IFERROR(INDEX(SFReportData!$G$2:$G$500,MATCH(1,($I5=SFReportData!$A$2:$A$500)*(U$1=SFReportData!$D$2:'SFReportData'!$D$500),0)),"")} -> 0 | V5: {=IFERROR(INDEX(SFReportData!$G$2:$G$500,MATCH(1,($I5=SFReportData!$A$2:$A$500)*(V$1=SFReportData!$D$2:'SFReportData'!$D$500),0)),"")} -> 0 | W5: {=IFERROR(INDEX(SFReportData!$G$2:$G$500,MATCH(1,($I5=SFReportData!$A$2:$A$500)*(W$1=SFReportData!$D$2:'SFReportData'!$D$500),0)),"")} -> 0 | X5: {=IFERROR(INDEX(SFReportData!$G$2:$G$500,MATCH(1,($I5=SFReportData!$A$2:$A$500)*(X$1=SFReportData!$D$2:'SFReportData'!$D$500),0)),"")} -> 0 | Z5: =O5 -> 0 | AA5: =T5 -> 0 | AB5: =J5 -> 0 | AC5: =P5 -> 0 | AD5: =U5 -> 0 | AE5: =K5 -> 0 | AF5: =Q5 -> 0 | AG5: =V5 -> 0 | AH5: =L5 -> 0 | AI5: =R5 -> 0 | AJ5: =W5 -> 0 | AK5: =M5 -> 0 | AL5: =S5 -> 0 | AM5: =X5 -> 0 | AN5: =N5 -> 0
A6: {=IF(IFERROR(INDEX(SFReportData!$A$2:'SFReportData'!$A$500, MATCH(0, COUNTIF(TransformData!$A$2:'TransformData'!$A5, SFReportData!$A$2:'SFReportData'!$A$500), 0)),"") = 0,"", IFERROR(INDEX(SFReportData!$A$2:'SFReportData'!$A$500, MATCH(0, COUNTIF(TransformData!$A$2:'TransformData'!$A5, SFReportData!$A$2:'SFReportData'!$A$500), 0)),""))} | B6: =IFERROR(VLOOKUP(A6,SFReportData!$A$2:$B$500,2,0),"") | C6: =IFERROR(VLOOKUP(A6,SFReportData!$A$2:$C$500,3,0),"") | D6: {=IFERROR(INDEX(SFReportData!$D$2:'SFReportData'!$D$500, MATCH(0, COUNTIF(TransformData!$D$2:'TransformData'!$D5, SFReportData!$D$2:'SFReportData'!$D$500), 0)),"")} | E6: =IFERROR(VLOOKUP(A6,SFReportData!$A$2:$J$500,10,0),"") | F6: =IFERROR(VLOOKUP(A6,SFReportData!$A$2:$K$500,11,0),"") | H6: =IFERROR(VLOOKUP(B6,SFReportData!B5:H503,7,0),"") | I6: {=CELL("contents",A6)} | J6: {=IFERROR(INDEX(SFReportData!$E$2:$E$500,MATCH(1,($I6=SFReportData!$A$2:$A$500)*(J$1=SFReportData!$D$2:'SFReportData'!$D$500),0)),"")} -> 0 | K6: {=IFERROR(INDEX(SFReportData!$E$2:$E$500,MATCH(1,($I6=SFReportData!$A$2:$A$500)*(K$1=SFReportData!$D$2:'SFReportData'!$D$500),0)),"")} -> 0 | L6: {=IFERROR(INDEX(SFReportData!$E$2:$E$500,MATCH(1,($I6=SFReportData!$A$2:$A$500)*(L$1=SFReportData!$D$2:'SFReportData'!$D$500),0)),"")} -> 0 | M6: {=IFERROR(INDEX(SFReportData!$E$2:$E$500,MATCH(1,($I6=SFReportData!$A$2:$A$500)*(M$1=SFReportData!$D$2:'SFReportData'!$D$500),0)),"")} -> 0 | N6: {=IFERROR(INDEX(SFReportData!$E$2:$E$500,MATCH(1,($I6=SFReportData!$A$2:$A$500)*(N$1=SFReportData!$D$2:'SFReportData'!$D$500),0)),"")} -> 0 | O6: {=IFERROR(INDEX(SFReportData!$F$2:$F$500,MATCH(1,($I6=SFReportData!$A$2:$A$500)*(O$1=SFReportData!$D$2:'SFReportData'!$D$500),0)),"")} -> 0 | P6: {=IFERROR(INDEX(SFReportData!$F$2:$F$500,MATCH(1,($I6=SFReportData!$A$2:$A$500)*(P$1=SFReportData!$D$2:'SFReportData'!$D$500),0)),"")} -> 0 | Q6: {=IFERROR(INDEX(SFReportData!$F$2:$F$500,MATCH(1,($I6=SFReportData!$A$2:$A$500)*(Q$1=SFReportData!$D$2:'SFReportData'!$D$500),0)),"")} -> 0 | R6: {=IFERROR(INDEX(SFReportData!$F$2:$F$500,MATCH(1,($I6=SFReportData!$A$2:$A$500)*(R$1=SFReportData!$D$2:'SFReportData'!$D$500),0)),"")} -> 0 | S6: {=IFERROR(INDEX(SFReportData!$F$2:$F$500,MATCH(1,($I6=SFReportData!$A$2:$A$500)*(S$1=SFReportData!$D$2:'SFReportData'!$D$500),0)),"")} -> 0 | T6: {=IFERROR(INDEX(SFReportData!$G$2:$G$500,MATCH(1,($I6=SFReportData!$A$2:$A$500)*(T$1=SFReportData!$D$2:'SFReportData'!$D$500),0)),"")} -> 0 | U6: {=IFERROR(INDEX(SFReportData!$G$2:$G$500,MATCH(1,($I6=SFReportData!$A$2:$A$500)*(U$1=SFReportData!$D$2:'SFReportData'!$D$500),0)),"")} -> 0 | V6: {=IFERROR(INDEX(SFReportData!$G$2:$G$500,MATCH(1,($I6=SFReportData!$A$2:$A$500)*(V$1=SFReportData!$D$2:'SFReportData'!$D$500),0)),"")} -> 0 | W6: {=IFERROR(INDEX(SFReportData!$G$2:$G$500,MATCH(1,($I6=SFReportData!$A$2:$A$500)*(W$1=SFReportData!$D$2:'SFReportData'!$D$500),0)),"")} -> 0 | X6: {=IFERROR(INDEX(SFReportData!$G$2:$G$500,MATCH(1,($I6=SFReportData!$A$2:$A$500)*(X$1=SFReportData!$D$2:'SFReportData'!$D$500),0)),"")} -> 0 | Z6: =O6 -> 0 | AA6: =T6 -> 0 | AB6: =J6 -> 0 | AC6: =P6 -> 0 | AD6: =U6 -> 0 | AE6: =K6 -> 0 | AF6: =Q6 -> 0 | AG6: =V6 -> 0 | AH6: =L6 -> 0 | AI6: =R6 -> 0 | AJ6: =W6 -> 0 | AK6: =M6 -> 0 | AL6: =S6 -> 0 | AM6: =X6 -> 0 | AN6: =N6 -> 0
A7: {=IF(IFERROR(INDEX(SFReportData!$A$2:'SFReportData'!$A$500, MATCH(0, COUNTIF(TransformData!$A$2:'TransformData'!$A6, SFReportData!$A$2:'SFReportData'!$A$500), 0)),"") = 0,"", IFERROR(INDEX(SFReportData!$A$2:'SFReportData'!$A$500, MATCH(0, COUNTIF(TransformData!$A$2:'TransformData'!$A6, SFReportData!$A$2:'SFReportData'!$A$500), 0)),""))} | B7: =IFERROR(VLOOKUP(A7,SFReportData!$A$2:$B$500,2,0),"") | C7: =IFERROR(VLOOKUP(A7,SFReportData!$A$2:$C$500,3,0),"") | D7: {=IFERROR(INDEX(SFReportData!$D$2:'SFReportData'!$D$500, MATCH(0, COUNTIF(TransformData!$D$2:'TransformData'!$D6, SFReportData!$D$2:'SFReportData'!$D$500), 0)),"")} | E7: =IFERROR(VLOOKUP(A7,SFReportData!$A$2:$J$500,10,0),"") | F7: =IFERROR(VLOOKUP(A7,SFReportData!$A$2:$K$500,11,0),"") | H7: =IFERROR(VLOOKUP(B7,SFReportData!B6:H504,7,0),"") | I7: {=CELL("contents",A7)} | J7: {=IFERROR(INDEX(SFReportData!$E$2:$E$500,MATCH(1,($I7=SFReportData!$A$2:$A$500)*(J$1=SFReportData!$D$2:'SFReportData'!$D$500),0)),"")} -> 0 | K7: {=IFERROR(INDEX(SFReportData!$E$2:$E$500,MATCH(1,($I7=SFReportData!$A$2:$A$500)*(K$1=SFReportData!$D$2:'SFReportData'!$D$500),0)),"")} -> 0 | L7: {=IFERROR(INDEX(SFReportData!$E$2:$E$500,MATCH(1,($I7=SFReportData!$A$2:$A$500)*(L$1=SFReportData!$D$2:'SFReportData'!$D$500),0)),"")} -> 0 | M7: {=IFERROR(INDEX(SFReportData!$E$2:$E$500,MATCH(1,($I7=SFReportData!$A$2:$A$500)*(M$1=SFReportData!$D$2:'SFReportData'!$D$500),0)),"")} -> 0 | N7: {=IFERROR(INDEX(SFReportData!$E$2:$E$500,MATCH(1,($I7=SFReportData!$A$2:$A$500)*(N$1=SFReportData!$D$2:'SFReportData'!$D$500),0)),"")} -> 0 | O7: {=IFERROR(INDEX(SFReportData!$F$2:$F$500,MATCH(1,($I7=SFReportData!$A$2:$A$500)*(O$1=SFReportData!$D$2:'SFReportData'!$D$500),0)),"")} -> 0 | P7: {=IFERROR(INDEX(SFReportData!$F$2:$F$500,MATCH(1,($I7=SFReportData!$A$2:$A$500)*(P$1=SFReportData!$D$2:'SFReportData'!$D$500),0)),"")} -> 0 | Q7: {=IFERROR(INDEX(SFReportData!$F$2:$F$500,MATCH(1,($I7=SFReportData!$A$2:$A$500)*(Q$1=SFReportData!$D$2:'SFReportData'!$D$500),0)),"")} -> 0 | R7: {=IFERROR(INDEX(SFReportData!$F$2:$F$500,MATCH(1,($I7=SFReportData!$A$2:$A$500)*(R$1=SFReportData!$D$2:'SFReportData'!$D$500),0)),"")} -> 0 | S7: {=IFERROR(INDEX(SFReportData!$F$2:$F$500,MATCH(1,($I7=SFReportData!$A$2:$A$500)*(S$1=SFReportData!$D$2:'SFReportData'!$D$500),0)),"")} -> 0 | T7: {=IFERROR(INDEX(SFReportData!$G$2:$G$500,MATCH(1,($I7=SFReportData!$A$2:$A$500)*(T$1=SFReportData!$D$2:'SFReportData'!$D$500),0)),"")} -> 0 | U7: {=IFERROR(INDEX(SFReportData!$G$2:$G$500,MATCH(1,($I7=SFReportData!$A$2:$A$500)*(U$1=SFReportData!$D$2:'SFReportData'!$D$500),0)),"")} -> 0 | V7: {=IFERROR(INDEX(SFReportData!$G$2:$G$500,MATCH(1,($I7=SFReportData!$A$2:$A$500)*(V$1=SFReportData!$D$2:'SFReportData'!$D$500),0)),"")} -> 0 | W7: {=IFERROR(INDEX(SFReportData!$G$2:$G$500,MATCH(1,($I7=SFReportData!$A$2:$A$500)*(W$1=SFReportData!$D$2:'SFReportData'!$D$500),0)),"")} -> 0 | X7: {=IFERROR(INDEX(SFReportData!$G$2:$G$500,MATCH(1,($I7=SFReportData!$A$2:$A$500)*(X$1=SFReportData!$D$2:'SFReportData'!$D$500),0)),"")} -> 0 | Z7: =O7 -> 0 | AA7: =T7 -> 0 | AB7: =J7 -> 0 | AC7: =P7 -> 0 | AD7: =U7 -> 0 | AE7: =K7 -> 0 | AF7: =Q7 -> 0 | AG7: =V7 -> 0 | AH7: =L7 -> 0 | AI7: =R7 -> 0 | AJ7: =W7 -> 0 | AK7: =M7 -> 0 | AL7: =S7 -> 0 | AM7: =X7 -> 0 | AN7: =N7 -> 0
A8: {=IF(IFERROR(INDEX(SFReportData!$A$2:'SFReportData'!$A$500, MATCH(0, COUNTIF(TransformData!$A$2:'TransformData'!$A7, SFReportData!$A$2:'SFReportData'!$A$500), 0)),"") = 0,"", IFERROR(INDEX(SFReportData!$A$2:'SFReportData'!$A$500, MATCH(0, COUNTIF(TransformData!$A$2:'TransformData'!$A7, SFReportData!$A$2:'SFReportData'!$A$500), 0)),""))} | B8: =IFERROR(VLOOKUP(A8,SFReportData!$A$2:$B$500,2,0),"") | C8: =IFERROR(VLOOKUP(A8,SFReportData!$A$2:$C$500,3,0),"") | D8: {=IFERROR(INDEX(SFReportData!$D$2:'SFReportData'!$D$500, MATCH(0, COUNTIF(TransformData!$D$2:'TransformData'!$D7, SFReportData!$D$2:'SFReportData'!$D$500), 0)),"")} | E8: =IFERROR(VLOOKUP(A8,SFReportData!$A$2:$J$500,10,0),"") | F8: =IFERROR(VLOOKUP(A8,SFReportData!$A$2:$K$500,11,0),"") | H8: =IFERROR(VLOOKUP(B8,SFReportData!B7:H505,7,0),"") | I8: {=CELL("contents",A8)} | J8: {=IFERROR(INDEX(SFReportData!$E$2:$E$500,MATCH(1,($I8=SFReportData!$A$2:$A$500)*(J$1=SFReportData!$D$2:'SFReportData'!$D$500),0)),"")} -> 0 | K8: {=IFERROR(INDEX(SFReportData!$E$2:$E$500,MATCH(1,($I8=SFReportData!$A$2:$A$500)*(K$1=SFReportData!$D$2:'SFReportData'!$D$500),0)),"")} -> 0 | L8: {=IFERROR(INDEX(SFReportData!$E$2:$E$500,MATCH(1,($I8=SFReportData!$A$2:$A$500)*(L$1=SFReportData!$D$2:'SFReportData'!$D$500),0)),"")} -> 0 | M8: {=IFERROR(INDEX(SFReportData!$E$2:$E$500,MATCH(1,($I8=SFReportData!$A$2:$A$500)*(M$1=SFReportData!$D$2:'SFReportData'!$D$500),0)),"")} -> 0 | N8: {=IFERROR(INDEX(SFReportData!$E$2:$E$500,MATCH(1,($I8=SFReportData!$A$2:$A$500)*(N$1=SFReportData!$D$2:'SFReportData'!$D$500),0)),"")} -> 0 | O8: {=IFERROR(INDEX(SFReportData!$F$2:$F$500,MATCH(1,($I8=SFReportData!$A$2:$A$500)*(O$1=SFReportData!$D$2:'SFReportData'!$D$500),0)),"")} -> 0 | P8: {=IFERROR(INDEX(SFReportData!$F$2:$F$500,MATCH(1,($I8=SFReportData!$A$2:$A$500)*(P$1=SFReportData!$D$2:'SFReportData'!$D$500),0)),"")} -> 0 | Q8: {=IFERROR(INDEX(SFReportData!$F$2:$F$500,MATCH(1,($I8=SFReportData!$A$2:$A$500)*(Q$1=SFReportData!$D$2:'SFReportData'!$D$500),0)),"")} -> 0 | R8: {=IFERROR(INDEX(SFReportData!$F$2:$F$500,MATCH(1,($I8=SFReportData!$A$2:$A$500)*(R$1=SFReportData!$D$2:'SFReportData'!$D$500),0)),"")} -> 0 | S8: {=IFERROR(INDEX(SFReportData!$F$2:$F$500,MATCH(1,($I8=SFReportData!$A$2:$A$500)*(S$1=SFReportData!$D$2:'SFReportData'!$D$500),0)),"")} -> 0 | T8: {=IFERROR(INDEX(SFReportData!$G$2:$G$500,MATCH(1,($I8=SFReportData!$A$2:$A$500)*(T$1=SFReportData!$D$2:'SFReportData'!$D$500),0)),"")} -> 0 | U8: {=IFERROR(INDEX(SFReportData!$G$2:$G$500,MATCH(1,($I8=SFReportData!$A$2:$A$500)*(U$1=SFReportData!$D$2:'SFReportData'!$D$500),0)),"")} -> 0 | V8: {=IFERROR(INDEX(SFReportData!$G$2:$G$500,MATCH(1,($I8=SFReportData!$A$2:$A$500)*(V$1=SFReportData!$D$2:'SFReportData'!$D$500),0)),"")} -> 0 | W8: {=IFERROR(INDEX(SFReportData!$G$2:$G$500,MATCH(1,($I8=SFReportData!$A$2:$A$500)*(W$1=SFReportData!$D$2:'SFReportData'!$D$500),0)),"")} -> 0 | X8: {=IFERROR(INDEX(SFReportData!$G$2:$G$500,MATCH(1,($I8=SFReportData!$A$2:$A$500)*(X$1=SFReportData!$D$2:'SFReportData'!$D$500),0)),"")} -> 0 | Z8: =O8 -> 0 | AA8: =T8 -> 0 | AB8: =J8 -> 0 | AC8: =P8 -> 0 | AD8: =U8 -> 0 | AE8: =K8 -> 0 | AF8: =Q8 -> 0 | AG8: =V8 -> 0 | AH8: =L8 -> 0 | AI8: =R8 -> 0 | AJ8: =W8 -> 0 | AK8: =M8 -> 0 | AL8: =S8 -> 0 | AM8: =X8 -> 0 | AN8: =N8 -> 0
A9: {=IF(IFERROR(INDEX(SFReportData!$A$2:'SFReportData'!$A$500, MATCH(0, COUNTIF(TransformData!$A$2:'TransformData'!$A8, SFReportData!$A$2:'SFReportData'!$A$500), 0)),"") = 0,"", IFERROR(INDEX(SFReportData!$A$2:'SFReportData'!$A$500, MATCH(0, COUNTIF(TransformData!$A$2:'TransformData'!$A8, SFReportData!$A$2:'SFReportData'!$A$500), 0)),""))} | B9: =IFERROR(VLOOKUP(A9,SFReportData!$A$2:$B$500,2,0),"") | C9: =IFERROR(VLOOKUP(A9,SFReportData!$A$2:$C$500,3,0),"") | D9: {=IFERROR(INDEX(SFReportData!$D$2:'SFReportData'!$D$500, MATCH(0, COUNTIF(TransformData!$D$2:'TransformData'!$D8, SFReportData!$D$2:'SFReportData'!$D$500), 0)),"")} | E9: =IFERROR(VLOOKUP(A9,SFReportData!$A$2:$J$500,10,0),"") | F9: =IFERROR(VLOOKUP(A9,SFReportData!$A$2:$K$500,11,0),"") | H9: =IFERROR(VLOOKUP(B9,SFReportData!B8:H506,7,0),"") | I9: {=CELL("contents",A9)} | J9: {=IFERROR(INDEX(SFReportData!$E$2:$E$500,MATCH(1,($I9=SFReportData!$A$2:$A$500)*(J$1=SFReportData!$D$2:'SFReportData'!$D$500),0)),"")} -> 0 | K9: {=IFERROR(INDEX(SFReportData!$E$2:$E$500,MATCH(1,($I9=SFReportData!$A$2:$A$500)*(K$1=SFReportData!$D$2:'SFReportData'!$D$500),0)),"")} -> 0 | L9: {=IFERROR(INDEX(SFReportData!$E$2:$E$500,MATCH(1,($I9=SFReportData!$A$2:$A$500)*(L$1=SFReportData!$D$2:'SFReportData'!$D$500),0)),"")} -> 0 | M9: {=IFERROR(INDEX(SFReportData!$E$2:$E$500,MATCH(1,($I9=SFReportData!$A$2:$A$500)*(M$1=SFReportData!$D$2:'SFReportData'!$D$500),0)),"")} -> 0 | N9: {=IFERROR(INDEX(SFReportData!$E$2:$E$500,MATCH(1,($I9=SFReportData!$A$2:$A$500)*(N$1=SFReportData!$D$2:'SFReportData'!$D$500),0)),"")} -> 0 | O9: {=IFERROR(INDEX(SFReportData!$F$2:$F$500,MATCH(1,($I9=SFReportData!$A$2:$A$500)*(O$1=SFReportData!$D$2:'SFReportData'!$D$500),0)),"")} -> 0 | P9: {=IFERROR(INDEX(SFReportData!$F$2:$F$500,MATCH(1,($I9=SFReportData!$A$2:$A$500)*(P$1=SFReportData!$D$2:'SFReportData'!$D$500),0)),"")} -> 0 | Q9: {=IFERROR(INDEX(SFReportData!$F$2:$F$500,MATCH(1,($I9=SFReportData!$A$2:$A$500)*(Q$1=SFReportData!$D$2:'SFReportData'!$D$500),0)),"")} -> 0 | R9: {=IFERROR(INDEX(SFReportData!$F$2:$F$500,MATCH(1,($I9=SFReportData!$A$2:$A$500)*(R$1=SFReportData!$D$2:'SFReportData'!$D$500),0)),"")} -> 0 | S9: {=IFERROR(INDEX(SFReportData!$F$2:$F$500,MATCH(1,($I9=SFReportData!$A$2:$A$500)*(S$1=SFReportData!$D$2:'SFReportData'!$D$500),0)),"")} -> 0 | T9: {=IFERROR(INDEX(SFReportData!$G$2:$G$500,MATCH(1,($I9=SFReportData!$A$2:$A$500)*(T$1=SFReportData!$D$2:'SFReportData'!$D$500),0)),"")} -> 0 | U9: {=IFERROR(INDEX(SFReportData!$G$2:$G$500,MATCH(1,($I9=SFReportData!$A$2:$A$500)*(U$1=SFReportData!$D$2:'SFReportData'!$D$500),0)),"")} -> 0 | V9: {=IFERROR(INDEX(SFReportData!$G$2:$G$500,MATCH(1,($I9=SFReportData!$A$2:$A$500)*(V$1=SFReportData!$D$2:'SFReportData'!$D$500),0)),"")} -> 0 | W9: {=IFERROR(INDEX(SFReportData!$G$2:$G$500,MATCH(1,($I9=SFReportData!$A$2:$A$500)*(W$1=SFReportData!$D$2:'SFReportData'!$D$500),0)),"")} -> 0 | X9: {=IFERROR(INDEX(SFReportData!$G$2:$G$500,MATCH(1,($I9=SFReportData!$A$2:$A$500)*(X$1=SFReportData!$D$2:'SFReportData'!$D$500),0)),"")} -> 0 | Z9: =O9 -> 0 | AA9: =T9 -> 0 | AB9: =J9 -> 0 | AC9: =P9 -> 0 | AD9: =U9 -> 0 | AE9: =K9 -> 0 | AF9: =Q9 -> 0 | AG9: =V9 -> 0 | AH9: =L9 -> 0 | AI9: =R9 -> 0 | AJ9: =W9 -> 0 | AK9: =M9 -> 0 | AL9: =S9 -> 0 | AM9: =X9 -> 0 | AN9: =N9 -> 0
A10: {=IF(IFERROR(INDEX(SFReportData!$A$2:'SFReportData'!$A$500, MATCH(0, COUNTIF(TransformData!$A$2:'TransformData'!$A9, SFReportData!$A$2:'SFReportData'!$A$500), 0)),"") = 0,"", IFERROR(INDEX(SFReportData!$A$2:'SFReportData'!$A$500, MATCH(0, COUNTIF(TransformData!$A$2:'TransformData'!$A9, SFReportData!$A$2:'SFReportData'!$A$500), 0)),""))} | B10: =IFERROR(VLOOKUP(A10,SFReportData!$A$2:$B$500,2,0),"") | C10: =IFERROR(VLOOKUP(A10,SFReportData!$A$2:$C$500,3,0),"") | D10: {=IFERROR(INDEX(SFReportData!$D$2:'SFReportData'!$D$500, MATCH(0, COUNTIF(TransformData!$D$2:'TransformData'!$D9, SFReportData!$D$2:'SFReportData'!$D$500), 0)),"")} | E10: =IFERROR(VLOOKUP(A10,SFReportData!$A$2:$J$500,10,0),"") | F10: =IFERROR(VLOOKUP(A10,SFReportData!$A$2:$K$500,11,0),"") | H10: =IFERROR(VLOOKUP(B10,SFReportData!B9:H507,7,0),"") | I10: {=CELL("contents",A10)} | J10: {=IFERROR(INDEX(SFReportData!$E$2:$E$500,MATCH(1,($I10=SFReportData!$A$2:$A$500)*(J$1=SFReportData!$D$2:'SFReportData'!$D$500),0)),"")} -> 0 | K10: {=IFERROR(INDEX(SFReportData!$E$2:$E$500,MATCH(1,($I10=SFReportData!$A$2:$A$500)*(K$1=SFReportData!$D$2:'SFReportData'!$D$500),0)),"")} -> 0 | L10: {=IFERROR(INDEX(SFReportData!$E$2:$E$500,MATCH(1,($I10=SFReportData!$A$2:$A$500)*(L$1=SFReportData!$D$2:'SFReportData'!$D$500),0)),"")} -> 0 | M10: {=IFERROR(INDEX(SFReportData!$E$2:$E$500,MATCH(1,($I10=SFReportData!$A$2:$A$500)*(M$1=SFReportData!$D$2:'SFReportData'!$D$500),0)),"")} -> 0 | N10: {=IFERROR(INDEX(SFReportData!$E$2:$E$500,MATCH(1,($I10=SFReportData!$A$2:$A$500)*(N$1=SFReportData!$D$2:'SFReportData'!$D$500),0)),"")} -> 0 | O10: {=IFERROR(INDEX(SFReportData!$F$2:$F$500,MATCH(1,($I10=SFReportData!$A$2:$A$500)*(O$1=SFReportData!$D$2:'SFReportData'!$D$500),0)),"")} -> 0 | P10: {=IFERROR(INDEX(SFReportData!$F$2:$F$500,MATCH(1,($I10=SFReportData!$A$2:$A$500)*(P$1=SFReportData!$D$2:'SFReportData'!$D$500),0)),"")} -> 0 | Q10: {=IFERROR(INDEX(SFReportData!$F$2:$F$500,MATCH(1,($I10=SFReportData!$A$2:$A$500)*(Q$1=SFReportData!$D$2:'SFReportData'!$D$500),0)),"")} -> 0 | R10: {=IFERROR(INDEX(SFReportData!$F$2:$F$500,MATCH(1,($I10=SFReportData!$A$2:$A$500)*(R$1=SFReportData!$D$2:'SFReportData'!$D$500),0)),"")} -> 0 | S10: {=IFERROR(INDEX(SFReportData!$F$2:$F$500,MATCH(1,($I10=SFReportData!$A$2:$A$500)*(S$1=SFReportData!$D$2:'SFReportData'!$D$500),0)),"")} -> 0 | T10: {=IFERROR(INDEX(SFReportData!$G$2:$G$500,MATCH(1,($I10=SFReportData!$A$2:$A$500)*(T$1=SFReportData!$D$2:'SFReportData'!$D$500),0)),"")} -> 0 | U10: {=IFERROR(INDEX(SFReportData!$G$2:$G$500,MATCH(1,($I10=SFReportData!$A$2:$A$500)*(U$1=SFReportData!$D$2:'SFReportData'!$D$500),0)),"")} -> 0 | V10: {=IFERROR(INDEX(SFReportData!$G$2:$G$500,MATCH(1,($I10=SFReportData!$A$2:$A$500)*(V$1=SFReportData!$D$2:'SFReportData'!$D$500),0)),"")} -> 0 | W10: {=IFERROR(INDEX(SFReportData!$G$2:$G$500,MATCH(1,($I10=SFReportData!$A$2:$A$500)*(W$1=SFReportData!$D$2:'SFReportData'!$D$500),0)),"")} -> 0 | X10: {=IFERROR(INDEX(SFReportData!$G$2:$G$500,MATCH(1,($I10=SFReportData!$A$2:$A$500)*(X$1=SFReportData!$D$2:'SFReportData'!$D$500),0)),"")} -> 0 | Z10: =O10 -> 0 | AA10: =T10 -> 0 | AB10: =J10 -> 0 | AC10: =P10 -> 0 | AD10: =U10 -> 0 | AE10: =K10 -> 0 | AF10: =Q10 -> 0 | AG10: =V10 -> 0 | AH10: =L10 -> 0 | AI10: =R10 -> 0 | AJ10: =W10 -> 0 | AK10: =M10 -> 0 | AL10: =S10 -> 0 | AM10: =X10 -> 0 | AN10: =N10 -> 0
A11: {=IF(IFERROR(INDEX(SFReportData!$A$2:'SFReportData'!$A$500, MATCH(0, COUNTIF(TransformData!$A$2:'TransformData'!$A10, SFReportData!$A$2:'SFReportData'!$A$500), 0)),"") = 0,"", IFERROR(INDEX(SFReportData!$A$2:'SFReportData'!$A$500, MATCH(0, COUNTIF(TransformData!$A$2:'TransformData'!$A10, SFReportData!$A$2:'SFReportData'!$A$500), 0)),""))} | B11: =IFERROR(VLOOKUP(A11,SFReportData!$A$2:$B$500,2,0),"") | C11: =IFERROR(VLOOKUP(A11,SFReportData!$A$2:$C$500,3,0),"") | D11: {=IFERROR(INDEX(SFReportData!$D$2:'SFReportData'!$D$500, MATCH(0, COUNTIF(TransformData!$D$2:'TransformData'!$D10, SFReportData!$D$2:'SFReportData'!$D$500), 0)),"")} | E11: =IFERROR(VLOOKUP(A11,SFReportData!$A$2:$J$500,10,0),"") | F11: =IFERROR(VLOOKUP(A11,SFReportData!$A$2:$K$500,11,0),"") | H11: =IFERROR(VLOOKUP(B11,SFReportData!B10:H508,7,0),"") | I11: {=CELL("contents",A11)} | J11: {=IFERROR(INDEX(SFReportData!$E$2:$E$500,MATCH(1,($I11=SFReportData!$A$2:$A$500)*(J$1=SFReportData!$D$2:'SFReportData'!$D$500),0)),"")} -> 0 | K11: {=IFERROR(INDEX(SFReportData!$E$2:$E$500,MATCH(1,($I11=SFReportData!$A$2:$A$500)*(K$1=SFReportData!$D$2:'SFReportData'!$D$500),0)),"")} -> 0 | L11: {=IFERROR(INDEX(SFReportData!$E$2:$E$500,MATCH(1,($I11=SFReportData!$A$2:$A$500)*(L$1=SFReportData!$D$2:'SFReportData'!$D$500),0)),"")} -> 0 | M11: {=IFERROR(INDEX(SFReportData!$E$2:$E$500,MATCH(1,($I11=SFReportData!$A$2:$A$500)*(M$1=SFReportData!$D$2:'SFReportData'!$D$500),0)),"")} -> 0 | N11: {=IFERROR(INDEX(SFReportData!$E$2:$E$500,MATCH(1,($I11=SFReportData!$A$2:$A$500)*(N$1=SFReportData!$D$2:'SFReportData'!$D$500),0)),"")} -> 0 | O11: {=IFERROR(INDEX(SFReportData!$F$2:$F$500,MATCH(1,($I11=SFReportData!$A$2:$A$500)*(O$1=SFReportData!$D$2:'SFReportData'!$D$500),0)),"")} -> 0 | P11: {=IFERROR(INDEX(SFReportData!$F$2:$F$500,MATCH(1,($I11=SFReportData!$A$2:$A$500)*(P$1=SFReportData!$D$2:'SFReportData'!$D$500),0)),"")} -> 0 | Q11: {=IFERROR(INDEX(SFReportData!$F$2:$F$500,MATCH(1,($I11=SFReportData!$A$2:$A$500)*(Q$1=SFReportData!$D$2:'SFReportData'!$D$500),0)),"")} -> 0 | R11: {=IFERROR(INDEX(SFReportData!$F$2:$F$500,MATCH(1,($I11=SFReportData!$A$2:$A$500)*(R$1=SFReportData!$D$2:'SFReportData'!$D$500),0)),"")} -> 0 | S11: {=IFERROR(INDEX(SFReportData!$F$2:$F$500,MATCH(1,($I11=SFReportData!$A$2:$A$500)*(S$1=SFReportData!$D$2:'SFReportData'!$D$500),0)),"")} -> 0 | T11: {=IFERROR(INDEX(SFReportData!$G$2:$G$500,MATCH(1,($I11=SFReportData!$A$2:$A$500)*(T$1=SFReportData!$D$2:'SFReportData'!$D$500),0)),"")} -> 0 | U11: {=IFERROR(INDEX(SFReportData!$G$2:$G$500,MATCH(1,($I11=SFReportData!$A$2:$A$500)*(U$1=SFReportData!$D$2:'SFReportData'!$D$500),0)),"")} -> 0 | V11: {=IFERROR(INDEX(SFReportData!$G$2:$G$500,MATCH(1,($I11=SFReportData!$A$2:$A$500)*(V$1=SFReportData!$D$2:'SFReportData'!$D$500),0)),"")} -> 0 | W11: {=IFERROR(INDEX(SFReportData!$G$2:$G$500,MATCH(1,($I11=SFReportData!$A$2:$A$500)*(W$1=SFReportData!$D$2:'SFReportData'!$D$500),0)),"")} -> 0 | X11: {=IFERROR(INDEX(SFReportData!$G$2:$G$500,MATCH(1,($I11=SFReportData!$A$2:$A$500)*(X$1=SFReportData!$D$2:'SFReportData'!$D$500),0)),"")} -> 0 | Z11: =O11 -> 0 | AA11: =T11 -> 0 | AB11: =J11 -> 0 | AC11: =P11 -> 0 | AD11: =U11 -> 0 | AE11: =K11 -> 0 | AF11: =Q11 -> 0 | AG11: =V11 -> 0 | AH11: =L11 -> 0 | AI11: =R11 -> 0 | AJ11: =W11 -> 0 | AK11: =M11 -> 0 | AL11: =S11 -> 0 | AM11: =X11 -> 0 | AN11: =N11 -> 0
A12: {=IF(IFERROR(INDEX(SFReportData!$A$2:'SFReportData'!$A$500, MATCH(0, COUNTIF(TransformData!$A$2:'TransformData'!$A11, SFReportData!$A$2:'SFReportData'!$A$500), 0)),"") = 0,"", IFERROR(INDEX(SFReportData!$A$2:'SFReportData'!$A$500, MATCH(0, COUNTIF(TransformData!$A$2:'TransformData'!$A11, SFReportData!$A$2:'SFReportData'!$A$500), 0)),""))} | B12: =IFERROR(VLOOKUP(A12,SFReportData!$A$2:$B$500,2,0),"") | C12: =IFERROR(VLOOKUP(A12,SFReportData!$A$2:$C$500,3,0),"") | D12: {=IFERROR(INDEX(SFReportData!$D$2:'SFReportData'!$D$500, MATCH(0, COUNTIF(TransformData!$D$2:'TransformData'!$D11, SFReportData!$D$2:'SFReportData'!$D$500), 0)),"")} | E12: =IFERROR(VLOOKUP(A12,SFReportData!$A$2:$J$500,10,0),"") | F12: =IFERROR(VLOOKUP(A12,SFReportData!$A$2:$K$500,11,0),"") | H12: =IFERROR(VLOOKUP(B12,SFReportData!B11:H509,7,0),"") | I12: {=CELL("contents",A12)} | J12: {=IFERROR(INDEX(SFReportData!$E$2:$E$500,MATCH(1,($I12=SFReportData!$A$2:$A$500)*(J$1=SFReportData!$D$2:'SFReportData'!$D$500),0)),"")} -> 0 | K12: {=IFERROR(INDEX(SFReportData!$E$2:$E$500,MATCH(1,($I12=SFReportData!$A$2:$A$500)*(K$1=SFReportData!$D$2:'SFReportData'!$D$500),0)),"")} -> 0 | L12: {=IFERROR(INDEX(SFReportData!$E$2:$E$500,MATCH(1,($I12=SFReportData!$A$2:$A$500)*(L$1=SFReportData!$D$2:'SFReportData'!$D$500),0)),"")} -> 0 | M12: {=IFERROR(INDEX(SFReportData!$E$2:$E$500,MATCH(1,($I12=SFReportData!$A$2:$A$500)*(M$1=SFReportData!$D$2:'SFReportData'!$D$500),0)),"")} -> 0 | N12: {=IFERROR(INDEX(SFReportData!$E$2:$E$500,MATCH(1,($I12=SFReportData!$A$2:$A$500)*(N$1=SFReportData!$D$2:'SFReportData'!$D$500),0)),"")} -> 0 | O12: {=IFERROR(INDEX(SFReportData!$F$2:$F$500,MATCH(1,($I12=SFReportData!$A$2:$A$500)*(O$1=SFReportData!$D$2:'SFReportData'!$D$500),0)),"")} -> 0 | P12: {=IFERROR(INDEX(SFReportData!$F$2:$F$500,MATCH(1,($I12=SFReportData!$A$2:$A$500)*(P$1=SFReportData!$D$2:'SFReportData'!$D$500),0)),"")} -> 0 | Q12: {=IFERROR(INDEX(SFReportData!$F$2:$F$500,MATCH(1,($I12=SFReportData!$A$2:$A$500)*(Q$1=SFReportData!$D$2:'SFReportData'!$D$500),0)),"")} -> 0 | R12: {=IFERROR(INDEX(SFReportData!$F$2:$F$500,MATCH(1,($I12=SFReportData!$A$2:$A$500)*(R$1=SFReportData!$D$2:'SFReportData'!$D$500),0)),"")} -> 0 | S12: {=IFERROR(INDEX(SFReportData!$F$2:$F$500,MATCH(1,($I12=SFReportData!$A$2:$A$500)*(S$1=SFReportData!$D$2:'SFReportData'!$D$500),0)),"")} -> 0 | T12: {=IFERROR(INDEX(SFReportData!$G$2:$G$500,MATCH(1,($I12=SFReportData!$A$2:$A$500)*(T$1=SFReportData!$D$2:'SFReportData'!$D$500),0)),"")} -> 0 | U12: {=IFERROR(INDEX(SFReportData!$G$2:$G$500,MATCH(1,($I12=SFReportData!$A$2:$A$500)*(U$1=SFReportData!$D$2:'SFReportData'!$D$500),0)),"")} -> 0 | V12: {=IFERROR(INDEX(SFReportData!$G$2:$G$500,MATCH(1,($I12=SFReportData!$A$2:$A$500)*(V$1=SFReportData!$D$2:'SFReportData'!$D$500),0)),"")} -> 0 | W12: {=IFERROR(INDEX(SFReportData!$G$2:$G$500,MATCH(1,($I12=SFReportData!$A$2:$A$500)*(W$1=SFReportData!$D$2:'SFReportData'!$D$500),0)),"")} -> 0 | X12: {=IFERROR(INDEX(SFReportData!$G$2:$G$500,MATCH(1,($I12=SFReportData!$A$2:$A$500)*(X$1=SFReportData!$D$2:'SFReportData'!$D$500),0)),"")} -> 0 | Z12: =O12 -> 0 | AA12: =T12 -> 0 | AB12: =J12 -> 0 | AC12: =P12 -> 0 | AD12: =U12 -> 0 | AE12: =K12 -> 0 | AF12: =Q12 -> 0 | AG12: =V12 -> 0 | AH12: =L12 -> 0 | AI12: =R12 -> 0 | AJ12: =W12 -> 0 | AK12: =M12 -> 0 | AL12: =S12 -> 0 | AM12: =X12 -> 0 | AN12: =N12 -> 0
A13: {=IF(IFERROR(INDEX(SFReportData!$A$2:'SFReportData'!$A$500, MATCH(0, COUNTIF(TransformData!$A$2:'TransformData'!$A12, SFReportData!$A$2:'SFReportData'!$A$500), 0)),"") = 0,"", IFERROR(INDEX(SFReportData!$A$2:'SFReportData'!$A$500, MATCH(0, COUNTIF(TransformData!$A$2:'TransformData'!$A12, SFReportData!$A$2:'SFReportData'!$A$500), 0)),""))} | B13: =IFERROR(VLOOKUP(A13,SFReportData!$A$2:$B$500,2,0),"") | C13: =IFERROR(VLOOKUP(A13,SFReportData!$A$2:$C$500,3,0),"") | D13: {=IFERROR(INDEX(SFReportData!$D$2:'SFReportData'!$D$500, MATCH(0, COUNTIF(TransformData!$D$2:'TransformData'!$D12, SFReportData!$D$2:'SFReportData'!$D$500), 0)),"")} | E13: =IFERROR(VLOOKUP(A13,SFReportData!$A$2:$J$500,10,0),"") | F13: =IFERROR(VLOOKUP(A13,SFReportData!$A$2:$K$500,11,0),"") | H13: =IFERROR(VLOOKUP(B13,SFReportData!B12:H510,7,0),"") | I13: {=CELL("contents",A13)} | J13: {=IFERROR(INDEX(SFReportData!$E$2:$E$500,MATCH(1,($I13=SFReportData!$A$2:$A$500)*(J$1=SFReportData!$D$2:'SFReportData'!$D$500),0)),"")} -> 0 | K13: {=IFERROR(INDEX(SFReportData!$E$2:$E$500,MATCH(1,($I13=SFReportData!$A$2:$A$500)*(K$1=SFReportData!$D$2:'SFReportData'!$D$500),0)),"")} -> 0 | L13: {=IFERROR(INDEX(SFReportData!$E$2:$E$500,MATCH(1,($I13=SFReportData!$A$2:$A$500)*(L$1=SFReportData!$D$2:'SFReportData'!$D$500),0)),"")} -> 0 | M13: {=IFERROR(INDEX(SFReportData!$E$2:$E$500,MATCH(1,($I13=SFReportData!$A$2:$A$500)*(M$1=SFReportData!$D$2:'SFReportData'!$D$500),0)),"")} -> 0 | N13: {=IFERROR(INDEX(SFReportData!$E$2:$E$500,MATCH(1,($I13=SFReportData!$A$2:$A$500)*(N$1=SFReportData!$D$2:'SFReportData'!$D$500),0)),"")} -> 0 | O13: {=IFERROR(INDEX(SFReportData!$F$2:$F$500,MATCH(1,($I13=SFReportData!$A$2:$A$500)*(O$1=SFReportData!$D$2:'SFReportData'!$D$500),0)),"")} -> 0 | P13: {=IFERROR(INDEX(SFReportData!$F$2:$F$500,MATCH(1,($I13=SFReportData!$A$2:$A$500)*(P$1=SFReportData!$D$2:'SFReportData'!$D$500),0)),"")} -> 0 | Q13: {=IFERROR(INDEX(SFReportData!$F$2:$F$500,MATCH(1,($I13=SFReportData!$A$2:$A$500)*(Q$1=SFReportData!$D$2:'SFReportData'!$D$500),0)),"")} -> 0 | R13: {=IFERROR(INDEX(SFReportData!$F$2:$F$500,MATCH(1,($I13=SFReportData!$A$2:$A$500)*(R$1=SFReportData!$D$2:'SFReportData'!$D$500),0)),"")} -> 0 | S13: {=IFERROR(INDEX(SFReportData!$F$2:$F$500,MATCH(1,($I13=SFReportData!$A$2:$A$500)*(S$1=SFReportData!$D$2:'SFReportData'!$D$500),0)),"")} -> 0 | T13: {=IFERROR(INDEX(SFReportData!$G$2:$G$500,MATCH(1,($I13=SFReportData!$A$2:$A$500)*(T$1=SFReportData!$D$2:'SFReportData'!$D$500),0)),"")} -> 0 | U13: {=IFERROR(INDEX(SFReportData!$G$2:$G$500,MATCH(1,($I13=SFReportData!$A$2:$A$500)*(U$1=SFReportData!$D$2:'SFReportData'!$D$500),0)),"")} -> 0 | V13: {=IFERROR(INDEX(SFReportData!$G$2:$G$500,MATCH(1,($I13=SFReportData!$A$2:$A$500)*(V$1=SFReportData!$D$2:'SFReportData'!$D$500),0)),"")} -> 0 | W13: {=IFERROR(INDEX(SFReportData!$G$2:$G$500,MATCH(1,($I13=SFReportData!$A$2:$A$500)*(W$1=SFReportData!$D$2:'SFReportData'!$D$500),0)),"")} -> 0 | X13: {=IFERROR(INDEX(SFReportData!$G$2:$G$500,MATCH(1,($I13=SFReportData!$A$2:$A$500)*(X$1=SFReportData!$D$2:'SFReportData'!$D$500),0)),"")} -> 0 | Z13: =O13 -> 0 | AA13: =T13 -> 0 | AB13: =J13 -> 0 | AC13: =P13 -> 0 | AD13: =U13 -> 0 | AE13: =K13 -> 0 | AF13: =Q13 -> 0 | AG13: =V13 -> 0 | AH13: =L13 -> 0 | AI13: =R13 -> 0 | AJ13: =W13 -> 0 | AK13: =M13 -> 0 | AL13: =S13 -> 0 | AM13: =X13 -> 0 | AN13: =N13 -> 0
A14: {=IF(IFERROR(INDEX(SFReportData!$A$2:'SFReportData'!$A$500, MATCH(0, COUNTIF(TransformData!$A$2:'TransformData'!$A13, SFReportData!$A$2:'SFReportData'!$A$500), 0)),"") = 0,"", IFERROR(INDEX(SFReportData!$A$2:'SFReportData'!$A$500, MATCH(0, COUNTIF(TransformData!$A$2:'TransformData'!$A13, SFReportData!$A$2:'SFReportData'!$A$500), 0)),""))} | B14: =IFERROR(VLOOKUP(A14,SFReportData!$A$2:$B$500,2,0),"") | C14: =IFERROR(VLOOKUP(A14,SFReportData!$A$2:$C$500,3,0),"") | D14: {=IFERROR(INDEX(SFReportData!$D$2:'SFReportData'!$D$500, MATCH(0, COUNTIF(TransformData!$D$2:'TransformData'!$D13, SFReportData!$D$2:'SFReportData'!$D$500), 0)),"")} | E14: =IFERROR(VLOOKUP(A14,SFReportData!$A$2:$J$500,10,0),"") | F14: =IFERROR(VLOOKUP(A14,SFReportData!$A$2:$K$500,11,0),"") | H14: =IFERROR(VLOOKUP(B14,SFReportData!B13:H511,7,0),"") | I14: {=CELL("contents",A14)} | J14: {=IFERROR(INDEX(SFReportData!$E$2:$E$500,MATCH(1,($I14=SFReportData!$A$2:$A$500)*(J$1=SFReportData!$D$2:'SFReportData'!$D$500),0)),"")} -> 0 | K14: {=IFERROR(INDEX(SFReportData!$E$2:$E$500,MATCH(1,($I14=SFReportData!$A$2:$A$500)*(K$1=SFReportData!$D$2:'SFReportData'!$D$500),0)),"")} -> 0 | L14: {=IFERROR(INDEX(SFReportData!$E$2:$E$500,MATCH(1,($I14=SFReportData!$A$2:$A$500)*(L$1=SFReportData!$D$2:'SFReportData'!$D$500),0)),"")} -> 0 | M14: {=IFERROR(INDEX(SFReportData!$E$2:$E$500,MATCH(1,($I14=SFReportData!$A$2:$A$500)*(M$1=SFReportData!$D$2:'SFReportData'!$D$500),0)),"")} -> 0 | N14: {=IFERROR(INDEX(SFReportData!$E$2:$E$500,MATCH(1,($I14=SFReportData!$A$2:$A$500)*(N$1=SFReportData!$D$2:'SFReportData'!$D$500),0)),"")} -> 0 | O14: {=IFERROR(INDEX(SFReportData!$F$2:$F$500,MATCH(1,($I14=SFReportData!$A$2:$A$500)*(O$1=SFReportData!$D$2:'SFReportData'!$D$500),0)),"")} -> 0 | P14: {=IFERROR(INDEX(SFReportData!$F$2:$F$500,MATCH(1,($I14=SFReportData!$A$2:$A$500)*(P$1=SFReportData!$D$2:'SFReportData'!$D$500),0)),"")} -> 0 | Q14: {=IFERROR(INDEX(SFReportData!$F$2:$F$500,MATCH(1,($I14=SFReportData!$A$2:$A$500)*(Q$1=SFReportData!$D$2:'SFReportData'!$D$500),0)),"")} -> 0 | R14: {=IFERROR(INDEX(SFReportData!$F$2:$F$500,MATCH(1,($I14=SFReportData!$A$2:$A$500)*(R$1=SFReportData!$D$2:'SFReportData'!$D$500),0)),"")} -> 0 | S14: {=IFERROR(INDEX(SFReportData!$F$2:$F$500,MATCH(1,($I14=SFReportData!$A$2:$A$500)*(S$1=SFReportData!$D$2:'SFReportData'!$D$500),0)),"")} -> 0 | T14: {=IFERROR(INDEX(SFReportData!$G$2:$G$500,MATCH(1,($I14=SFReportData!$A$2:$A$500)*(T$1=SFReportData!$D$2:'SFReportData'!$D$500),0)),"")} -> 0 | U14: {=IFERROR(INDEX(SFReportData!$G$2:$G$500,MATCH(1,($I14=SFReportData!$A$2:$A$500)*(U$1=SFReportData!$D$2:'SFReportData'!$D$500),0)),"")} -> 0 | V14: {=IFERROR(INDEX(SFReportData!$G$2:$G$500,MATCH(1,($I14=SFReportData!$A$2:$A$500)*(V$1=SFReportData!$D$2:'SFReportData'!$D$500),0)),"")} -> 0 | W14: {=IFERROR(INDEX(SFReportData!$G$2:$G$500,MATCH(1,($I14=SFReportData!$A$2:$A$500)*(W$1=SFReportData!$D$2:'SFReportData'!$D$500),0)),"")} -> 0 | X14: {=IFERROR(INDEX(SFReportData!$G$2:$G$500,MATCH(1,($I14=SFReportData!$A$2:$A$500)*(X$1=SFReportData!$D$2:'SFReportData'!$D$500),0)),"")} -> 0 | Z14: =O14 -> 0 | AA14: =T14 -> 0 | AB14: =J14 -> 0 | AC14: =P14 -> 0 | AD14: =U14 -> 0 | AE14: =K14 -> 0 | AF14: =Q14 -> 0 | AG14: =V14 -> 0 | AH14: =L14 -> 0 | AI14: =R14 -> 0 | AJ14: =W14 -> 0 | AK14: =M14 -> 0 | AL14: =S14 -> 0 | AM14: =X14 -> 0 | AN14: =N14 -> 0
A15: {=IF(IFERROR(INDEX(SFReportData!$A$2:'SFReportData'!$A$500, MATCH(0, COUNTIF(TransformData!$A$2:'TransformData'!$A14, SFReportData!$A$2:'SFReportData'!$A$500), 0)),"") = 0,"", IFERROR(INDEX(SFReportData!$A$2:'SFReportData'!$A$500, MATCH(0, COUNTIF(TransformData!$A$2:'TransformData'!$A14, SFReportData!$A$2:'SFReportData'!$A$500), 0)),""))} | B15: =IFERROR(VLOOKUP(A15,SFReportData!$A$2:$B$500,2,0),"") | C15: =IFERROR(VLOOKUP(A15,SFReportData!$A$2:$C$500,3,0),"") | D15: {=IFERROR(INDEX(SFReportData!$D$2:'SFReportData'!$D$500, MATCH(0, COUNTIF(TransformData!$D$2:'TransformData'!$D14, SFReportData!$D$2:'SFReportData'!$D$500), 0)),"")} | E15: =IFERROR(VLOOKUP(A15,SFReportData!$A$2:$J$500,10,0),"") | F15: =IFERROR(VLOOKUP(A15,SFReportData!$A$2:$K$500,11,0),"") | H15: =IFERROR(VLOOKUP(B15,SFReportData!B14:H512,7,0),"") | I15: {=CELL("contents",A15)} | J15: {=IFERROR(INDEX(SFReportData!$E$2:$E$500,MATCH(1,($I15=SFReportData!$A$2:$A$500)*(J$1=SFReportData!$D$2:'SFReportData'!$D$500),0)),"")} -> 0 | K15: {=IFERROR(INDEX(SFReportData!$E$2:$E$500,MATCH(1,($I15=SFReportData!$A$2:$A$500)*(K$1=SFReportData!$D$2:'SFReportData'!$D$500),0)),"")} -> 0 | L15: {=IFERROR(INDEX(SFReportData!$E$2:$E$500,MATCH(1,($I15=SFReportData!$A$2:$A$500)*(L$1=SFReportData!$D$2:'SFReportData'!$D$500),0)),"")} -> 0 | M15: {=IFERROR(INDEX(SFReportData!$E$2:$E$500,MATCH(1,($I15=SFReportData!$A$2:$A$500)*(M$1=SFReportData!$D$2:'SFReportData'!$D$500),0)),"")} -> 0 | N15: {=IFERROR(INDEX(SFReportData!$E$2:$E$500,MATCH(1,($I15=SFReportData!$A$2:$A$500)*(N$1=SFReportData!$D$2:'SFReportData'!$D$500),0)),"")} -> 0 | O15: {=IFERROR(INDEX(SFReportData!$F$2:$F$500,MATCH(1,($I15=SFReportData!$A$2:$A$500)*(O$1=SFReportData!$D$2:'SFReportData'!$D$500),0)),"")} -> 0 | P15: {=IFERROR(INDEX(SFReportData!$F$2:$F$500,MATCH(1,($I15=SFReportData!$A$2:$A$500)*(P$1=SFReportData!$D$2:'SFReportData'!$D$500),0)),"")} -> 0 | Q15: {=IFERROR(INDEX(SFReportData!$F$2:$F$500,MATCH(1,($I15=SFReportData!$A$2:$A$500)*(Q$1=SFReportData!$D$2:'SFReportData'!$D$500),0)),"")} -> 0 | R15: {=IFERROR(INDEX(SFReportData!$F$2:$F$500,MATCH(1,($I15=SFReportData!$A$2:$A$500)*(R$1=SFReportData!$D$2:'SFReportData'!$D$500),0)),"")} -> 0 | S15: {=IFERROR(INDEX(SFReportData!$F$2:$F$500,MATCH(1,($I15=SFReportData!$A$2:$A$500)*(S$1=SFReportData!$D$2:'SFReportData'!$D$500),0)),"")} -> 0 | T15: {=IFERROR(INDEX(SFReportData!$G$2:$G$500,MATCH(1,($I15=SFReportData!$A$2:$A$500)*(T$1=SFReportData!$D$2:'SFReportData'!$D$500),0)),"")} -> 0 | U15: {=IFERROR(INDEX(SFReportData!$G$2:$G$500,MATCH(1,($I15=SFReportData!$A$2:$A$500)*(U$1=SFReportData!$D$2:'SFReportData'!$D$500),0)),"")} -> 0 | V15: {=IFERROR(INDEX(SFReportData!$G$2:$G$500,MATCH(1,($I15=SFReportData!$A$2:$A$500)*(V$1=SFReportData!$D$2:'SFReportData'!$D$500),0)),"")} -> 0 | W15: {=IFERROR(INDEX(SFReportData!$G$2:$G$500,MATCH(1,($I15=SFReportData!$A$2:$A$500)*(W$1=SFReportData!$D$2:'SFReportData'!$D$500),0)),"")} -> 0 | X15: {=IFERROR(INDEX(SFReportData!$G$2:$G$500,MATCH(1,($I15=SFReportData!$A$2:$A$500)*(X$1=SFReportData!$D$2:'SFReportData'!$D$500),0)),"")} -> 0 | Z15: =O15 -> 0 | AA15: =T15 -> 0 | AB15: =J15 -> 0 | AC15: =P15 -> 0 | AD15: =U15 -> 0 | AE15: =K15 -> 0 | AF15: =Q15 -> 0 | AG15: =V15 -> 0 | AH15: =L15 -> 0 | AI15: =R15 -> 0 | AJ15: =W15 -> 0 | AK15: =M15 -> 0 | AL15: =S15 -> 0 | AM15: =X15 -> 0 | AN15: =N15 -> 0
... A50: {=IF(IFERROR(INDEX(SFReportData!$A$2:'SFReportData'!$A$500, MATCH(0, COUNTIF(TransformData!$A$2:'TransformData'!$A49, SFReportData!$A$2:'SFReportData'!$A$500), 0)),"") = 0,"", IFERROR(INDEX(SFReportData!$A$2:'SFReportData'!$A$500, MATCH(0, COUNTIF(TransformData!$A$2:'TransformData'!$A49, SFReportData!$A$2:'SFReportData'!$A$500), 0)),""))} | B50: =IFERROR(VLOOKUP(A50,SFReportData!$A$2:$B$500,2,0),"") | C50: =IFERROR(VLOOKUP(A50,SFReportData!$A$2:$C$500,3,0),"") | D50: {=IFERROR(INDEX(SFReportData!$D$2:'SFReportData'!$D$500, MATCH(0, COUNTIF(TransformData!$D$2:'TransformData'!$D49, SFReportData!$D$2:'SFReportData'!$D$500), 0)),"")} | E50: =IFERROR(VLOOKUP(A50,SFReportData!$A$2:$J$500,10,0),"") | F50: =IFERROR(VLOOKUP(A50,SFReportData!$A$2:$K$500,11,0),"") | H50: =IFERROR(VLOOKUP(B50,SFReportData!B49:H547,7,0),"") | I50: {=CELL("contents",A50)} | J50: {=IFERROR(INDEX(SFReportData!$E$2:$E$500,MATCH(1,($I50=SFReportData!$A$2:$A$500)*(J$1=SFReportData!$D$2:'SFReportData'!$D$500),0)),"")} -> 0 | K50: {=IFERROR(INDEX(SFReportData!$E$2:$E$500,MATCH(1,($I50=SFReportData!$A$2:$A$500)*(K$1=SFReportData!$D$2:'SFReportData'!$D$500),0)),"")} -> 0 | L50: {=IFERROR(INDEX(SFReportData!$E$2:$E$500,MATCH(1,($I50=SFReportData!$A$2:$A$500)*(L$1=SFReportData!$D$2:'SFReportData'!$D$500),0)),"")} -> 0 | M50: {=IFERROR(INDEX(SFReportData!$E$2:$E$500,MATCH(1,($I50=SFReportData!$A$2:$A$500)*(M$1=SFReportData!$D$2:'SFReportData'!$D$500),0)),"")} -> 0 | N50: {=IFERROR(INDEX(SFReportData!$E$2:$E$500,MATCH(1,($I50=SFReportData!$A$2:$A$500)*(N$1=SFReportData!$D$2:'SFReportData'!$D$500),0)),"")} -> 0 | O50: {=IFERROR(INDEX(SFReportData!$F$2:$F$500,MATCH(1,($I50=SFReportData!$A$2:$A$500)*(O$1=SFReportData!$D$2:'SFReportData'!$D$500),0)),"")} -> 0 | P50: {=IFERROR(INDEX(SFReportData!$F$2:$F$500,MATCH(1,($I50=SFReportData!$A$2:$A$500)*(P$1=SFReportData!$D$2:'SFReportData'!$D$500),0)),"")} -> 0 | Q50: {=IFERROR(INDEX(SFReportData!$F$2:$F$500,MATCH(1,($I50=SFReportData!$A$2:$A$500)*(Q$1=SFReportData!$D$2:'SFReportData'!$D$500),0)),"")} -> 0 | R50: {=IFERROR(INDEX(SFReportData!$F$2:$F$500,MATCH(1,($I50=SFReportData!$A$2:$A$500)*(R$1=SFReportData!$D$2:'SFReportData'!$D$500),0)),"")} -> 0 | S50: {=IFERROR(INDEX(SFReportData!$F$2:$F$500,MATCH(1,($I50=SFReportData!$A$2:$A$500)*(S$1=SFReportData!$D$2:'SFReportData'!$D$500),0)),"")} -> 0 | T50: {=IFERROR(INDEX(SFReportData!$G$2:$G$500,MATCH(1,($I50=SFReportData!$A$2:$A$500)*(T$1=SFReportData!$D$2:'SFReportData'!$D$500),0)),"")} -> 0 | U50: {=IFERROR(INDEX(SFReportData!$G$2:$G$500,MATCH(1,($I50=SFReportData!$A$2:$A$500)*(U$1=SFReportData!$D$2:'SFReportData'!$D$500),0)),"")} -> 0 | V50: {=IFERROR(INDEX(SFReportData!$G$2:$G$500,MATCH(1,($I50=SFReportData!$A$2:$A$500)*(V$1=SFReportData!$D$2:'SFReportData'!$D$500),0)),"")} -> 0 | W50: {=IFERROR(INDEX(SFReportData!$G$2:$G$500,MATCH(1,($I50=SFReportData!$A$2:$A$500)*(W$1=SFReportData!$D$2:'SFReportData'!$D$500),0)),"")} -> 0 | X50: {=IFERROR(INDEX(SFReportData!$G$2:$G$500,MATCH(1,($I50=SFReportData!$A$2:$A$500)*(X$1=SFReportData!$D$2:'SFReportData'!$D$500),0)),"")} -> 0 | Z50: =O50 -> 0 | AA50: =T50 -> 0 | AB50: =J50 -> 0 | AC50: =P50 -> 0 | AD50: =U50 -> 0 | AE50: =K50 -> 0 | AF50: =Q50 -> 0 | AG50: =V50 -> 0 | AH50: =L50 -> 0 | AI50: =R50 -> 0 | AJ50: =W50 -> 0 | AK50: =M50 -> 0 | AL50: =S50 -> 0 | AM50: =X50 -> 0 | AN50: =N50 -> 0
A51: {=IF(IFERROR(INDEX(SFReportData!$A$2:'SFReportData'!$A$500, MATCH(0, COUNTIF(TransformData!$A$2:'TransformData'!$A50, SFReportData!$A$2:'SFReportData'!$A$500), 0)),"") = 0,"", IFERROR(INDEX(SFReportData!$A$2:'SFReportData'!$A$500, MATCH(0, COUNTIF(TransformData!$A$2:'TransformData'!$A50, SFReportData!$A$2:'SFReportData'!$A$500), 0)),""))} | B51: =IFERROR(VLOOKUP(A51,SFReportData!$A$2:$B$500,2,0),"") | C51: =IFERROR(VLOOKUP(A51,SFReportData!$A$2:$C$500,3,0),"") | E51: =IFERROR(VLOOKUP(A51,SFReportData!$A$2:$J$500,10,0),"") | F51: =IFERROR(VLOOKUP(A51,SFReportData!$A$2:$K$500,11,0),"") | H51: =IFERROR(VLOOKUP(B51,SFReportData!B50:H548,7,0),"") | I51: {=CELL("contents",A51)} | J51: {=IFERROR(INDEX(SFReportData!$E$2:$E$500,MATCH(1,($I51=SFReportData!$A$2:$A$500)*(J$1=SFReportData!$D$2:'SFReportData'!$D$500),0)),"")} -> 0 | K51: {=IFERROR(INDEX(SFReportData!$E$2:$E$500,MATCH(1,($I51=SFReportData!$A$2:$A$500)*(K$1=SFReportData!$D$2:'SFReportData'!$D$500),0)),"")} -> 0 | L51: {=IFERROR(INDEX(SFReportData!$E$2:$E$500,MATCH(1,($I51=SFReportData!$A$2:$A$500)*(L$1=SFReportData!$D$2:'SFReportData'!$D$500),0)),"")} -> 0 | M51: {=IFERROR(INDEX(SFReportData!$E$2:$E$500,MATCH(1,($I51=SFReportData!$A$2:$A$500)*(M$1=SFReportData!$D$2:'SFReportData'!$D$500),0)),"")} -> 0 | N51: {=IFERROR(INDEX(SFReportData!$E$2:$E$500,MATCH(1,($I51=SFReportData!$A$2:$A$500)*(N$1=SFReportData!$D$2:'SFReportData'!$D$500),0)),"")} -> 0 | O51: {=IFERROR(INDEX(SFReportData!$F$2:$F$500,MATCH(1,($I51=SFReportData!$A$2:$A$500)*(O$1=SFReportData!$D$2:'SFReportData'!$D$500),0)),"")} -> 0 | P51: {=IFERROR(INDEX(SFReportData!$F$2:$F$500,MATCH(1,($I51=SFReportData!$A$2:$A$500)*(P$1=SFReportData!$D$2:'SFReportData'!$D$500),0)),"")} -> 0 | Q51: {=IFERROR(INDEX(SFReportData!$F$2:$F$500,MATCH(1,($I51=SFReportData!$A$2:$A$500)*(Q$1=SFReportData!$D$2:'SFReportData'!$D$500),0)),"")} -> 0 | R51: {=IFERROR(INDEX(SFReportData!$F$2:$F$500,MATCH(1,($I51=SFReportData!$A$2:$A$500)*(R$1=SFReportData!$D$2:'SFReportData'!$D$500),0)),"")} -> 0 | S51: {=IFERROR(INDEX(SFReportData!$F$2:$F$500,MATCH(1,($I51=SFReportData!$A$2:$A$500)*(S$1=SFReportData!$D$2:'SFReportData'!$D$500),0)),"")} -> 0 | T51: {=IFERROR(INDEX(SFReportData!$G$2:$G$500,MATCH(1,($I51=SFReportData!$A$2:$A$500)*(T$1=SFReportData!$D$2:'SFReportData'!$D$500),0)),"")} -> 0 | U51: {=IFERROR(INDEX(SFReportData!$G$2:$G$500,MATCH(1,($I51=SFReportData!$A$2:$A$500)*(U$1=SFReportData!$D$2:'SFReportData'!$D$500),0)),"")} -> 0 | V51: {=IFERROR(INDEX(SFReportData!$G$2:$G$500,MATCH(1,($I51=SFReportData!$A$2:$A$500)*(V$1=SFReportData!$D$2:'SFReportData'!$D$500),0)),"")} -> 0 | W51: {=IFERROR(INDEX(SFReportData!$G$2:$G$500,MATCH(1,($I51=SFReportData!$A$2:$A$500)*(W$1=SFReportData!$D$2:'SFReportData'!$D$500),0)),"")} -> 0 | X51: {=IFERROR(INDEX(SFReportData!$G$2:$G$500,MATCH(1,($I51=SFReportData!$A$2:$A$500)*(X$1=SFReportData!$D$2:'SFReportData'!$D$500),0)),"")} -> 0 | Z51: =O51 -> 0 | AA51: =T51 -> 0 | AB51: =J51 -> 0 | AC51: =P51 -> 0 | AD51: =U51 -> 0 | AE51: =K51 -> 0 | AF51: =Q51 -> 0 | AG51: =V51 -> 0 | AH51: =L51 -> 0 | AI51: =R51 -> 0 | AJ51: =W51 -> 0 | AK51: =M51 -> 0 | AL51: =S51 -> 0 | AM51: =X51 -> 0 | AN51: =N51 -> 0
A52: {=IF(IFERROR(INDEX(SFReportData!$A$2:'SFReportData'!$A$500, MATCH(0, COUNTIF(TransformData!$A$2:'TransformData'!$A51, SFReportData!$A$2:'SFReportData'!$A$500), 0)),"") = 0,"", IFERROR(INDEX(SFReportData!$A$2:'SFReportData'!$A$500, MATCH(0, COUNTIF(TransformData!$A$2:'TransformData'!$A51, SFReportData!$A$2:'SFReportData'!$A$500), 0)),""))} | B52: =IFERROR(VLOOKUP(A52,SFReportData!$A$2:$B$500,2,0),"") | C52: =IFERROR(VLOOKUP(A52,SFReportData!$A$2:$C$500,3,0),"") | E52: =IFERROR(VLOOKUP(A52,SFReportData!$A$2:$J$500,10,0),"") | F52: =IFERROR(VLOOKUP(A52,SFReportData!$A$2:$K$500,11,0),"") | H52: =IFERROR(VLOOKUP(B52,SFReportData!B51:H549,7,0),"") | I52: {=CELL("contents",A52)} | J52: {=IFERROR(INDEX(SFReportData!$E$2:$E$500,MATCH(1,($I52=SFReportData!$A$2:$A$500)*(J$1=SFReportData!$D$2:'SFReportData'!$D$500),0)),"")} -> 0 | K52: {=IFERROR(INDEX(SFReportData!$E$2:$E$500,MATCH(1,($I52=SFReportData!$A$2:$A$500)*(K$1=SFReportData!$D$2:'SFReportData'!$D$500),0)),"")} -> 0 | L52: {=IFERROR(INDEX(SFReportData!$E$2:$E$500,MATCH(1,($I52=SFReportData!$A$2:$A$500)*(L$1=SFReportData!$D$2:'SFReportData'!$D$500),0)),"")} -> 0 | M52: {=IFERROR(INDEX(SFReportData!$E$2:$E$500,MATCH(1,($I52=SFReportData!$A$2:$A$500)*(M$1=SFReportData!$D$2:'SFReportData'!$D$500),0)),"")} -> 0 | N52: {=IFERROR(INDEX(SFReportData!$E$2:$E$500,MATCH(1,($I52=SFReportData!$A$2:$A$500)*(N$1=SFReportData!$D$2:'SFReportData'!$D$500),0)),"")} -> 0 | O52: {=IFERROR(INDEX(SFReportData!$F$2:$F$500,MATCH(1,($I52=SFReportData!$A$2:$A$500)*(O$1=SFReportData!$D$2:'SFReportData'!$D$500),0)),"")} -> 0 | P52: {=IFERROR(INDEX(SFReportData!$F$2:$F$500,MATCH(1,($I52=SFReportData!$A$2:$A$500)*(P$1=SFReportData!$D$2:'SFReportData'!$D$500),0)),"")} -> 0 | Q52: {=IFERROR(INDEX(SFReportData!$F$2:$F$500,MATCH(1,($I52=SFReportData!$A$2:$A$500)*(Q$1=SFReportData!$D$2:'SFReportData'!$D$500),0)),"")} -> 0 | R52: {=IFERROR(INDEX(SFReportData!$F$2:$F$500,MATCH(1,($I52=SFReportData!$A$2:$A$500)*(R$1=SFReportData!$D$2:'SFReportData'!$D$500),0)),"")} -> 0 | S52: {=IFERROR(INDEX(SFReportData!$F$2:$F$500,MATCH(1,($I52=SFReportData!$A$2:$A$500)*(S$1=SFReportData!$D$2:'SFReportData'!$D$500),0)),"")} -> 0 | T52: {=IFERROR(INDEX(SFReportData!$G$2:$G$500,MATCH(1,($I52=SFReportData!$A$2:$A$500)*(T$1=SFReportData!$D$2:'SFReportData'!$D$500),0)),"")} -> 0 | U52: {=IFERROR(INDEX(SFReportData!$G$2:$G$500,MATCH(1,($I52=SFReportData!$A$2:$A$500)*(U$1=SFReportData!$D$2:'SFReportData'!$D$500),0)),"")} -> 0 | V52: {=IFERROR(INDEX(SFReportData!$G$2:$G$500,MATCH(1,($I52=SFReportData!$A$2:$A$500)*(V$1=SFReportData!$D$2:'SFReportData'!$D$500),0)),"")} -> 0 | W52: {=IFERROR(INDEX(SFReportData!$G$2:$G$500,MATCH(1,($I52=SFReportData!$A$2:$A$500)*(W$1=SFReportData!$D$2:'SFReportData'!$D$500),0)),"")} -> 0 | X52: {=IFERROR(INDEX(SFReportData!$G$2:$G$500,MATCH(1,($I52=SFReportData!$A$2:$A$500)*(X$1=SFReportData!$D$2:'SFReportData'!$D$500),0)),"")} -> 0 | Z52: =O52 -> 0 | AA52: =T52 -> 0 | AB52: =J52 -> 0 | AC52: =P52 -> 0 | AD52: =U52 -> 0 | AE52: =K52 -> 0 | AF52: =Q52 -> 0 | AG52: =V52 -> 0 | AH52: =L52 -> 0 | AI52: =R52 -> 0 | AJ52: =W52 -> 0 | AK52: =M52 -> 0 | AL52: =S52 -> 0 | AM52: =X52 -> 0 | AN52: =N52 -> 0
A53: {=IF(IFERROR(INDEX(SFReportData!$A$2:'SFReportData'!$A$500, MATCH(0, COUNTIF(TransformData!$A$2:'TransformData'!$A52, SFReportData!$A$2:'SFReportData'!$A$500), 0)),"") = 0,"", IFERROR(INDEX(SFReportData!$A$2:'SFReportData'!$A$500, MATCH(0, COUNTIF(TransformData!$A$2:'TransformData'!$A52, SFReportData!$A$2:'SFReportData'!$A$500), 0)),""))} | B53: =IFERROR(VLOOKUP(A53,SFReportData!$A$2:$B$500,2,0),"") | C53: =IFERROR(VLOOKUP(A53,SFReportData!$A$2:$C$500,3,0),"") | E53: =IFERROR(VLOOKUP(A53,SFReportData!$A$2:$J$500,10,0),"") | F53: =IFERROR(VLOOKUP(A53,SFReportData!$A$2:$K$500,11,0),"") | H53: =IFERROR(VLOOKUP(B53,SFReportData!B52:H550,7,0),"") | I53: {=CELL("contents",A53)} | J53: {=IFERROR(INDEX(SFReportData!$E$2:$E$500,MATCH(1,($I53=SFReportData!$A$2:$A$500)*(J$1=SFReportData!$D$2:'SFReportData'!$D$500),0)),"")} -> 0 | K53: {=IFERROR(INDEX(SFReportData!$E$2:$E$500,MATCH(1,($I53=SFReportData!$A$2:$A$500)*(K$1=SFReportData!$D$2:'SFReportData'!$D$500),0)),"")} -> 0 | L53: {=IFERROR(INDEX(SFReportData!$E$2:$E$500,MATCH(1,($I53=SFReportData!$A$2:$A$500)*(L$1=SFReportData!$D$2:'SFReportData'!$D$500),0)),"")} -> 0 | M53: {=IFERROR(INDEX(SFReportData!$E$2:$E$500,MATCH(1,($I53=SFReportData!$A$2:$A$500)*(M$1=SFReportData!$D$2:'SFReportData'!$D$500),0)),"")} -> 0 | N53: {=IFERROR(INDEX(SFReportData!$E$2:$E$500,MATCH(1,($I53=SFReportData!$A$2:$A$500)*(N$1=SFReportData!$D$2:'SFReportData'!$D$500),0)),"")} -> 0 | O53: {=IFERROR(INDEX(SFReportData!$F$2:$F$500,MATCH(1,($I53=SFReportData!$A$2:$A$500)*(O$1=SFReportData!$D$2:'SFReportData'!$D$500),0)),"")} -> 0 | P53: {=IFERROR(INDEX(SFReportData!$F$2:$F$500,MATCH(1,($I53=SFReportData!$A$2:$A$500)*(P$1=SFReportData!$D$2:'SFReportData'!$D$500),0)),"")} -> 0 | Q53: {=IFERROR(INDEX(SFReportData!$F$2:$F$500,MATCH(1,($I53=SFReportData!$A$2:$A$500)*(Q$1=SFReportData!$D$2:'SFReportData'!$D$500),0)),"")} -> 0 | R53: {=IFERROR(INDEX(SFReportData!$F$2:$F$500,MATCH(1,($I53=SFReportData!$A$2:$A$500)*(R$1=SFReportData!$D$2:'SFReportData'!$D$500),0)),"")} -> 0 | S53: {=IFERROR(INDEX(SFReportData!$F$2:$F$500,MATCH(1,($I53=SFReportData!$A$2:$A$500)*(S$1=SFReportData!$D$2:'SFReportData'!$D$500),0)),"")} -> 0 | T53: {=IFERROR(INDEX(SFReportData!$G$2:$G$500,MATCH(1,($I53=SFReportData!$A$2:$A$500)*(T$1=SFReportData!$D$2:'SFReportData'!$D$500),0)),"")} -> 0 | U53: {=IFERROR(INDEX(SFReportData!$G$2:$G$500,MATCH(1,($I53=SFReportData!$A$2:$A$500)*(U$1=SFReportData!$D$2:'SFReportData'!$D$500),0)),"")} -> 0 | V53: {=IFERROR(INDEX(SFReportData!$G$2:$G$500,MATCH(1,($I53=SFReportData!$A$2:$A$500)*(V$1=SFReportData!$D$2:'SFReportData'!$D$500),0)),"")} -> 0 | W53: {=IFERROR(INDEX(SFReportData!$G$2:$G$500,MATCH(1,($I53=SFReportData!$A$2:$A$500)*(W$1=SFReportData!$D$2:'SFReportData'!$D$500),0)),"")} -> 0 | X53: {=IFERROR(INDEX(SFReportData!$G$2:$G$500,MATCH(1,($I53=SFReportData!$A$2:$A$500)*(X$1=SFReportData!$D$2:'SFReportData'!$D$500),0)),"")} -> 0 | Z53: =O53 -> 0 | AA53: =T53 -> 0 | AB53: =J53 -> 0 | AC53: =P53 -> 0 | AD53: =U53 -> 0 | AE53: =K53 -> 0 | AF53: =Q53 -> 0 | AG53: =V53 -> 0 | AH53: =L53 -> 0 | AI53: =R53 -> 0 | AJ53: =W53 -> 0 | AK53: =M53 -> 0 | AL53: =S53 -> 0 | AM53: =X53 -> 0 | AN53: =N53 -> 0
