Workbook
Name MassTableRange: 'Final Data'!$A$4:$I$9
Name No_of_Periods: DataTransformation!$AB$3
Name Period_1: 'Final Data'!$B$3
Name Period_2: 'Final Data'!$D$3
Name Period_3: 'Final Data'!$F$3
Name Period_4: 'Final Data'!$H$3
Name Spec_Mass_and_Balance_Period: SalesforceData!$B$2
Name Spec_Mass_and_Balance_Start: SalesforceData!$A$2:$F$2
Name Spec_Mass_and_Balance_Unit: SalesforceData!$C$2
Name Spec_Mass_and_Balance_Unit_Alt: SalesforceData!$E$2
Name Spec_Mass_and_Balance_Weight: SalesforceData!$D$2
Name Spec_Mass_and_Balance_Weight_Alt: SalesforceData!$F$2
Name Spec_Mass_and_Balance_Weight_Type: SalesforceData!$A$2
Name Weight_Table_Data: 'Final Preview Data'!$A$4:$I$50
Name WeightAltUnit_1: 'Final Data'!$C$4
Name WeightAltUnit_2: 'Final Data'!$E$4
Name WeightAltUnit_3: 'Final Data'!$G$4
Name WeightAltUnit_4: 'Final Data'!$I$4
Name WeightUnit_1: 'Final Data'!$B$4
Name WeightUnit_2: 'Final Data'!$D$4
Name WeightUnit_3: 'Final Data'!$F$4
Name WeightUnit_4: 'Final Data'!$H$4

Sheet SalesforceData
A1: Weight Type | B1: Period | C1: Unit | D1: Weight | E1: Unit Alternative | F1: Weight Alternative

Sheet DataTransformation
A1: Unique Data
A2: Weight Type | B2: Period | E2: Transformed Data | H2: {=TRANSPOSE(C3:C10)} | Q2: Formatted Data | S2: {=IF(CELL("contents",G2)=0,"",CELL("contents",G2))} | T2: {=IF(CELL("contents",H2)=0,"",CELL("contents",H2))} | U2: {=IF(CELL("contents",I2)=0,"",CELL("contents",I2))} | V2: {=IF(CELL("contents",J2)=0,"",CELL("contents",J2))} | W2: {=IF(CELL("contents",K2)=0,"",CELL("contents",K2))} | X2: {=IF(CELL("contents",L2)=0,"",CELL("contents",L2))} | Y2: {=IF(CELL("contents",M2)=0,"",CELL("contents",M2))} | Z2: {=IF(CELL("contents",N2)=0,"",CELL("contents",N2))} | AA2: {=IF(CELL("contents",O2)=0,"",CELL("contents",O2))} | AB2: # of Periods
A3: {=IF(IFERROR(INDEX(SalesforceData!$A$2:'SalesforceData'!$A$36, MATCH(0, COUNTIF(DataTransformation!$A$2:'DataTransformation'!$A2, SalesforceData!$A$2:'SalesforceData'!$A$36), 0)),"") = 0,"", IFERROR(INDEX(SalesforceData!$A$2:'SalesforceData'!$A$36, MATCH(0, COUNTIF(DataTransformation!$A$2:'DataTransformation'!$A2, SalesforceData!$A$2:'SalesforceData'!$A$36), 0)),""))} | B3: {=IF(IFERROR(INDEX(SalesforceData!$B$2:'SalesforceData'!$B$36, MATCH(0, COUNTIF(DataTransformation!$B$2:'DataTransformation'!$B2, SalesforceData!$B$2:'SalesforceData'!$B$36), 0)),"") = 0,"", IFERROR(INDEX(SalesforceData!$B$2:'SalesforceData'!$B$36, MATCH(0, COUNTIF(DataTransformation!$B$2:'DataTransformation'!$B2, SalesforceData!$B$2:'SalesforceData'!$B$36), 0)),""))} | C3: =B3 | D3: =IF(LEN(C3)>0,"kg","") | H3: {=TRANSPOSE(D3:D10)} | S3: {=IF(CELL("contents",G3)=0,"",CELL("contents",G3))} | T3: {=IF(CELL("contents",H3)=0,"",CELL("contents",H3))} | U3: {=IF(CELL("contents",I3)=0,"",CELL("contents",I3))} | V3: {=IF(CELL("contents",J3)=0,"",CELL("contents",J3))} | W3: {=IF(CELL("contents",K3)=0,"",CELL("contents",K3))} | X3: {=IF(CELL("contents",L3)=0,"",CELL("contents",L3))} | Y3: {=IF(CELL("contents",M3)=0,"",CELL("contents",M3))} | Z3: {=IF(CELL("contents",N3)=0,"",CELL("contents",N3))} | AA3: {=IF(CELL("contents",O3)=0,"",CELL("contents",O3))} | AB3: =COUNTIF(B3:B7,">""") -> 0
A4: {=IF(IFERROR(INDEX(SalesforceData!$A$2:'SalesforceData'!$A$36, MATCH(0, COUNTIF(DataTransformation!$A$2:'DataTransformation'!$A3, SalesforceData!$A$2:'SalesforceData'!$A$36), 0)),"") = 0,"", IFERROR(INDEX(SalesforceData!$A$2:'SalesforceData'!$A$36, MATCH(0, COUNTIF(DataTransformation!$A$2:'DataTransformation'!$A3, SalesforceData!$A$2:'SalesforceData'!$A$36), 0)),""))} | B4: {=IF(IFERROR(INDEX(SalesforceData!$B$2:'SalesforceData'!$B$36, MATCH(0, COUNTIF(DataTransformation!$B$2:'DataTransformation'!$B3, SalesforceData!$B$2:'SalesforceData'!$B$36), 0)),"") = 0,"", IFERROR(INDEX(SalesforceData!$B$2:'SalesforceData'!$B$36, MATCH(0, COUNTIF(DataTransformation!$B$2:'DataTransformation'!$B3, SalesforceData!$B$2:'SalesforceData'!$B$36), 0)),""))} | C4: =C3 | D4: =IF(LEN(C4)>0,"lbs","") | G4: =A3 | H4: {=IFERROR(IF(COUNT(INDEX(SalesforceData!$D$2:$D$36,MATCH(1,($G4=SalesforceData!$A$2:$A$36)*(H$2=SalesforceData!$B$2:'SalesforceData'!$B$36)*(H$3=SalesforceData!$C$2:'SalesforceData'!$C$36),0)))=0,INDEX(SalesforceData!$F$2:$F$36,MATCH(1,($G4=SalesforceData!$A$2:$A$36)*(H$2=SalesforceData!$B$2:'SalesforceData'!$B$36) * (H$3=SalesforceData!$E$2:'SalesforceData'!$E$36),0)),INDEX(SalesforceData!$D$2:$D$36,MATCH(1,($G4=SalesforceData!$A$2:$A$36)*(H$2=SalesforceData!$B$2:'SalesforceData'!$B$36)*(H$3=SalesforceData!$C$2:'SalesforceData'!$C$36),0))),"")} -> 0 | I4: {=IFERROR(IF(COUNT(INDEX(SalesforceData!$D$2:$D$36,MATCH(1,($G4=SalesforceData!$A$2:$A$36)*(I$2=SalesforceData!$B$2:'SalesforceData'!$B$36)*(I$3=SalesforceData!$C$2:'SalesforceData'!$C$36),0)))=0,INDEX(SalesforceData!$F$2:$F$36,MATCH(1,($G4=SalesforceData!$A$2:$A$36)*(I$2=SalesforceData!$B$2:'SalesforceData'!$B$36) * (I$3=SalesforceData!$E$2:'SalesforceData'!$E$36),0)),INDEX(SalesforceData!$D$2:$D$36,MATCH(1,($G4=SalesforceData!$A$2:$A$36)*(I$2=SalesforceData!$B$2:'SalesforceData'!$B$36)*(I$3=SalesforceData!$C$2:'SalesforceData'!$C$36),0))),"")} -> 0 | J4: {=IFERROR(IF(COUNT(INDEX(SalesforceData!$D$2:$D$36,MATCH(1,($G4=SalesforceData!$A$2:$A$36)*(J$2=SalesforceData!$B$2:'SalesforceData'!$B$36)*(J$3=SalesforceData!$C$2:'SalesforceData'!$C$36),0)))=0,INDEX(SalesforceData!$F$2:$F$36,MATCH(1,($G4=SalesforceData!$A$2:$A$36)*(J$2=SalesforceData!$B$2:'SalesforceData'!$B$36) * (J$3=SalesforceData!$E$2:'SalesforceData'!$E$36),0)),INDEX(SalesforceData!$D$2:$D$36,MATCH(1,($G4=SalesforceData!$A$2:$A$36)*(J$2=SalesforceData!$B$2:'SalesforceData'!$B$36)*(J$3=SalesforceData!$C$2:'SalesforceData'!$C$36),0))),"")} -> 0 | K4: {=IFERROR(IF(COUNT(INDEX(SalesforceData!$D$2:$D$36,MATCH(1,($G4=SalesforceData!$A$2:$A$36)*(K$2=SalesforceData!$B$2:'SalesforceData'!$B$36)*(K$3=SalesforceData!$C$2:'SalesforceData'!$C$36),0)))=0,INDEX(SalesforceData!$F$2:$F$36,MATCH(1,($G4=SalesforceData!$A$2:$A$36)*(K$2=SalesforceData!$B$2:'SalesforceData'!$B$36) * (K$3=SalesforceData!$E$2:'SalesforceData'!$E$36),0)),INDEX(SalesforceData!$D$2:$D$36,MATCH(1,($G4=SalesforceData!$A$2:$A$36)*(K$2=SalesforceData!$B$2:'SalesforceData'!$B$36)*(K$3=SalesforceData!$C$2:'SalesforceData'!$C$36),0))),"")} -> 0 | L4: {=IFERROR(IF(COUNT(INDEX(SalesforceData!$D$2:$D$36,MATCH(1,($G4=SalesforceData!$A$2:$A$36)*(L$2=SalesforceData!$B$2:'SalesforceData'!$B$36)*(L$3=SalesforceData!$C$2:'SalesforceData'!$C$36),0)))=0,INDEX(SalesforceData!$F$2:$F$36,MATCH(1,($G4=SalesforceData!$A$2:$A$36)*(L$2=SalesforceData!$B$2:'SalesforceData'!$B$36) * (L$3=SalesforceData!$E$2:'SalesforceData'!$E$36),0)),INDEX(SalesforceData!$D$2:$D$36,MATCH(1,($G4=SalesforceData!$A$2:$A$36)*(L$2=SalesforceData!$B$2:'SalesforceData'!$B$36)*(L$3=SalesforceData!$C$2:'SalesforceData'!$C$36),0))),"")} -> 0 | M4: {=IFERROR(IF(COUNT(INDEX(SalesforceData!$D$2:$D$36,MATCH(1,($G4=SalesforceData!$A$2:$A$36)*(M$2=SalesforceData!$B$2:'SalesforceData'!$B$36)*(M$3=SalesforceData!$C$2:'SalesforceData'!$C$36),0)))=0,INDEX(SalesforceData!$F$2:$F$36,MATCH(1,($G4=SalesforceData!$A$2:$A$36)*(M$2=SalesforceData!$B$2:'SalesforceData'!$B$36) * (M$3=SalesforceData!$E$2:'SalesforceData'!$E$36),0)),INDEX(SalesforceData!$D$2:$D$36,MATCH(1,($G4=SalesforceData!$A$2:$A$36)*(M$2=SalesforceData!$B$2:'SalesforceData'!$B$36)*(M$3=SalesforceData!$C$2:'SalesforceData'!$C$36),0))),"")} -> 0 | N4: {=IFERROR(IF(COUNT(INDEX(SalesforceData!$D$2:$D$36,MATCH(1,($G4=SalesforceData!$A$2:$A$36)*(N$2=SalesforceData!$B$2:'SalesforceData'!$B$36)*(N$3=SalesforceData!$C$2:'SalesforceData'!$C$36),0)))=0,INDEX(SalesforceData!$F$2:$F$36,MATCH(1,($G4=SalesforceData!$A$2:$A$36)*(N$2=SalesforceData!$B$2:'SalesforceData'!$B$36) * (N$3=SalesforceData!$E$2:'SalesforceData'!$E$36),0)),INDEX(SalesforceData!$D$2:$D$36,MATCH(1,($G4=SalesforceData!$A$2:$A$36)*(N$2=SalesforceData!$B$2:'SalesforceData'!$B$36)*(N$3=SalesforceData!$C$2:'SalesforceData'!$C$36),0))),"")} -> 0 | O4: {=IFERROR(IF(COUNT(INDEX(SalesforceData!$D$2:$D$36,MATCH(1,($G4=SalesforceData!$A$2:$A$36)*(O$2=SalesforceData!$B$2:'SalesforceData'!$B$36)*(O$3=SalesforceData!$C$2:'SalesforceData'!$C$36),0)))=0,INDEX(SalesforceData!$F$2:$F$36,MATCH(1,($G4=SalesforceData!$A$2:$A$36)*(O$2=SalesforceData!$B$2:'SalesforceData'!$B$36) * (O$3=SalesforceData!$E$2:'SalesforceData'!$E$36),0)),INDEX(SalesforceData!$D$2:$D$36,MATCH(1,($G4=SalesforceData!$A$2:$A$36)*(O$2=SalesforceData!$B$2:'SalesforceData'!$B$36)*(O$3=SalesforceData!$C$2:'SalesforceData'!$C$36),0))),"")} -> 0 | S4: {=IF(CELL("contents",G4)=0,"",CELL("contents",G4))} | T4: {=IF(CELL("contents",H4)=0,"",CELL("contents",H4))} | U4: {=IF(CELL("contents",I4)=0,"",CELL("contents",I4))} | V4: {=IF(CELL("contents",J4)=0,"",CELL("contents",J4))} | W4: {=IF(CELL("contents",K4)=0,"",CELL("contents",K4))} | X4: {=IF(CELL("contents",L4)=0,"",CELL("contents",L4))} | Y4: {=IF(CELL("contents",M4)=0,"",CELL("contents",M4))} | Z4: {=IF(CELL("contents",N4)=0,"",CELL("contents",N4))} | AA4: {=IF(CELL("contents",O4)=0,"",CELL("contents",O4))}
A5: {=IF(IFERROR(INDEX(SalesforceData!$A$2:'SalesforceData'!$A$36, MATCH(0, COUNTIF(DataTransformation!$A$2:'DataTransformation'!$A4, SalesforceData!$A$2:'SalesforceData'!$A$36), 0)),"") = 0,"", IFERROR(INDEX(SalesforceData!$A$2:'SalesforceData'!$A$36, MATCH(0, COUNTIF(DataTransformation!$A$2:'DataTransformation'!$A4, SalesforceData!$A$2:'SalesforceData'!$A$36), 0)),""))} | B5: {=IF(IFERROR(INDEX(SalesforceData!$B$2:'SalesforceData'!$B$36, MATCH(0, COUNTIF(DataTransformation!$B$2:'DataTransformation'!$B4, SalesforceData!$B$2:'SalesforceData'!$B$36), 0)),"") = 0,"", IFERROR(INDEX(SalesforceData!$B$2:'SalesforceData'!$B$36, MATCH(0, COUNTIF(DataTransformation!$B$2:'DataTransformation'!$B4, SalesforceData!$B$2:'SalesforceData'!$B$36), 0)),""))} | C5: =B4 | D5: =IF(LEN(C5)>0,"kg","") | G5: =A4 | H5: {=IFERROR(IF(COUNT(INDEX(SalesforceData!$D$2:$D$36,MATCH(1,($G5=SalesforceData!$A$2:$A$36)*(H$2=SalesforceData!$B$2:'SalesforceData'!$B$36)*(H$3=SalesforceData!$C$2:'SalesforceData'!$C$36),0)))=0,INDEX(SalesforceData!$F$2:$F$36,MATCH(1,($G5=SalesforceData!$A$2:$A$36)*(H$2=SalesforceData!$B$2:'SalesforceData'!$B$36) * (H$3=SalesforceData!$E$2:'SalesforceData'!$E$36),0)),INDEX(SalesforceData!$D$2:$D$36,MATCH(1,($G5=SalesforceData!$A$2:$A$36)*(H$2=SalesforceData!$B$2:'SalesforceData'!$B$36)*(H$3=SalesforceData!$C$2:'SalesforceData'!$C$36),0))),"")} -> 0 | I5: {=IFERROR(IF(COUNT(INDEX(SalesforceData!$D$2:$D$36,MATCH(1,($G5=SalesforceData!$A$2:$A$36)*(I$2=SalesforceData!$B$2:'SalesforceData'!$B$36)*(I$3=SalesforceData!$C$2:'SalesforceData'!$C$36),0)))=0,INDEX(SalesforceData!$F$2:$F$36,MATCH(1,($G5=SalesforceData!$A$2:$A$36)*(I$2=SalesforceData!$B$2:'SalesforceData'!$B$36) * (I$3=SalesforceData!$E$2:'SalesforceData'!$E$36),0)),INDEX(SalesforceData!$D$2:$D$36,MATCH(1,($G5=SalesforceData!$A$2:$A$36)*(I$2=SalesforceData!$B$2:'SalesforceData'!$B$36)*(I$3=SalesforceData!$C$2:'SalesforceData'!$C$36),0))),"")} -> 0 | J5: {=IFERROR(IF(COUNT(INDEX(SalesforceData!$D$2:$D$36,MATCH(1,($G5=SalesforceData!$A$2:$A$36)*(J$2=SalesforceData!$B$2:'SalesforceData'!$B$36)*(J$3=SalesforceData!$C$2:'SalesforceData'!$C$36),0)))=0,INDEX(SalesforceData!$F$2:$F$36,MATCH(1,($G5=SalesforceData!$A$2:$A$36)*(J$2=SalesforceData!$B$2:'SalesforceData'!$B$36) * (J$3=SalesforceData!$E$2:'SalesforceData'!$E$36),0)),INDEX(SalesforceData!$D$2:$D$36,MATCH(1,($G5=SalesforceData!$A$2:$A$36)*(J$2=SalesforceData!$B$2:'SalesforceData'!$B$36)*(J$3=SalesforceData!$C$2:'SalesforceData'!$C$36),0))),"")} -> 0 | K5: {=IFERROR(IF(COUNT(INDEX(SalesforceData!$D$2:$D$36,MATCH(1,($G5=SalesforceData!$A$2:$A$36)*(K$2=SalesforceData!$B$2:'SalesforceData'!$B$36)*(K$3=SalesforceData!$C$2:'SalesforceData'!$C$36),0)))=0,INDEX(SalesforceData!$F$2:$F$36,MATCH(1,($G5=SalesforceData!$A$2:$A$36)*(K$2=SalesforceData!$B$2:'SalesforceData'!$B$36) * (K$3=SalesforceData!$E$2:'SalesforceData'!$E$36),0)),INDEX(SalesforceData!$D$2:$D$36,MATCH(1,($G5=SalesforceData!$A$2:$A$36)*(K$2=SalesforceData!$B$2:'SalesforceData'!$B$36)*(K$3=SalesforceData!$C$2:'SalesforceData'!$C$36),0))),"")} -> 0 | L5: {=IFERROR(IF(COUNT(INDEX(SalesforceData!$D$2:$D$36,MATCH(1,($G5=SalesforceData!$A$2:$A$36)*(L$2=SalesforceData!$B$2:'SalesforceData'!$B$36)*(L$3=SalesforceData!$C$2:'SalesforceData'!$C$36),0)))=0,INDEX(SalesforceData!$F$2:$F$36,MATCH(1,($G5=SalesforceData!$A$2:$A$36)*(L$2=SalesforceData!$B$2:'SalesforceData'!$B$36) * (L$3=SalesforceData!$E$2:'SalesforceData'!$E$36),0)),INDEX(SalesforceData!$D$2:$D$36,MATCH(1,($G5=SalesforceData!$A$2:$A$36)*(L$2=SalesforceData!$B$2:'SalesforceData'!$B$36)*(L$3=SalesforceData!$C$2:'SalesforceData'!$C$36),0))),"")} -> 0 | M5: {=IFERROR(IF(COUNT(INDEX(SalesforceData!$D$2:$D$36,MATCH(1,($G5=SalesforceData!$A$2:$A$36)*(M$2=SalesforceData!$B$2:'SalesforceData'!$B$36)*(M$3=SalesforceData!$C$2:'SalesforceData'!$C$36),0)))=0,INDEX(SalesforceData!$F$2:$F$36,MATCH(1,($G5=SalesforceData!$A$2:$A$36)*(M$2=SalesforceData!$B$2:'SalesforceData'!$B$36) * (M$3=SalesforceData!$E$2:'SalesforceData'!$E$36),0)),INDEX(SalesforceData!$D$2:$D$36,MATCH(1,($G5=SalesforceData!$A$2:$A$36)*(M$2=SalesforceData!$B$2:'SalesforceData'!$B$36)*(M$3=SalesforceData!$C$2:'SalesforceData'!$C$36),0))),"")} -> 0 | N5: {=IFERROR(IF(COUNT(INDEX(SalesforceData!$D$2:$D$36,MATCH(1,($G5=SalesforceData!$A$2:$A$36)*(N$2=SalesforceData!$B$2:'SalesforceData'!$B$36)*(N$3=SalesforceData!$C$2:'SalesforceData'!$C$36),0)))=0,INDEX(SalesforceData!$F$2:$F$36,MATCH(1,($G5=SalesforceData!$A$2:$A$36)*(N$2=SalesforceData!$B$2:'SalesforceData'!$B$36) * (N$3=SalesforceData!$E$2:'SalesforceData'!$E$36),0)),INDEX(SalesforceData!$D$2:$D$36,MATCH(1,($G5=SalesforceData!$A$2:$A$36)*(N$2=SalesforceData!$B$2:'SalesforceData'!$B$36)*(N$3=SalesforceData!$C$2:'SalesforceData'!$C$36),0))),"")} -> 0 | O5: {=IFERROR(IF(COUNT(INDEX(SalesforceData!$D$2:$D$36,MATCH(1,($G5=SalesforceData!$A$2:$A$36)*(O$2=SalesforceData!$B$2:'SalesforceData'!$B$36)*(O$3=SalesforceData!$C$2:'SalesforceData'!$C$36),0)))=0,INDEX(SalesforceData!$F$2:$F$36,MATCH(1,($G5=SalesforceData!$A$2:$A$36)*(O$2=SalesforceData!$B$2:'SalesforceData'!$B$36) * (O$3=SalesforceData!$E$2:'SalesforceData'!$E$36),0)),INDEX(SalesforceData!$D$2:$D$36,MATCH(1,($G5=SalesforceData!$A$2:$A$36)*(O$2=SalesforceData!$B$2:'SalesforceData'!$B$36)*(O$3=SalesforceData!$C$2:'SalesforceData'!$C$36),0))),"")} -> 0 | S5: {=IF(CELL("contents",G5)=0,"",CELL("contents",G5))} | T5: {=IF(CELL("contents",H5)=0,"",CELL("contents",H5))} | U5: {=IF(CELL("contents",I5)=0,"",CELL("contents",I5))} | V5: {=IF(CELL("contents",J5)=0,"",CELL("contents",J5))} | W5: {=IF(CELL("contents",K5)=0,"",CELL("contents",K5))} | X5: {=IF(CELL("contents",L5)=0,"",CELL("contents",L5))} | Y5: {=IF(CELL("contents",M5)=0,"",CELL("contents",M5))} | Z5: {=IF(CELL("contents",N5)=0,"",CELL("contents",N5))} | AA5: {=IF(CELL("contents",O5)=0,"",CELL("contents",O5))}
A6: {=IF(IFERROR(INDEX(SalesforceData!$A$2:'SalesforceData'!$A$36, MATCH(0, COUNTIF(DataTransformation!$A$2:'DataTransformation'!$A5, SalesforceData!$A$2:'SalesforceData'!$A$36), 0)),"") = 0,"", IFERROR(INDEX(SalesforceData!$A$2:'SalesforceData'!$A$36, MATCH(0, COUNTIF(DataTransformation!$A$2:'DataTransformation'!$A5, SalesforceData!$A$2:'SalesforceData'!$A$36), 0)),""))} | B6: {=IF(IFERROR(INDEX(SalesforceData!$B$2:'SalesforceData'!$B$36, MATCH(0, COUNTIF(DataTransformation!$B$2:'DataTransformation'!$B5, SalesforceData!$B$2:'SalesforceData'!$B$36), 0)),"") = 0,"", IFERROR(INDEX(SalesforceData!$B$2:'SalesforceData'!$B$36, MATCH(0, COUNTIF(DataTransformation!$B$2:'DataTransformation'!$B5, SalesforceData!$B$2:'SalesforceData'!$B$36), 0)),""))} | C6: =C5 | D6: =IF(LEN(C6)>0,"lbs","") | G6: =A5 | H6: {=IFERROR(IF(COUNT(INDEX(SalesforceData!$D$2:$D$36,MATCH(1,($G6=SalesforceData!$A$2:$A$36)*(H$2=SalesforceData!$B$2:'SalesforceData'!$B$36)*(H$3=SalesforceData!$C$2:'SalesforceData'!$C$36),0)))=0,INDEX(SalesforceData!$F$2:$F$36,MATCH(1,($G6=SalesforceData!$A$2:$A$36)*(H$2=SalesforceData!$B$2:'SalesforceData'!$B$36) * (H$3=SalesforceData!$E$2:'SalesforceData'!$E$36),0)),INDEX(SalesforceData!$D$2:$D$36,MATCH(1,($G6=SalesforceData!$A$2:$A$36)*(H$2=SalesforceData!$B$2:'SalesforceData'!$B$36)*(H$3=SalesforceData!$C$2:'SalesforceData'!$C$36),0))),"")} -> 0 | I6: {=IFERROR(IF(COUNT(INDEX(SalesforceData!$D$2:$D$36,MATCH(1,($G6=SalesforceData!$A$2:$A$36)*(I$2=SalesforceData!$B$2:'SalesforceData'!$B$36)*(I$3=SalesforceData!$C$2:'SalesforceData'!$C$36),0)))=0,INDEX(SalesforceData!$F$2:$F$36,MATCH(1,($G6=SalesforceData!$A$2:$A$36)*(I$2=SalesforceData!$B$2:'SalesforceData'!$B$36) * (I$3=SalesforceData!$E$2:'SalesforceData'!$E$36),0)),INDEX(SalesforceData!$D$2:$D$36,MATCH(1,($G6=SalesforceData!$A$2:$A$36)*(I$2=SalesforceData!$B$2:'SalesforceData'!$B$36)*(I$3=SalesforceData!$C$2:'SalesforceData'!$C$36),0))),"")} -> 0 | J6: {=IFERROR(IF(COUNT(INDEX(SalesforceData!$D$2:$D$36,MATCH(1,($G6=SalesforceData!$A$2:$A$36)*(J$2=SalesforceData!$B$2:'SalesforceData'!$B$36)*(J$3=SalesforceData!$C$2:'SalesforceData'!$C$36),0)))=0,INDEX(SalesforceData!$F$2:$F$36,MATCH(1,($G6=SalesforceData!$A$2:$A$36)*(J$2=SalesforceData!$B$2:'SalesforceData'!$B$36) * (J$3=SalesforceData!$E$2:'SalesforceData'!$E$36),0)),INDEX(SalesforceData!$D$2:$D$36,MATCH(1,($G6=SalesforceData!$A$2:$A$36)*(J$2=SalesforceData!$B$2:'SalesforceData'!$B$36)*(J$3=SalesforceData!$C$2:'SalesforceData'!$C$36),0))),"")} -> 0 | K6: {=IFERROR(IF(COUNT(INDEX(SalesforceData!$D$2:$D$36,MATCH(1,($G6=SalesforceData!$A$2:$A$36)*(K$2=SalesforceData!$B$2:'SalesforceData'!$B$36)*(K$3=SalesforceData!$C$2:'SalesforceData'!$C$36),0)))=0,INDEX(SalesforceData!$F$2:$F$36,MATCH(1,($G6=SalesforceData!$A$2:$A$36)*(K$2=SalesforceData!$B$2:'SalesforceData'!$B$36) * (K$3=SalesforceData!$E$2:'SalesforceData'!$E$36),0)),INDEX(SalesforceData!$D$2:$D$36,MATCH(1,($G6=SalesforceData!$A$2:$A$36)*(K$2=SalesforceData!$B$2:'SalesforceData'!$B$36)*(K$3=SalesforceData!$C$2:'SalesforceData'!$C$36),0))),"")} -> 0 | L6: {=IFERROR(IF(COUNT(INDEX(SalesforceData!$D$2:$D$36,MATCH(1,($G6=SalesforceData!$A$2:$A$36)*(L$2=SalesforceData!$B$2:'SalesforceData'!$B$36)*(L$3=SalesforceData!$C$2:'SalesforceData'!$C$36),0)))=0,INDEX(SalesforceData!$F$2:$F$36,MATCH(1,($G6=SalesforceData!$A$2:$A$36)*(L$2=SalesforceData!$B$2:'SalesforceData'!$B$36) * (L$3=SalesforceData!$E$2:'SalesforceData'!$E$36),0)),INDEX(SalesforceData!$D$2:$D$36,MATCH(1,($G6=SalesforceData!$A$2:$A$36)*(L$2=SalesforceData!$B$2:'SalesforceData'!$B$36)*(L$3=SalesforceData!$C$2:'SalesforceData'!$C$36),0))),"")} -> 0 | M6: {=IFERROR(IF(COUNT(INDEX(SalesforceData!$D$2:$D$36,MATCH(1,($G6=SalesforceData!$A$2:$A$36)*(M$2=SalesforceData!$B$2:'SalesforceData'!$B$36)*(M$3=SalesforceData!$C$2:'SalesforceData'!$C$36),0)))=0,INDEX(SalesforceData!$F$2:$F$36,MATCH(1,($G6=SalesforceData!$A$2:$A$36)*(M$2=SalesforceData!$B$2:'SalesforceData'!$B$36) * (M$3=SalesforceData!$E$2:'SalesforceData'!$E$36),0)),INDEX(SalesforceData!$D$2:$D$36,MATCH(1,($G6=SalesforceData!$A$2:$A$36)*(M$2=SalesforceData!$B$2:'SalesforceData'!$B$36)*(M$3=SalesforceData!$C$2:'SalesforceData'!$C$36),0))),"")} -> 0 | N6: {=IFERROR(IF(COUNT(INDEX(SalesforceData!$D$2:$D$36,MATCH(1,($G6=SalesforceData!$A$2:$A$36)*(N$2=SalesforceData!$B$2:'SalesforceData'!$B$36)*(N$3=SalesforceData!$C$2:'SalesforceData'!$C$36),0)))=0,INDEX(SalesforceData!$F$2:$F$36,MATCH(1,($G6=SalesforceData!$A$2:$A$36)*(N$2=SalesforceData!$B$2:'SalesforceData'!$B$36) * (N$3=SalesforceData!$E$2:'SalesforceData'!$E$36),0)),INDEX(SalesforceData!$D$2:$D$36,MATCH(1,($G6=SalesforceData!$A$2:$A$36)*(N$2=SalesforceData!$B$2:'SalesforceData'!$B$36)*(N$3=SalesforceData!$C$2:'SalesforceData'!$C$36),0))),"")} -> 0 | O6: {=IFERROR(IF(COUNT(INDEX(SalesforceData!$D$2:$D$36,MATCH(1,($G6=SalesforceData!$A$2:$A$36)*(O$2=SalesforceData!$B$2:'SalesforceData'!$B$36)*(O$3=SalesforceData!$C$2:'SalesforceData'!$C$36),0)))=0,INDEX(SalesforceData!$F$2:$F$36,MATCH(1,($G6=SalesforceData!$A$2:$A$36)*(O$2=SalesforceData!$B$2:'SalesforceData'!$B$36) * (O$3=SalesforceData!$E$2:'SalesforceData'!$E$36),0)),INDEX(SalesforceData!$D$2:$D$36,MATCH(1,($G6=SalesforceData!$A$2:$A$36)*(O$2=SalesforceData!$B$2:'SalesforceData'!$B$36)*(O$3=SalesforceData!$C$2:'SalesforceData'!$C$36),0))),"")} -> 0 | S6: {=IF(CELL("contents",G6)=0,"",CELL("contents",G6))} | T6: {=IF(CELL("contents",H6)=0,"",CELL("contents",H6))} | U6: {=IF(CELL("contents",I6)=0,"",CELL("contents",I6))} | V6: {=IF(CELL("contents",J6)=0,"",CELL("contents",J6))} | W6: {=IF(CELL("contents",K6)=0,"",CELL("contents",K6))} | X6: {=IF(CELL("contents",L6)=0,"",CELL("contents",L6))} | Y6: {=IF(CELL("contents",M6)=0,"",CELL("contents",M6))} | Z6: {=IF(CELL("contents",N6)=0,"",CELL("contents",N6))} | AA6: {=IF(CELL("contents",O6)=0,"",CELL("contents",O6))}
A7: {=IF(IFERROR(INDEX(SalesforceData!$A$2:'SalesforceData'!$A$36, MATCH(0, COUNTIF(DataTransformation!$A$2:'DataTransformation'!$A6, SalesforceData!$A$2:'SalesforceData'!$A$36), 0)),"") = 0,"", IFERROR(INDEX(SalesforceData!$A$2:'SalesforceData'!$A$36, MATCH(0, COUNTIF(DataTransformation!$A$2:'DataTransformation'!$A6, SalesforceData!$A$2:'SalesforceData'!$A$36), 0)),""))} | B7: {=IF(IFERROR(INDEX(SalesforceData!$B$2:'SalesforceData'!$B$36, MATCH(0, COUNTIF(DataTransformation!$B$2:'DataTransformation'!$B6, SalesforceData!$B$2:'SalesforceData'!$B$36), 0)),"") = 0,"", IFERROR(INDEX(SalesforceData!$B$2:'SalesforceData'!$B$36, MATCH(0, COUNTIF(DataTransformation!$B$2:'DataTransformation'!$B6, SalesforceData!$B$2:'SalesforceData'!$B$36), 0)),""))} | C7: =B5 | D7: =IF(LEN(C7)>0,"kg","") | G7: =A6 | H7: {=IFERROR(IF(COUNT(INDEX(SalesforceData!$D$2:$D$36,MATCH(1,($G7=SalesforceData!$A$2:$A$36)*(H$2=SalesforceData!$B$2:'SalesforceData'!$B$36)*(H$3=SalesforceData!$C$2:'SalesforceData'!$C$36),0)))=0,INDEX(SalesforceData!$F$2:$F$36,MATCH(1,($G7=SalesforceData!$A$2:$A$36)*(H$2=SalesforceData!$B$2:'SalesforceData'!$B$36) * (H$3=SalesforceData!$E$2:'SalesforceData'!$E$36),0)),INDEX(SalesforceData!$D$2:$D$36,MATCH(1,($G7=SalesforceData!$A$2:$A$36)*(H$2=SalesforceData!$B$2:'SalesforceData'!$B$36)*(H$3=SalesforceData!$C$2:'SalesforceData'!$C$36),0))),"")} -> 0 | I7: {=IFERROR(IF(COUNT(INDEX(SalesforceData!$D$2:$D$36,MATCH(1,($G7=SalesforceData!$A$2:$A$36)*(I$2=SalesforceData!$B$2:'SalesforceData'!$B$36)*(I$3=SalesforceData!$C$2:'SalesforceData'!$C$36),0)))=0,INDEX(SalesforceData!$F$2:$F$36,MATCH(1,($G7=SalesforceData!$A$2:$A$36)*(I$2=SalesforceData!$B$2:'SalesforceData'!$B$36) * (I$3=SalesforceData!$E$2:'SalesforceData'!$E$36),0)),INDEX(SalesforceData!$D$2:$D$36,MATCH(1,($G7=SalesforceData!$A$2:$A$36)*(I$2=SalesforceData!$B$2:'SalesforceData'!$B$36)*(I$3=SalesforceData!$C$2:'SalesforceData'!$C$36),0))),"")} -> 0 | J7: {=IFERROR(IF(COUNT(INDEX(SalesforceData!$D$2:$D$36,MATCH(1,($G7=SalesforceData!$A$2:$A$36)*(J$2=SalesforceData!$B$2:'SalesforceData'!$B$36)*(J$3=SalesforceData!$C$2:'SalesforceData'!$C$36),0)))=0,INDEX(SalesforceData!$F$2:$F$36,MATCH(1,($G7=SalesforceData!$A$2:$A$36)*(J$2=SalesforceData!$B$2:'SalesforceData'!$B$36) * (J$3=SalesforceData!$E$2:'SalesforceData'!$E$36),0)),INDEX(SalesforceData!$D$2:$D$36,MATCH(1,($G7=SalesforceData!$A$2:$A$36)*(J$2=SalesforceData!$B$2:'SalesforceData'!$B$36)*(J$3=SalesforceData!$C$2:'SalesforceData'!$C$36),0))),"")} -> 0 | K7: {=IFERROR(IF(COUNT(INDEX(SalesforceData!$D$2:$D$36,MATCH(1,($G7=SalesforceData!$A$2:$A$36)*(K$2=SalesforceData!$B$2:'SalesforceData'!$B$36)*(K$3=SalesforceData!$C$2:'SalesforceData'!$C$36),0)))=0,INDEX(SalesforceData!$F$2:$F$36,MATCH(1,($G7=SalesforceData!$A$2:$A$36)*(K$2=SalesforceData!$B$2:'SalesforceData'!$B$36) * (K$3=SalesforceData!$E$2:'SalesforceData'!$E$36),0)),INDEX(SalesforceData!$D$2:$D$36,MATCH(1,($G7=SalesforceData!$A$2:$A$36)*(K$2=SalesforceData!$B$2:'SalesforceData'!$B$36)*(K$3=SalesforceData!$C$2:'SalesforceData'!$C$36),0))),"")} -> 0 | L7: {=IFERROR(IF(COUNT(INDEX(SalesforceData!$D$2:$D$36,MATCH(1,($G7=SalesforceData!$A$2:$A$36)*(L$2=SalesforceData!$B$2:'SalesforceData'!$B$36)*(L$3=SalesforceData!$C$2:'SalesforceData'!$C$36),0)))=0,INDEX(SalesforceData!$F$2:$F$36,MATCH(1,($G7=SalesforceData!$A$2:$A$36)*(L$2=SalesforceData!$B$2:'SalesforceData'!$B$36) * (L$3=SalesforceData!$E$2:'SalesforceData'!$E$36),0)),INDEX(SalesforceData!$D$2:$D$36,MATCH(1,($G7=SalesforceData!$A$2:$A$36)*(L$2=SalesforceData!$B$2:'SalesforceData'!$B$36)*(L$3=SalesforceData!$C$2:'SalesforceData'!$C$36),0))),"")} -> 0 | M7: {=IFERROR(IF(COUNT(INDEX(SalesforceData!$D$2:$D$36,MATCH(1,($G7=SalesforceData!$A$2:$A$36)*(M$2=SalesforceData!$B$2:'SalesforceData'!$B$36)*(M$3=SalesforceData!$C$2:'SalesforceData'!$C$36),0)))=0,INDEX(SalesforceData!$F$2:$F$36,MATCH(1,($G7=SalesforceData!$A$2:$A$36)*(M$2=SalesforceData!$B$2:'SalesforceData'!$B$36) * (M$3=SalesforceData!$E$2:'SalesforceData'!$E$36),0)),INDEX(SalesforceData!$D$2:$D$36,MATCH(1,($G7=SalesforceData!$A$2:$A$36)*(M$2=SalesforceData!$B$2:'SalesforceData'!$B$36)*(M$3=SalesforceData!$C$2:'SalesforceData'!$C$36),0))),"")} -> 0 | N7: {=IFERROR(IF(COUNT(INDEX(SalesforceData!$D$2:$D$36,MATCH(1,($G7=SalesforceData!$A$2:$A$36)*(N$2=SalesforceData!$B$2:'SalesforceData'!$B$36)*(N$3=SalesforceData!$C$2:'SalesforceData'!$C$36),0)))=0,INDEX(SalesforceData!$F$2:$F$36,MATCH(1,($G7=SalesforceData!$A$2:$A$36)*(N$2=SalesforceData!$B$2:'SalesforceData'!$B$36) * (N$3=SalesforceData!$E$2:'SalesforceData'!$E$36),0)),INDEX(SalesforceData!$D$2:$D$36,MATCH(1,($G7=SalesforceData!$A$2:$A$36)*(N$2=SalesforceData!$B$2:'SalesforceData'!$B$36)*(N$3=SalesforceData!$C$2:'SalesforceData'!$C$36),0))),"")} -> 0 | O7: {=IFERROR(IF(COUNT(INDEX(SalesforceData!$D$2:$D$36,MATCH(1,($G7=SalesforceData!$A$2:$A$36)*(O$2=SalesforceData!$B$2:'SalesforceData'!$B$36)*(O$3=SalesforceData!$C$2:'SalesforceData'!$C$36),0)))=0,INDEX(SalesforceData!$F$2:$F$36,MATCH(1,($G7=SalesforceData!$A$2:$A$36)*(O$2=SalesforceData!$B$2:'SalesforceData'!$B$36) * (O$3=SalesforceData!$E$2:'SalesforceData'!$E$36),0)),INDEX(SalesforceData!$D$2:$D$36,MATCH(1,($G7=SalesforceData!$A$2:$A$36)*(O$2=SalesforceData!$B$2:'SalesforceData'!$B$36)*(O$3=SalesforceData!$C$2:'SalesforceData'!$C$36),0))),"")} -> 0 | S7: {=IF(CELL("contents",G7)=0,"",CELL("contents",G7))} | T7: {=IF(CELL("contents",H7)=0,"",CELL("contents",H7))} | U7: {=IF(CELL("contents",I7)=0,"",CELL("contents",I7))} | V7: {=IF(CELL("contents",J7)=0,"",CELL("contents",J7))} | W7: {=IF(CELL("contents",K7)=0,"",CELL("contents",K7))} | X7: {=IF(CELL("contents",L7)=0,"",CELL("contents",L7))} | Y7: {=IF(CELL("contents",M7)=0,"",CELL("contents",M7))} | Z7: {=IF(CELL("contents",N7)=0,"",CELL("contents",N7))} | AA7: {=IF(CELL("contents",O7)=0,"",CELL("contents",O7))}
A8: {=IF(IFERROR(INDEX(SalesforceData!$A$2:'SalesforceData'!$A$36, MATCH(0, COUNTIF(DataTransformation!$A$2:'DataTransformation'!$A7, SalesforceData!$A$2:'SalesforceData'!$A$36), 0)),"") = 0,"", IFERROR(INDEX(SalesforceData!$A$2:'SalesforceData'!$A$36, MATCH(0, COUNTIF(DataTransformation!$A$2:'DataTransformation'!$A7, SalesforceData!$A$2:'SalesforceData'!$A$36), 0)),""))} | B8: {=IF(IFERROR(INDEX(SalesforceData!$B$2:'SalesforceData'!$B$36, MATCH(0, COUNTIF(DataTransformation!$B$2:'DataTransformation'!$B7, SalesforceData!$B$2:'SalesforceData'!$B$36), 0)),"") = 0,"", IFERROR(INDEX(SalesforceData!$B$2:'SalesforceData'!$B$36, MATCH(0, COUNTIF(DataTransformation!$B$2:'DataTransformation'!$B7, SalesforceData!$B$2:'SalesforceData'!$B$36), 0)),""))} | C8: =C7 | D8: =IF(LEN(C8)>0,"lbs","") | G8: =A7 | H8: {=IFERROR(IF(COUNT(INDEX(SalesforceData!$D$2:$D$36,MATCH(1,($G8=SalesforceData!$A$2:$A$36)*(H$2=SalesforceData!$B$2:'SalesforceData'!$B$36)*(H$3=SalesforceData!$C$2:'SalesforceData'!$C$36),0)))=0,INDEX(SalesforceData!$F$2:$F$36,MATCH(1,($G8=SalesforceData!$A$2:$A$36)*(H$2=SalesforceData!$B$2:'SalesforceData'!$B$36) * (H$3=SalesforceData!$E$2:'SalesforceData'!$E$36),0)),INDEX(SalesforceData!$D$2:$D$36,MATCH(1,($G8=SalesforceData!$A$2:$A$36)*(H$2=SalesforceData!$B$2:'SalesforceData'!$B$36)*(H$3=SalesforceData!$C$2:'SalesforceData'!$C$36),0))),"")} -> 0 | I8: {=IFERROR(IF(COUNT(INDEX(SalesforceData!$D$2:$D$36,MATCH(1,($G8=SalesforceData!$A$2:$A$36)*(I$2=SalesforceData!$B$2:'SalesforceData'!$B$36)*(I$3=SalesforceData!$C$2:'SalesforceData'!$C$36),0)))=0,INDEX(SalesforceData!$F$2:$F$36,MATCH(1,($G8=SalesforceData!$A$2:$A$36)*(I$2=SalesforceData!$B$2:'SalesforceData'!$B$36) * (I$3=SalesforceData!$E$2:'SalesforceData'!$E$36),0)),INDEX(SalesforceData!$D$2:$D$36,MATCH(1,($G8=SalesforceData!$A$2:$A$36)*(I$2=SalesforceData!$B$2:'SalesforceData'!$B$36)*(I$3=SalesforceData!$C$2:'SalesforceData'!$C$36),0))),"")} -> 0 | J8: {=IFERROR(IF(COUNT(INDEX(SalesforceData!$D$2:$D$36,MATCH(1,($G8=SalesforceData!$A$2:$A$36)*(J$2=SalesforceData!$B$2:'SalesforceData'!$B$36)*(J$3=SalesforceData!$C$2:'SalesforceData'!$C$36),0)))=0,INDEX(SalesforceData!$F$2:$F$36,MATCH(1,($G8=SalesforceData!$A$2:$A$36)*(J$2=SalesforceData!$B$2:'SalesforceData'!$B$36) * (J$3=SalesforceData!$E$2:'SalesforceData'!$E$36),0)),INDEX(SalesforceData!$D$2:$D$36,MATCH(1,($G8=SalesforceData!$A$2:$A$36)*(J$2=SalesforceData!$B$2:'SalesforceData'!$B$36)*(J$3=SalesforceData!$C$2:'SalesforceData'!$C$36),0))),"")} -> 0 | K8: {=IFERROR(IF(COUNT(INDEX(SalesforceData!$D$2:$D$36,MATCH(1,($G8=SalesforceData!$A$2:$A$36)*(K$2=SalesforceData!$B$2:'SalesforceData'!$B$36)*(K$3=SalesforceData!$C$2:'SalesforceData'!$C$36),0)))=0,INDEX(SalesforceData!$F$2:$F$36,MATCH(1,($G8=SalesforceData!$A$2:$A$36)*(K$2=SalesforceData!$B$2:'SalesforceData'!$B$36) * (K$3=SalesforceData!$E$2:'SalesforceData'!$E$36),0)),INDEX(SalesforceData!$D$2:$D$36,MATCH(1,($G8=SalesforceData!$A$2:$A$36)*(K$2=SalesforceData!$B$2:'SalesforceData'!$B$36)*(K$3=SalesforceData!$C$2:'SalesforceData'!$C$36),0))),"")} -> 0 | L8: {=IFERROR(IF(COUNT(INDEX(SalesforceData!$D$2:$D$36,MATCH(1,($G8=SalesforceData!$A$2:$A$36)*(L$2=SalesforceData!$B$2:'SalesforceData'!$B$36)*(L$3=SalesforceData!$C$2:'SalesforceData'!$C$36),0)))=0,INDEX(SalesforceData!$F$2:$F$36,MATCH(1,($G8=SalesforceData!$A$2:$A$36)*(L$2=SalesforceData!$B$2:'SalesforceData'!$B$36) * (L$3=SalesforceData!$E$2:'SalesforceData'!$E$36),0)),INDEX(SalesforceData!$D$2:$D$36,MATCH(1,($G8=SalesforceData!$A$2:$A$36)*(L$2=SalesforceData!$B$2:'SalesforceData'!$B$36)*(L$3=SalesforceData!$C$2:'SalesforceData'!$C$36),0))),"")} -> 0 | M8: {=IFERROR(IF(COUNT(INDEX(SalesforceData!$D$2:$D$36,MATCH(1,($G8=SalesforceData!$A$2:$A$36)*(M$2=SalesforceData!$B$2:'SalesforceData'!$B$36)*(M$3=SalesforceData!$C$2:'SalesforceData'!$C$36),0)))=0,INDEX(SalesforceData!$F$2:$F$36,MATCH(1,($G8=SalesforceData!$A$2:$A$36)*(M$2=SalesforceData!$B$2:'SalesforceData'!$B$36) * (M$3=SalesforceData!$E$2:'SalesforceData'!$E$36),0)),INDEX(SalesforceData!$D$2:$D$36,MATCH(1,($G8=SalesforceData!$A$2:$A$36)*(M$2=SalesforceData!$B$2:'SalesforceData'!$B$36)*(M$3=SalesforceData!$C$2:'SalesforceData'!$C$36),0))),"")} -> 0 | N8: {=IFERROR(IF(COUNT(INDEX(SalesforceData!$D$2:$D$36,MATCH(1,($G8=SalesforceData!$A$2:$A$36)*(N$2=SalesforceData!$B$2:'SalesforceData'!$B$36)*(N$3=SalesforceData!$C$2:'SalesforceData'!$C$36),0)))=0,INDEX(SalesforceData!$F$2:$F$36,MATCH(1,($G8=SalesforceData!$A$2:$A$36)*(N$2=SalesforceData!$B$2:'SalesforceData'!$B$36) * (N$3=SalesforceData!$E$2:'SalesforceData'!$E$36),0)),INDEX(SalesforceData!$D$2:$D$36,MATCH(1,($G8=SalesforceData!$A$2:$A$36)*(N$2=SalesforceData!$B$2:'SalesforceData'!$B$36)*(N$3=SalesforceData!$C$2:'SalesforceData'!$C$36),0))),"")} -> 0 | O8: {=IFERROR(IF(COUNT(INDEX(SalesforceData!$D$2:$D$36,MATCH(1,($G8=SalesforceData!$A$2:$A$36)*(O$2=SalesforceData!$B$2:'SalesforceData'!$B$36)*(O$3=SalesforceData!$C$2:'SalesforceData'!$C$36),0)))=0,INDEX(SalesforceData!$F$2:$F$36,MATCH(1,($G8=SalesforceData!$A$2:$A$36)*(O$2=SalesforceData!$B$2:'SalesforceData'!$B$36) * (O$3=SalesforceData!$E$2:'SalesforceData'!$E$36),0)),INDEX(SalesforceData!$D$2:$D$36,MATCH(1,($G8=SalesforceData!$A$2:$A$36)*(O$2=SalesforceData!$B$2:'SalesforceData'!$B$36)*(O$3=SalesforceData!$C$2:'SalesforceData'!$C$36),0))),"")} -> 0 | S8: {=IF(CELL("contents",G8)=0,"",CELL("contents",G8))} | T8: {=IF(CELL("contents",H8)=0,"",CELL("contents",H8))} | U8: {=IF(CELL("contents",I8)=0,"",CELL("contents",I8))} | V8: {=IF(CELL("contents",J8)=0,"",CELL("contents",J8))} | W8: {=IF(CELL("contents",K8)=0,"",CELL("contents",K8))} | X8: {=IF(CELL("contents",L8)=0,"",CELL("contents",L8))} | Y8: {=IF(CELL("contents",M8)=0,"",CELL("contents",M8))} | Z8: {=IF(CELL("contents",N8)=0,"",CELL("contents",N8))} | AA8: {=IF(CELL("contents",O8)=0,"",CELL("contents",O8))}
A9: {=IF(IFERROR(INDEX(SalesforceData!$A$2:'SalesforceData'!$A$36, MATCH(0, COUNTIF(DataTransformation!$A$2:'DataTransformation'!$A8, SalesforceData!$A$2:'SalesforceData'!$A$36), 0)),"") = 0,"", IFERROR(INDEX(SalesforceData!$A$2:'SalesforceData'!$A$36, MATCH(0, COUNTIF(DataTransformation!$A$2:'DataTransformation'!$A8, SalesforceData!$A$2:'SalesforceData'!$A$36), 0)),""))} | B9: {=IF(IFERROR(INDEX(SalesforceData!$B$2:'SalesforceData'!$B$36, MATCH(0, COUNTIF(DataTransformation!$B$2:'DataTransformation'!$B8, SalesforceData!$B$2:'SalesforceData'!$B$36), 0)),"") = 0,"", IFERROR(INDEX(SalesforceData!$B$2:'SalesforceData'!$B$36, MATCH(0, COUNTIF(DataTransformation!$B$2:'DataTransformation'!$B8, SalesforceData!$B$2:'SalesforceData'!$B$36), 0)),""))} | C9: =B6 | D9: =IF(LEN(C9)>0,"kg","") | G9: =A8 | H9: {=IFERROR(IF(COUNT(INDEX(SalesforceData!$D$2:$D$36,MATCH(1,($G9=SalesforceData!$A$2:$A$36)*(H$2=SalesforceData!$B$2:'SalesforceData'!$B$36)*(H$3=SalesforceData!$C$2:'SalesforceData'!$C$36),0)))=0,INDEX(SalesforceData!$F$2:$F$36,MATCH(1,($G9=SalesforceData!$A$2:$A$36)*(H$2=SalesforceData!$B$2:'SalesforceData'!$B$36) * (H$3=SalesforceData!$E$2:'SalesforceData'!$E$36),0)),INDEX(SalesforceData!$D$2:$D$36,MATCH(1,($G9=SalesforceData!$A$2:$A$36)*(H$2=SalesforceData!$B$2:'SalesforceData'!$B$36)*(H$3=SalesforceData!$C$2:'SalesforceData'!$C$36),0))),"")} -> 0 | I9: {=IFERROR(IF(COUNT(INDEX(SalesforceData!$D$2:$D$36,MATCH(1,($G9=SalesforceData!$A$2:$A$36)*(I$2=SalesforceData!$B$2:'SalesforceData'!$B$36)*(I$3=SalesforceData!$C$2:'SalesforceData'!$C$36),0)))=0,INDEX(SalesforceData!$F$2:$F$36,MATCH(1,($G9=SalesforceData!$A$2:$A$36)*(I$2=SalesforceData!$B$2:'SalesforceData'!$B$36) * (I$3=SalesforceData!$E$2:'SalesforceData'!$E$36),0)),INDEX(SalesforceData!$D$2:$D$36,MATCH(1,($G9=SalesforceData!$A$2:$A$36)*(I$2=SalesforceData!$B$2:'SalesforceData'!$B$36)*(I$3=SalesforceData!$C$2:'SalesforceData'!$C$36),0))),"")} -> 0 | J9: {=IFERROR(IF(COUNT(INDEX(SalesforceData!$D$2:$D$36,MATCH(1,($G9=SalesforceData!$A$2:$A$36)*(J$2=SalesforceData!$B$2:'SalesforceData'!$B$36)*(J$3=SalesforceData!$C$2:'SalesforceData'!$C$36),0)))=0,INDEX(SalesforceData!$F$2:$F$36,MATCH(1,($G9=SalesforceData!$A$2:$A$36)*(J$2=SalesforceData!$B$2:'SalesforceData'!$B$36) * (J$3=SalesforceData!$E$2:'SalesforceData'!$E$36),0)),INDEX(SalesforceData!$D$2:$D$36,MATCH(1,($G9=SalesforceData!$A$2:$A$36)*(J$2=SalesforceData!$B$2:'SalesforceData'!$B$36)*(J$3=SalesforceData!$C$2:'SalesforceData'!$C$36),0))),"")} -> 0 | K9: {=IFERROR(IF(COUNT(INDEX(SalesforceData!$D$2:$D$36,MATCH(1,($G9=SalesforceData!$A$2:$A$36)*(K$2=SalesforceData!$B$2:'SalesforceData'!$B$36)*(K$3=SalesforceData!$C$2:'SalesforceData'!$C$36),0)))=0,INDEX(SalesforceData!$F$2:$F$36,MATCH(1,($G9=SalesforceData!$A$2:$A$36)*(K$2=SalesforceData!$B$2:'SalesforceData'!$B$36) * (K$3=SalesforceData!$E$2:'SalesforceData'!$E$36),0)),INDEX(SalesforceData!$D$2:$D$36,MATCH(1,($G9=SalesforceData!$A$2:$A$36)*(K$2=SalesforceData!$B$2:'SalesforceData'!$B$36)*(K$3=SalesforceData!$C$2:'SalesforceData'!$C$36),0))),"")} -> 0 | L9: {=IFERROR(IF(COUNT(INDEX(SalesforceData!$D$2:$D$36,MATCH(1,($G9=SalesforceData!$A$2:$A$36)*(L$2=SalesforceData!$B$2:'SalesforceData'!$B$36)*(L$3=SalesforceData!$C$2:'SalesforceData'!$C$36),0)))=0,INDEX(SalesforceData!$F$2:$F$36,MATCH(1,($G9=SalesforceData!$A$2:$A$36)*(L$2=SalesforceData!$B$2:'SalesforceData'!$B$36) * (L$3=SalesforceData!$E$2:'SalesforceData'!$E$36),0)),INDEX(SalesforceData!$D$2:$D$36,MATCH(1,($G9=SalesforceData!$A$2:$A$36)*(L$2=SalesforceData!$B$2:'SalesforceData'!$B$36)*(L$3=SalesforceData!$C$2:'SalesforceData'!$C$36),0))),"")} -> 0 | M9: {=IFERROR(IF(COUNT(INDEX(SalesforceData!$D$2:$D$36,MATCH(1,($G9=SalesforceData!$A$2:$A$36)*(M$2=SalesforceData!$B$2:'SalesforceData'!$B$36)*(M$3=SalesforceData!$C$2:'SalesforceData'!$C$36),0)))=0,INDEX(SalesforceData!$F$2:$F$36,MATCH(1,($G9=SalesforceData!$A$2:$A$36)*(M$2=SalesforceData!$B$2:'SalesforceData'!$B$36) * (M$3=SalesforceData!$E$2:'SalesforceData'!$E$36),0)),INDEX(SalesforceData!$D$2:$D$36,MATCH(1,($G9=SalesforceData!$A$2:$A$36)*(M$2=SalesforceData!$B$2:'SalesforceData'!$B$36)*(M$3=SalesforceData!$C$2:'SalesforceData'!$C$36),0))),"")} -> 0 | N9: {=IFERROR(IF(COUNT(INDEX(SalesforceData!$D$2:$D$36,MATCH(1,($G9=SalesforceData!$A$2:$A$36)*(N$2=SalesforceData!$B$2:'SalesforceData'!$B$36)*(N$3=SalesforceData!$C$2:'SalesforceData'!$C$36),0)))=0,INDEX(SalesforceData!$F$2:$F$36,MATCH(1,($G9=SalesforceData!$A$2:$A$36)*(N$2=SalesforceData!$B$2:'SalesforceData'!$B$36) * (N$3=SalesforceData!$E$2:'SalesforceData'!$E$36),0)),INDEX(SalesforceData!$D$2:$D$36,MATCH(1,($G9=SalesforceData!$A$2:$A$36)*(N$2=SalesforceData!$B$2:'SalesforceData'!$B$36)*(N$3=SalesforceData!$C$2:'SalesforceData'!$C$36),0))),"")} -> 0 | O9: {=IFERROR(IF(COUNT(INDEX(SalesforceData!$D$2:$D$36,MATCH(1,($G9=SalesforceData!$A$2:$A$36)*(O$2=SalesforceData!$B$2:'SalesforceData'!$B$36)*(O$3=SalesforceData!$C$2:'SalesforceData'!$C$36),0)))=0,INDEX(SalesforceData!$F$2:$F$36,MATCH(1,($G9=SalesforceData!$A$2:$A$36)*(O$2=SalesforceData!$B$2:'SalesforceData'!$B$36) * (O$3=SalesforceData!$E$2:'SalesforceData'!$E$36),0)),INDEX(SalesforceData!$D$2:$D$36,MATCH(1,($G9=SalesforceData!$A$2:$A$36)*(O$2=SalesforceData!$B$2:'SalesforceData'!$B$36)*(O$3=SalesforceData!$C$2:'SalesforceData'!$C$36),0))),"")} -> 0 | S9: {=IF(CELL("contents",G9)=0,"",CELL("contents",G9))} | T9: {=IF(CELL("contents",H9)=0,"",CELL("contents",H9))} | U9: {=IF(CELL("contents",I9)=0,"",CELL("contents",I9))} | V9: {=IF(CELL("contents",J9)=0,"",CELL("contents",J9))} | W9: {=IF(CELL("contents",K9)=0,"",CELL("contents",K9))} | X9: {=IF(CELL("contents",L9)=0,"",CELL("contents",L9))} | Y9: {=IF(CELL("contents",M9)=0,"",CELL("contents",M9))} | Z9: {=IF(CELL("contents",N9)=0,"",CELL("contents",N9))} | AA9: {=IF(CELL("contents",O9)=0,"",CELL("contents",O9))}
A10: {=IF(IFERROR(INDEX(SalesforceData!$A$2:'SalesforceData'!$A$36, MATCH(0, COUNTIF(DataTransformation!$A$2:'DataTransformation'!$A9, SalesforceData!$A$2:'SalesforceData'!$A$36), 0)),"") = 0,"", IFERROR(INDEX(SalesforceData!$A$2:'SalesforceData'!$A$36, MATCH(0, COUNTIF(DataTransformation!$A$2:'DataTransformation'!$A9, SalesforceData!$A$2:'SalesforceData'!$A$36), 0)),""))} | B10: {=IF(IFERROR(INDEX(SalesforceData!$B$2:'SalesforceData'!$B$36, MATCH(0, COUNTIF(DataTransformation!$B$2:'DataTransformation'!$B9, SalesforceData!$B$2:'SalesforceData'!$B$36), 0)),"") = 0,"", IFERROR(INDEX(SalesforceData!$B$2:'SalesforceData'!$B$36, MATCH(0, COUNTIF(DataTransformation!$B$2:'DataTransformation'!$B9, SalesforceData!$B$2:'SalesforceData'!$B$36), 0)),""))} | C10: =C9 | D10: =IF(LEN(C10)>0,"lbs","") | G10: =A9 | H10: {=IFERROR(IF(COUNT(INDEX(SalesforceData!$D$2:$D$36,MATCH(1,($G10=SalesforceData!$A$2:$A$36)*(H$2=SalesforceData!$B$2:'SalesforceData'!$B$36)*(H$3=SalesforceData!$C$2:'SalesforceData'!$C$36),0)))=0,INDEX(SalesforceData!$F$2:$F$36,MATCH(1,($G10=SalesforceData!$A$2:$A$36)*(H$2=SalesforceData!$B$2:'SalesforceData'!$B$36) * (H$3=SalesforceData!$E$2:'SalesforceData'!$E$36),0)),INDEX(SalesforceData!$D$2:$D$36,MATCH(1,($G10=SalesforceData!$A$2:$A$36)*(H$2=SalesforceData!$B$2:'SalesforceData'!$B$36)*(H$3=SalesforceData!$C$2:'SalesforceData'!$C$36),0))),"")} -> 0 | I10: {=IFERROR(IF(COUNT(INDEX(SalesforceData!$D$2:$D$36,MATCH(1,($G10=SalesforceData!$A$2:$A$36)*(I$2=SalesforceData!$B$2:'SalesforceData'!$B$36)*(I$3=SalesforceData!$C$2:'SalesforceData'!$C$36),0)))=0,INDEX(SalesforceData!$F$2:$F$36,MATCH(1,($G10=SalesforceData!$A$2:$A$36)*(I$2=SalesforceData!$B$2:'SalesforceData'!$B$36) * (I$3=SalesforceData!$E$2:'SalesforceData'!$E$36),0)),INDEX(SalesforceData!$D$2:$D$36,MATCH(1,($G10=SalesforceData!$A$2:$A$36)*(I$2=SalesforceData!$B$2:'SalesforceData'!$B$36)*(I$3=SalesforceData!$C$2:'SalesforceData'!$C$36),0))),"")} -> 0 | J10: {=IFERROR(IF(COUNT(INDEX(SalesforceData!$D$2:$D$36,MATCH(1,($G10=SalesforceData!$A$2:$A$36)*(J$2=SalesforceData!$B$2:'SalesforceData'!$B$36)*(J$3=SalesforceData!$C$2:'SalesforceData'!$C$36),0)))=0,INDEX(SalesforceData!$F$2:$F$36,MATCH(1,($G10=SalesforceData!$A$2:$A$36)*(J$2=SalesforceData!$B$2:'SalesforceData'!$B$36) * (J$3=SalesforceData!$E$2:'SalesforceData'!$E$36),0)),INDEX(SalesforceData!$D$2:$D$36,MATCH(1,($G10=SalesforceData!$A$2:$A$36)*(J$2=SalesforceData!$B$2:'SalesforceData'!$B$36)*(J$3=SalesforceData!$C$2:'SalesforceData'!$C$36),0))),"")} -> 0 | K10: {=IFERROR(IF(COUNT(INDEX(SalesforceData!$D$2:$D$36,MATCH(1,($G10=SalesforceData!$A$2:$A$36)*(K$2=SalesforceData!$B$2:'SalesforceData'!$B$36)*(K$3=SalesforceData!$C$2:'SalesforceData'!$C$36),0)))=0,INDEX(SalesforceData!$F$2:$F$36,MATCH(1,($G10=SalesforceData!$A$2:$A$36)*(K$2=SalesforceData!$B$2:'SalesforceData'!$B$36) * (K$3=SalesforceData!$E$2:'SalesforceData'!$E$36),0)),INDEX(SalesforceData!$D$2:$D$36,MATCH(1,($G10=SalesforceData!$A$2:$A$36)*(K$2=SalesforceData!$B$2:'SalesforceData'!$B$36)*(K$3=SalesforceData!$C$2:'SalesforceData'!$C$36),0))),"")} -> 0 | L10: {=IFERROR(IF(COUNT(INDEX(SalesforceData!$D$2:$D$36,MATCH(1,($G10=SalesforceData!$A$2:$A$36)*(L$2=SalesforceData!$B$2:'SalesforceData'!$B$36)*(L$3=SalesforceData!$C$2:'SalesforceData'!$C$36),0)))=0,INDEX(SalesforceData!$F$2:$F$36,MATCH(1,($G10=SalesforceData!$A$2:$A$36)*(L$2=SalesforceData!$B$2:'SalesforceData'!$B$36) * (L$3=SalesforceData!$E$2:'SalesforceData'!$E$36),0)),INDEX(SalesforceData!$D$2:$D$36,MATCH(1,($G10=SalesforceData!$A$2:$A$36)*(L$2=SalesforceData!$B$2:'SalesforceData'!$B$36)*(L$3=SalesforceData!$C$2:'SalesforceData'!$C$36),0))),"")} -> 0 | M10: {=IFERROR(IF(COUNT(INDEX(SalesforceData!$D$2:$D$36,MATCH(1,($G10=SalesforceData!$A$2:$A$36)*(M$2=SalesforceData!$B$2:'SalesforceData'!$B$36)*(M$3=SalesforceData!$C$2:'SalesforceData'!$C$36),0)))=0,INDEX(SalesforceData!$F$2:$F$36,MATCH(1,($G10=SalesforceData!$A$2:$A$36)*(M$2=SalesforceData!$B$2:'SalesforceData'!$B$36) * (M$3=SalesforceData!$E$2:'SalesforceData'!$E$36),0)),INDEX(SalesforceData!$D$2:$D$36,MATCH(1,($G10=SalesforceData!$A$2:$A$36)*(M$2=SalesforceData!$B$2:'SalesforceData'!$B$36)*(M$3=SalesforceData!$C$2:'SalesforceData'!$C$36),0))),"")} -> 0 | N10: {=IFERROR(IF(COUNT(INDEX(SalesforceData!$D$2:$D$36,MATCH(1,($G10=SalesforceData!$A$2:$A$36)*(N$2=SalesforceData!$B$2:'SalesforceData'!$B$36)*(N$3=SalesforceData!$C$2:'SalesforceData'!$C$36),0)))=0,INDEX(SalesforceData!$F$2:$F$36,MATCH(1,($G10=SalesforceData!$A$2:$A$36)*(N$2=SalesforceData!$B$2:'SalesforceData'!$B$36) * (N$3=SalesforceData!$E$2:'SalesforceData'!$E$36),0)),INDEX(SalesforceData!$D$2:$D$36,MATCH(1,($G10=SalesforceData!$A$2:$A$36)*(N$2=SalesforceData!$B$2:'SalesforceData'!$B$36)*(N$3=SalesforceData!$C$2:'SalesforceData'!$C$36),0))),"")} -> 0 | O10: {=IFERROR(IF(COUNT(INDEX(SalesforceData!$D$2:$D$36,MATCH(1,($G10=SalesforceData!$A$2:$A$36)*(O$2=SalesforceData!$B$2:'SalesforceData'!$B$36)*(O$3=SalesforceData!$C$2:'SalesforceData'!$C$36),0)))=0,INDEX(SalesforceData!$F$2:$F$36,MATCH(1,($G10=SalesforceData!$A$2:$A$36)*(O$2=SalesforceData!$B$2:'SalesforceData'!$B$36) * (O$3=SalesforceData!$E$2:'SalesforceData'!$E$36),0)),INDEX(SalesforceData!$D$2:$D$36,MATCH(1,($G10=SalesforceData!$A$2:$A$36)*(O$2=SalesforceData!$B$2:'SalesforceData'!$B$36)*(O$3=SalesforceData!$C$2:'SalesforceData'!$C$36),0))),"")} -> 0 | S10: {=IF(CELL("contents",G10)=0,"",CELL("contents",G10))} | T10: {=IF(CELL("contents",H10)=0,"",CELL("contents",H10))} | U10: {=IF(CELL("contents",I10)=0,"",CELL("contents",I10))} | V10: {=IF(CELL("contents",J10)=0,"",CELL("contents",J10))} | W10: {=IF(CELL("contents",K10)=0,"",CELL("contents",K10))} | X10: {=IF(CELL("contents",L10)=0,"",CELL("contents",L10))} | Y10: {=IF(CELL("contents",M10)=0,"",CELL("contents",M10))} | Z10: {=IF(CELL("contents",N10)=0,"",CELL("contents",N10))} | AA10: {=IF(CELL("contents",O10)=0,"",CELL("contents",O10))}
A11: {=IF(IFERROR(INDEX(SalesforceData!$A$2:'SalesforceData'!$A$36, MATCH(0, COUNTIF(DataTransformation!$A$2:'DataTransformation'!$A10, SalesforceData!$A$2:'SalesforceData'!$A$36), 0)),"") = 0,"", IFERROR(INDEX(SalesforceData!$A$2:'SalesforceData'!$A$36, MATCH(0, COUNTIF(DataTransformation!$A$2:'DataTransformation'!$A10, SalesforceData!$A$2:'SalesforceData'!$A$36), 0)),""))} | B11: {=IF(IFERROR(INDEX(SalesforceData!$B$2:'SalesforceData'!$B$36, MATCH(0, COUNTIF(DataTransformation!$B$2:'DataTransformation'!$B10, SalesforceData!$B$2:'SalesforceData'!$B$36), 0)),"") = 0,"", IFERROR(INDEX(SalesforceData!$B$2:'SalesforceData'!$B$36, MATCH(0, COUNTIF(DataTransformation!$B$2:'DataTransformation'!$B10, SalesforceData!$B$2:'SalesforceData'!$B$36), 0)),""))} | D11: =IF(LEN(C11)>0,"kg","") | G11: =A10 | H11: {=IFERROR(IF(COUNT(INDEX(SalesforceData!$D$2:$D$36,MATCH(1,($G11=SalesforceData!$A$2:$A$36)*(H$2=SalesforceData!$B$2:'SalesforceData'!$B$36)*(H$3=SalesforceData!$C$2:'SalesforceData'!$C$36),0)))=0,INDEX(SalesforceData!$F$2:$F$36,MATCH(1,($G11=SalesforceData!$A$2:$A$36)*(H$2=SalesforceData!$B$2:'SalesforceData'!$B$36) * (H$3=SalesforceData!$E$2:'SalesforceData'!$E$36),0)),INDEX(SalesforceData!$D$2:$D$36,MATCH(1,($G11=SalesforceData!$A$2:$A$36)*(H$2=SalesforceData!$B$2:'SalesforceData'!$B$36)*(H$3=SalesforceData!$C$2:'SalesforceData'!$C$36),0))),"")} -> 0 | I11: {=IFERROR(IF(COUNT(INDEX(SalesforceData!$D$2:$D$36,MATCH(1,($G11=SalesforceData!$A$2:$A$36)*(I$2=SalesforceData!$B$2:'SalesforceData'!$B$36)*(I$3=SalesforceData!$C$2:'SalesforceData'!$C$36),0)))=0,INDEX(SalesforceData!$F$2:$F$36,MATCH(1,($G11=SalesforceData!$A$2:$A$36)*(I$2=SalesforceData!$B$2:'SalesforceData'!$B$36) * (I$3=SalesforceData!$E$2:'SalesforceData'!$E$36),0)),INDEX(SalesforceData!$D$2:$D$36,MATCH(1,($G11=SalesforceData!$A$2:$A$36)*(I$2=SalesforceData!$B$2:'SalesforceData'!$B$36)*(I$3=SalesforceData!$C$2:'SalesforceData'!$C$36),0))),"")} -> 0 | J11: {=IFERROR(IF(COUNT(INDEX(SalesforceData!$D$2:$D$36,MATCH(1,($G11=SalesforceData!$A$2:$A$36)*(J$2=SalesforceData!$B$2:'SalesforceData'!$B$36)*(J$3=SalesforceData!$C$2:'SalesforceData'!$C$36),0)))=0,INDEX(SalesforceData!$F$2:$F$36,MATCH(1,($G11=SalesforceData!$A$2:$A$36)*(J$2=SalesforceData!$B$2:'SalesforceData'!$B$36) * (J$3=SalesforceData!$E$2:'SalesforceData'!$E$36),0)),INDEX(SalesforceData!$D$2:$D$36,MATCH(1,($G11=SalesforceData!$A$2:$A$36)*(J$2=SalesforceData!$B$2:'SalesforceData'!$B$36)*(J$3=SalesforceData!$C$2:'SalesforceData'!$C$36),0))),"")} -> 0 | K11: {=IFERROR(IF(COUNT(INDEX(SalesforceData!$D$2:$D$36,MATCH(1,($G11=SalesforceData!$A$2:$A$36)*(K$2=SalesforceData!$B$2:'SalesforceData'!$B$36)*(K$3=SalesforceData!$C$2:'SalesforceData'!$C$36),0)))=0,INDEX(SalesforceData!$F$2:$F$36,MATCH(1,($G11=SalesforceData!$A$2:$A$36)*(K$2=SalesforceData!$B$2:'SalesforceData'!$B$36) * (K$3=SalesforceData!$E$2:'SalesforceData'!$E$36),0)),INDEX(SalesforceData!$D$2:$D$36,MATCH(1,($G11=SalesforceData!$A$2:$A$36)*(K$2=SalesforceData!$B$2:'SalesforceData'!$B$36)*(K$3=SalesforceData!$C$2:'SalesforceData'!$C$36),0))),"")} -> 0 | L11: {=IFERROR(IF(COUNT(INDEX(SalesforceData!$D$2:$D$36,MATCH(1,($G11=SalesforceData!$A$2:$A$36)*(L$2=SalesforceData!$B$2:'SalesforceData'!$B$36)*(L$3=SalesforceData!$C$2:'SalesforceData'!$C$36),0)))=0,INDEX(SalesforceData!$F$2:$F$36,MATCH(1,($G11=SalesforceData!$A$2:$A$36)*(L$2=SalesforceData!$B$2:'SalesforceData'!$B$36) * (L$3=SalesforceData!$E$2:'SalesforceData'!$E$36),0)),INDEX(SalesforceData!$D$2:$D$36,MATCH(1,($G11=SalesforceData!$A$2:$A$36)*(L$2=SalesforceData!$B$2:'SalesforceData'!$B$36)*(L$3=SalesforceData!$C$2:'SalesforceData'!$C$36),0))),"")} -> 0 | M11: {=IFERROR(IF(COUNT(INDEX(SalesforceData!$D$2:$D$36,MATCH(1,($G11=SalesforceData!$A$2:$A$36)*(M$2=SalesforceData!$B$2:'SalesforceData'!$B$36)*(M$3=SalesforceData!$C$2:'SalesforceData'!$C$36),0)))=0,INDEX(SalesforceData!$F$2:$F$36,MATCH(1,($G11=SalesforceData!$A$2:$A$36)*(M$2=SalesforceData!$B$2:'SalesforceData'!$B$36) * (M$3=SalesforceData!$E$2:'SalesforceData'!$E$36),0)),INDEX(SalesforceData!$D$2:$D$36,MATCH(1,($G11=SalesforceData!$A$2:$A$36)*(M$2=SalesforceData!$B$2:'SalesforceData'!$B$36)*(M$3=SalesforceData!$C$2:'SalesforceData'!$C$36),0))),"")} -> 0 | N11: {=IFERROR(IF(COUNT(INDEX(SalesforceData!$D$2:$D$36,MATCH(1,($G11=SalesforceData!$A$2:$A$36)*(N$2=SalesforceData!$B$2:'SalesforceData'!$B$36)*(N$3=SalesforceData!$C$2:'SalesforceData'!$C$36),0)))=0,INDEX(SalesforceData!$F$2:$F$36,MATCH(1,($G11=SalesforceData!$A$2:$A$36)*(N$2=SalesforceData!$B$2:'SalesforceData'!$B$36) * (N$3=SalesforceData!$E$2:'SalesforceData'!$E$36),0)),INDEX(SalesforceData!$D$2:$D$36,MATCH(1,($G11=SalesforceData!$A$2:$A$36)*(N$2=SalesforceData!$B$2:'SalesforceData'!$B$36)*(N$3=SalesforceData!$C$2:'SalesforceData'!$C$36),0))),"")} -> 0 | O11: {=IFERROR(IF(COUNT(INDEX(SalesforceData!$D$2:$D$36,MATCH(1,($G11=SalesforceData!$A$2:$A$36)*(O$2=SalesforceData!$B$2:'SalesforceData'!$B$36)*(O$3=SalesforceData!$C$2:'SalesforceData'!$C$36),0)))=0,INDEX(SalesforceData!$F$2:$F$36,MATCH(1,($G11=SalesforceData!$A$2:$A$36)*(O$2=SalesforceData!$B$2:'SalesforceData'!$B$36) * (O$3=SalesforceData!$E$2:'SalesforceData'!$E$36),0)),INDEX(SalesforceData!$D$2:$D$36,MATCH(1,($G11=SalesforceData!$A$2:$A$36)*(O$2=SalesforceData!$B$2:'SalesforceData'!$B$36)*(O$3=SalesforceData!$C$2:'SalesforceData'!$C$36),0))),"")} -> 0 | S11: {=IF(CELL("contents",G11)=0,"",CELL("contents",G11))} | T11: {=IF(CELL("contents",H11)=0,"",CELL("contents",H11))} | U11: {=IF(CELL("contents",I11)=0,"",CELL("contents",I11))} | V11: {=IF(CELL("contents",J11)=0,"",CELL("contents",J11))} | W11: {=IF(CELL("contents",K11)=0,"",CELL("contents",K11))} | X11: {=IF(CELL("contents",L11)=0,"",CELL("contents",L11))} | Y11: {=IF(CELL("contents",M11)=0,"",CELL("contents",M11))} | Z11: {=IF(CELL("contents",N11)=0,"",CELL("contents",N11))} | AA11: {=IF(CELL("contents",O11)=0,"",CELL("contents",O11))}
A12: {=IF(IFERROR(INDEX(SalesforceData!$A$2:'SalesforceData'!$A$36, MATCH(0, COUNTIF(DataTransformation!$A$2:'DataTransformation'!$A11, SalesforceData!$A$2:'SalesforceData'!$A$36), 0)),"") = 0,"", IFERROR(INDEX(SalesforceData!$A$2:'SalesforceData'!$A$36, MATCH(0, COUNTIF(DataTransformation!$A$2:'DataTransformation'!$A11, SalesforceData!$A$2:'SalesforceData'!$A$36), 0)),""))} | B12: {=IF(IFERROR(INDEX(SalesforceData!$B$2:'SalesforceData'!$B$36, MATCH(0, COUNTIF(DataTransformation!$B$2:'DataTransformation'!$B11, SalesforceData!$B$2:'SalesforceData'!$B$36), 0)),"") = 0,"", IFERROR(INDEX(SalesforceData!$B$2:'SalesforceData'!$B$36, MATCH(0, COUNTIF(DataTransformation!$B$2:'DataTransformation'!$B11, SalesforceData!$B$2:'SalesforceData'!$B$36), 0)),""))} | G12: =A11 | H12: {=IFERROR(IF(COUNT(INDEX(SalesforceData!$D$2:$D$36,MATCH(1,($G12=SalesforceData!$A$2:$A$36)*(H$2=SalesforceData!$B$2:'SalesforceData'!$B$36)*(H$3=SalesforceData!$C$2:'SalesforceData'!$C$36),0)))=0,INDEX(SalesforceData!$F$2:$F$36,MATCH(1,($G12=SalesforceData!$A$2:$A$36)*(H$2=SalesforceData!$B$2:'SalesforceData'!$B$36) * (H$3=SalesforceData!$E$2:'SalesforceData'!$E$36),0)),INDEX(SalesforceData!$D$2:$D$36,MATCH(1,($G12=SalesforceData!$A$2:$A$36)*(H$2=SalesforceData!$B$2:'SalesforceData'!$B$36)*(H$3=SalesforceData!$C$2:'SalesforceData'!$C$36),0))),"")} -> 0 | I12: {=IFERROR(IF(COUNT(INDEX(SalesforceData!$D$2:$D$36,MATCH(1,($G12=SalesforceData!$A$2:$A$36)*(I$2=SalesforceData!$B$2:'SalesforceData'!$B$36)*(I$3=SalesforceData!$C$2:'SalesforceData'!$C$36),0)))=0,INDEX(SalesforceData!$F$2:$F$36,MATCH(1,($G12=SalesforceData!$A$2:$A$36)*(I$2=SalesforceData!$B$2:'SalesforceData'!$B$36) * (I$3=SalesforceData!$E$2:'SalesforceData'!$E$36),0)),INDEX(SalesforceData!$D$2:$D$36,MATCH(1,($G12=SalesforceData!$A$2:$A$36)*(I$2=SalesforceData!$B$2:'SalesforceData'!$B$36)*(I$3=SalesforceData!$C$2:'SalesforceData'!$C$36),0))),"")} -> 0 | J12: {=IFERROR(IF(COUNT(INDEX(SalesforceData!$D$2:$D$36,MATCH(1,($G12=SalesforceData!$A$2:$A$36)*(J$2=SalesforceData!$B$2:'SalesforceData'!$B$36)*(J$3=SalesforceData!$C$2:'SalesforceData'!$C$36),0)))=0,INDEX(SalesforceData!$F$2:$F$36,MATCH(1,($G12=SalesforceData!$A$2:$A$36)*(J$2=SalesforceData!$B$2:'SalesforceData'!$B$36) * (J$3=SalesforceData!$E$2:'SalesforceData'!$E$36),0)),INDEX(SalesforceData!$D$2:$D$36,MATCH(1,($G12=SalesforceData!$A$2:$A$36)*(J$2=SalesforceData!$B$2:'SalesforceData'!$B$36)*(J$3=SalesforceData!$C$2:'SalesforceData'!$C$36),0))),"")} -> 0 | K12: {=IFERROR(IF(COUNT(INDEX(SalesforceData!$D$2:$D$36,MATCH(1,($G12=SalesforceData!$A$2:$A$36)*(K$2=SalesforceData!$B$2:'SalesforceData'!$B$36)*(K$3=SalesforceData!$C$2:'SalesforceData'!$C$36),0)))=0,INDEX(SalesforceData!$F$2:$F$36,MATCH(1,($G12=SalesforceData!$A$2:$A$36)*(K$2=SalesforceData!$B$2:'SalesforceData'!$B$36) * (K$3=SalesforceData!$E$2:'SalesforceData'!$E$36),0)),INDEX(SalesforceData!$D$2:$D$36,MATCH(1,($G12=SalesforceData!$A$2:$A$36)*(K$2=SalesforceData!$B$2:'SalesforceData'!$B$36)*(K$3=SalesforceData!$C$2:'SalesforceData'!$C$36),0))),"")} -> 0 | L12: {=IFERROR(IF(COUNT(INDEX(SalesforceData!$D$2:$D$36,MATCH(1,($G12=SalesforceData!$A$2:$A$36)*(L$2=SalesforceData!$B$2:'SalesforceData'!$B$36)*(L$3=SalesforceData!$C$2:'SalesforceData'!$C$36),0)))=0,INDEX(SalesforceData!$F$2:$F$36,MATCH(1,($G12=SalesforceData!$A$2:$A$36)*(L$2=SalesforceData!$B$2:'SalesforceData'!$B$36) * (L$3=SalesforceData!$E$2:'SalesforceData'!$E$36),0)),INDEX(SalesforceData!$D$2:$D$36,MATCH(1,($G12=SalesforceData!$A$2:$A$36)*(L$2=SalesforceData!$B$2:'SalesforceData'!$B$36)*(L$3=SalesforceData!$C$2:'SalesforceData'!$C$36),0))),"")} -> 0 | M12: {=IFERROR(IF(COUNT(INDEX(SalesforceData!$D$2:$D$36,MATCH(1,($G12=SalesforceData!$A$2:$A$36)*(M$2=SalesforceData!$B$2:'SalesforceData'!$B$36)*(M$3=SalesforceData!$C$2:'SalesforceData'!$C$36),0)))=0,INDEX(SalesforceData!$F$2:$F$36,MATCH(1,($G12=SalesforceData!$A$2:$A$36)*(M$2=SalesforceData!$B$2:'SalesforceData'!$B$36) * (M$3=SalesforceData!$E$2:'SalesforceData'!$E$36),0)),INDEX(SalesforceData!$D$2:$D$36,MATCH(1,($G12=SalesforceData!$A$2:$A$36)*(M$2=SalesforceData!$B$2:'SalesforceData'!$B$36)*(M$3=SalesforceData!$C$2:'SalesforceData'!$C$36),0))),"")} -> 0 | N12: {=IFERROR(IF(COUNT(INDEX(SalesforceData!$D$2:$D$36,MATCH(1,($G12=SalesforceData!$A$2:$A$36)*(N$2=SalesforceData!$B$2:'SalesforceData'!$B$36)*(N$3=SalesforceData!$C$2:'SalesforceData'!$C$36),0)))=0,INDEX(SalesforceData!$F$2:$F$36,MATCH(1,($G12=SalesforceData!$A$2:$A$36)*(N$2=SalesforceData!$B$2:'SalesforceData'!$B$36) * (N$3=SalesforceData!$E$2:'SalesforceData'!$E$36),0)),INDEX(SalesforceData!$D$2:$D$36,MATCH(1,($G12=SalesforceData!$A$2:$A$36)*(N$2=SalesforceData!$B$2:'SalesforceData'!$B$36)*(N$3=SalesforceData!$C$2:'SalesforceData'!$C$36),0))),"")} -> 0 | O12: {=IFERROR(IF(COUNT(INDEX(SalesforceData!$D$2:$D$36,MATCH(1,($G12=SalesforceData!$A$2:$A$36)*(O$2=SalesforceData!$B$2:'SalesforceData'!$B$36)*(O$3=SalesforceData!$C$2:'SalesforceData'!$C$36),0)))=0,INDEX(SalesforceData!$F$2:$F$36,MATCH(1,($G12=SalesforceData!$A$2:$A$36)*(O$2=SalesforceData!$B$2:'SalesforceData'!$B$36) * (O$3=SalesforceData!$E$2:'SalesforceData'!$E$36),0)),INDEX(SalesforceData!$D$2:$D$36,MATCH(1,($G12=SalesforceData!$A$2:$A$36)*(O$2=SalesforceData!$B$2:'SalesforceData'!$B$36)*(O$3=SalesforceData!$C$2:'SalesforceData'!$C$36),0))),"")} -> 0 | S12: {=IF(CELL("contents",G12)=0,"",CELL("contents",G12))} | T12: {=IF(CELL("contents",H12)=0,"",CELL("contents",H12))} | U12: {=IF(CELL("contents",I12)=0,"",CELL("contents",I12))} | V12: {=IF(CELL("contents",J12)=0,"",CELL("contents",J12))} | W12: {=IF(CELL("contents",K12)=0,"",CELL("contents",K12))} | X12: {=IF(CELL("contents",L12)=0,"",CELL("contents",L12))} | Y12: {=IF(CELL("contents",M12)=0,"",CELL("contents",M12))} | Z12: {=IF(CELL("contents",N12)=0,"",CELL("contents",N12))} | AA12: {=IF(CELL("contents",O12)=0,"",CELL("contents",O12))}
