Workbook
Name Both_FH_FC.Assembly_Id: PBH_RR!$D$3
Name Both_FH_FC.Assembly_Name: PBH_RR!$C$3
Name Both_FH_FC.Invoice.Rent.Stepped_Rent_Local_Currency_local: PBH_RR!$N$3
Name Both_FH_FC.PBH_Rent_Assembly.PBH_Rent_Rate_From_Value__000: PBH_RR!$G$3
Name Both_FH_FC.PBH_Rent_Assembly.PBH_Rent_Rate_From_Value_FC__000: PBH_RR!$H$3
Name Both_FH_FC.PBH_Rent_Assembly.PBH_Rent_Rate_Id: PBH_RR!$A$3
Name Both_FH_FC.PBH_Rent_Assembly.PBH_Rent_Rate_PBH_Rate: PBH_RR!$I$3
Name Both_FH_FC.PBH_Rent_Assembly.PBH_Rent_Rate_PBH_Rate_FC: PBH_RR!$J$3
Name Both_FH_FC.PBH_Rent_Assembly.PBH_Rent_Rate_Selection: PBH_RR!$F$3
Name Both_FH_FC.PBH_Rent_Assembly.Rent_Schedule.Stepped_Rent_Id: PBH_RR!$K$3
Name Both_FH_FC.PBH_Rent_Assembly_PBH_Rate_F: PBH_RR!#REF!
Name Both_FH_FC.PBH_Rent_Assembly_Rate_Basis_F: PBH_RR!$E$3
Name Both_FH_FC.PBH_Rent_Assembly_Unit_Type: PBH_RR!$L$3
Name Both_FH_FC.PBH_Rent_Assembly_Utilization_Unit__000: PBH_RR!$M$3
Name Both_FH_FC_Converted_Currency_Line_Amount: PBH_RR!$O$3
Name Both_FH_FC_Start: PBH_RR!$A$3:$Q$3
Name Both_FH_FC_Total_Line_Amount: PBH_RR!$Q$3
Name ILI_TO_Rate: Sheet1!$A$1:$H$99
Name ILI_TO_RentRate.Assembly_Id: SF_Data!$B$2
Name ILI_TO_RentRate.Assembly_Name: SF_Data!$D$2
Name ILI_TO_RentRate.Invoice.Rent.Stepped_Rent_Local_Currency_local: SF_Data!$J$2
Name ILI_TO_RentRate.PBH_Rent_Assembly.PBH_Rent_Rate_From_Value__000: SF_Data!$Q$2
Name ILI_TO_RentRate.PBH_Rent_Assembly.PBH_Rent_Rate_From_Value_FC__000: SF_Data!$R$2
Name ILI_TO_RentRate.PBH_Rent_Assembly.PBH_Rent_Rate_Id: SF_Data!$N$2
Name ILI_TO_RentRate.PBH_Rent_Assembly.PBH_Rent_Rate_Name: SF_Data!$O$2
Name ILI_TO_RentRate.PBH_Rent_Assembly.PBH_Rent_Rate_PBH_Rate: SF_Data!$S$2
Name ILI_TO_RentRate.PBH_Rent_Assembly.PBH_Rent_Rate_PBH_Rate_FC: SF_Data!$T$2
Name ILI_TO_RentRate.PBH_Rent_Assembly.PBH_Rent_Rate_Selection: SF_Data!$P$2
Name ILI_TO_RentRate.PBH_Rent_Assembly.Rent_Schedule.Stepped_Rent_Id: SF_Data!$E$2
Name ILI_TO_RentRate.PBH_Rent_Assembly_Id: SF_Data!$C$2
Name ILI_TO_RentRate.PBH_Rent_Assembly_Name: SF_Data!$A$2
Name ILI_TO_RentRate.PBH_Rent_Assembly_PBH_Rate_F: SF_Data!$H$2
Name ILI_TO_RentRate.PBH_Rent_Assembly_Rate_Basis_F: SF_Data!$F$2
Name ILI_TO_RentRate.PBH_Rent_Assembly_Unit_Type: SF_Data!$M$2
Name ILI_TO_RentRate.PBH_Rent_Assembly_Utilization_Unit__000: SF_Data!$G$2
Name ILI_TO_RentRate_Converted_Currency_Line_Amount: SF_Data!$I$2
Name ILI_TO_RentRate_Start: SF_Data!$A$2:$T$2
Name ILI_TO_RentRate_Total_Line_Amount: SF_Data!$K$2
Name PBH_Line.PBH_Rent_Assembly_Id: PBH_Lines!$E$2
Name PBH_Line.PBH_Rent_Assembly_Rate_Basis_F: PBH_Lines!$C$2
Name PBH_Line.PBH_Rent_Rate_Id: PBH_Lines!$D$2
Name PBH_Line_Name: PBH_Lines!$A$2
Name PBH_Line_PBH_Amount__000: PBH_Lines!$F$2
Name PBH_Line_Start: PBH_Lines!$A$2:$F$2
Name PBH_Line_Utilization_Unit__000: PBH_Lines!$B$2
Name PBH_RR.Associated_Assembly_Id: PBH_RR!$D$2
Name PBH_RR.Associated_Assembly_Name: PBH_RR!$C$2
Name PBH_RR.Multi_Rent_Schedule_Id: PBH_RR!$K$2
Name PBH_RR_From_Value__000: PBH_RR!$G$2
Name PBH_RR_From_Value_FC__000: PBH_RR!$H$2
Name PBH_RR_Id: PBH_RR!$A$2
Name PBH_RR_Multi_Rent_Schedule: #REF!
Name PBH_RR_Name: PBH_RR!$B$2
Name PBH_RR_PBH_Rate: PBH_RR!$I$2
Name PBH_RR_PBH_Rate_FC: PBH_RR!$J$2
Name PBH_RR_Rate_Basis_F: PBH_RR!$E$2
Name PBH_RR_Selection: PBH_RR!$F$2
Name PBH_RR_Start: PBH_RR!$A$2:$K$2
Name RateValue: Sheet1!$J$1:$Q$100

Sheet SF_Data
A1: PBH Name | B1: Assembly | C1: PBH Assembly ID | D1: Assembly Name | E1: Rent Schedule Id | F1: Rate Basis | G1: Utilization Unit | H1: Rate | I1: ILI Cnvrt Amt | J1: Local Currency | K1: Total Amount | L1: Utilization Unit | M1: Unit Type | N1: PBH Rate Id | O1: Pbh Rate Name | P1: Selection | Q1: From (FH) | R1: From (FC) | S1: PBH (FH) | T1: PBH (FC) | U1: Final Amount
U2: =IF(A2="","",IF(J2="",K2,I2))
U3: =IF(A3="","",IF(J3="",K3,I3))
U4: =IF(A4="","",IF(J4="",K4,I4))
U5: =IF(A5="","",IF(J5="",K5,I5))
U6: =IF(A6="","",IF(J6="",K6,I6))
U7: =IF(A7="","",IF(J7="",K7,I7))
U8: =IF(A8="","",IF(J8="",K8,I8))
U9: =IF(A9="","",IF(J9="",K9,I9))
U10: =IF(A10="","",IF(J10="",K10,I10))
U11: =IF(A11="","",IF(J11="",K11,I11))
U12: =IF(A12="","",IF(J12="",K12,I12))
U13: =IF(A13="","",IF(J13="",K13,I13))
... U200: =IF(A200="","",IF(J200="",K200,I200))

Sheet PBH_Lines
A1: Name | B1: Utilization Unit | C1: Rate Basis | D1: PBH RR ID | E1: PBH Assembly ID | F1: Amount | J1: Name | K1: Utilization Unit | L1: Rate Basis | M1: PBH RR ID | N1: PBH Assembly ID | O1: Amount
G2: =IF(A2="","",IF(COUNTIF(SF_Data!C:C,E2)>0,TRUE,FALSE)) | H2: =IF(G2=TRUE,A2,"") | J2: {=IFERROR(INDEX($H$2:$H$1000,SMALL(IF($H$2:$H$1000<>"",ROW($H$2:$H$1000)-1),ROW(1:1))),"")} | K2: =IF(J2="","",INDEX(B:B,MATCH(J2,A:A,0))) | L2: =IF(J2="","",INDEX(C:C,MATCH(J2,A:A,0))) | M2: =IF(J2="","",INDEX(D:D,MATCH(J2,A:A,0))) | N2: =IF(J2="","",INDEX(E:E,MATCH(J2,A:A,0))) | O2: =IF(J2="","",INDEX(F:F,MATCH(J2,A:A,0)))
G3: =IF(A3="","",IF(COUNTIF(SF_Data!C:C,E3)>0,TRUE,FALSE)) | H3: =IF(G3=TRUE,A3,"") | J3: {=IFERROR(INDEX($H$2:$H$1000,SMALL(IF($H$2:$H$1000<>"",ROW($H$2:$H$1000)-1),ROW(2:2))),"")} | K3: =IF(J3="","",INDEX(B:B,MATCH(J3,A:A,0))) | L3: =IF(J3="","",INDEX(C:C,MATCH(J3,A:A,0))) | M3: =IF(J3="","",INDEX(D:D,MATCH(J3,A:A,0))) | N3: =IF(J3="","",INDEX(E:E,MATCH(J3,A:A,0))) | O3: =IF(J3="","",INDEX(F:F,MATCH(J3,A:A,0)))
G4: =IF(A4="","",IF(COUNTIF(SF_Data!C:C,E4)>0,TRUE,FALSE)) | H4: =IF(G4=TRUE,A4,"") | J4: {=IFERROR(INDEX($H$2:$H$1000,SMALL(IF($H$2:$H$1000<>"",ROW($H$2:$H$1000)-1),ROW(3:3))),"")} | K4: =IF(J4="","",INDEX(B:B,MATCH(J4,A:A,0))) | L4: =IF(J4="","",INDEX(C:C,MATCH(J4,A:A,0))) | M4: =IF(J4="","",INDEX(D:D,MATCH(J4,A:A,0))) | N4: =IF(J4="","",INDEX(E:E,MATCH(J4,A:A,0))) | O4: =IF(J4="","",INDEX(F:F,MATCH(J4,A:A,0)))
G5: =IF(A5="","",IF(COUNTIF(SF_Data!C:C,E5)>0,TRUE,FALSE)) | H5: =IF(G5=TRUE,A5,"") | J5: {=IFERROR(INDEX($H$2:$H$1000,SMALL(IF($H$2:$H$1000<>"",ROW($H$2:$H$1000)-1),ROW(4:4))),"")} | K5: =IF(J5="","",INDEX(B:B,MATCH(J5,A:A,0))) | L5: =IF(J5="","",INDEX(C:C,MATCH(J5,A:A,0))) | M5: =IF(J5="","",INDEX(D:D,MATCH(J5,A:A,0))) | N5: =IF(J5="","",INDEX(E:E,MATCH(J5,A:A,0))) | O5: =IF(J5="","",INDEX(F:F,MATCH(J5,A:A,0)))
G6: =IF(A6="","",IF(COUNTIF(SF_Data!C:C,E6)>0,TRUE,FALSE)) | H6: =IF(G6=TRUE,A6,"") | J6: {=IFERROR(INDEX($H$2:$H$1000,SMALL(IF($H$2:$H$1000<>"",ROW($H$2:$H$1000)-1),ROW(5:5))),"")} | K6: =IF(J6="","",INDEX(B:B,MATCH(J6,A:A,0))) | L6: =IF(J6="","",INDEX(C:C,MATCH(J6,A:A,0))) | M6: =IF(J6="","",INDEX(D:D,MATCH(J6,A:A,0))) | N6: =IF(J6="","",INDEX(E:E,MATCH(J6,A:A,0))) | O6: =IF(J6="","",INDEX(F:F,MATCH(J6,A:A,0)))
G7: =IF(A7="","",IF(COUNTIF(SF_Data!C:C,E7)>0,TRUE,FALSE)) | H7: =IF(G7=TRUE,A7,"") | J7: {=IFERROR(INDEX($H$2:$H$1000,SMALL(IF($H$2:$H$1000<>"",ROW($H$2:$H$1000)-1),ROW(6:6))),"")} | K7: =IF(J7="","",INDEX(B:B,MATCH(J7,A:A,0))) | L7: =IF(J7="","",INDEX(C:C,MATCH(J7,A:A,0))) | M7: =IF(J7="","",INDEX(D:D,MATCH(J7,A:A,0))) | N7: =IF(J7="","",INDEX(E:E,MATCH(J7,A:A,0))) | O7: =IF(J7="","",INDEX(F:F,MATCH(J7,A:A,0)))
G8: =IF(A8="","",IF(COUNTIF(SF_Data!C:C,E8)>0,TRUE,FALSE)) | H8: =IF(G8=TRUE,A8,"") | J8: {=IFERROR(INDEX($H$2:$H$1000,SMALL(IF($H$2:$H$1000<>"",ROW($H$2:$H$1000)-1),ROW(7:7))),"")} | K8: =IF(J8="","",INDEX(B:B,MATCH(J8,A:A,0))) | L8: =IF(J8="","",INDEX(C:C,MATCH(J8,A:A,0))) | M8: =IF(J8="","",INDEX(D:D,MATCH(J8,A:A,0))) | N8: =IF(J8="","",INDEX(E:E,MATCH(J8,A:A,0))) | O8: =IF(J8="","",INDEX(F:F,MATCH(J8,A:A,0)))
G9: =IF(A9="","",IF(COUNTIF(SF_Data!C:C,E9)>0,TRUE,FALSE)) | H9: =IF(G9=TRUE,A9,"") | J9: {=IFERROR(INDEX($H$2:$H$1000,SMALL(IF($H$2:$H$1000<>"",ROW($H$2:$H$1000)-1),ROW(8:8))),"")} | K9: =IF(J9="","",INDEX(B:B,MATCH(J9,A:A,0))) | L9: =IF(J9="","",INDEX(C:C,MATCH(J9,A:A,0))) | M9: =IF(J9="","",INDEX(D:D,MATCH(J9,A:A,0))) | N9: =IF(J9="","",INDEX(E:E,MATCH(J9,A:A,0))) | O9: =IF(J9="","",INDEX(F:F,MATCH(J9,A:A,0)))
G10: =IF(A10="","",IF(COUNTIF(SF_Data!C:C,E10)>0,TRUE,FALSE)) | H10: =IF(G10=TRUE,A10,"") | J10: {=IFERROR(INDEX($H$2:$H$1000,SMALL(IF($H$2:$H$1000<>"",ROW($H$2:$H$1000)-1),ROW(9:9))),"")} | K10: =IF(J10="","",INDEX(B:B,MATCH(J10,A:A,0))) | L10: =IF(J10="","",INDEX(C:C,MATCH(J10,A:A,0))) | M10: =IF(J10="","",INDEX(D:D,MATCH(J10,A:A,0))) | N10: =IF(J10="","",INDEX(E:E,MATCH(J10,A:A,0))) | O10: =IF(J10="","",INDEX(F:F,MATCH(J10,A:A,0)))
G11: =IF(A11="","",IF(COUNTIF(SF_Data!C:C,E11)>0,TRUE,FALSE)) | H11: =IF(G11=TRUE,A11,"") | J11: {=IFERROR(INDEX($H$2:$H$1000,SMALL(IF($H$2:$H$1000<>"",ROW($H$2:$H$1000)-1),ROW(10:10))),"")} | K11: =IF(J11="","",INDEX(B:B,MATCH(J11,A:A,0))) | L11: =IF(J11="","",INDEX(C:C,MATCH(J11,A:A,0))) | M11: =IF(J11="","",INDEX(D:D,MATCH(J11,A:A,0))) | N11: =IF(J11="","",INDEX(E:E,MATCH(J11,A:A,0))) | O11: =IF(J11="","",INDEX(F:F,MATCH(J11,A:A,0)))
G12: =IF(A12="","",IF(COUNTIF(SF_Data!C:C,E12)>0,TRUE,FALSE)) | H12: =IF(G12=TRUE,A12,"") | J12: {=IFERROR(INDEX($H$2:$H$1000,SMALL(IF($H$2:$H$1000<>"",ROW($H$2:$H$1000)-1),ROW(11:11))),"")} | K12: =IF(J12="","",INDEX(B:B,MATCH(J12,A:A,0))) | L12: =IF(J12="","",INDEX(C:C,MATCH(J12,A:A,0))) | M12: =IF(J12="","",INDEX(D:D,MATCH(J12,A:A,0))) | N12: =IF(J12="","",INDEX(E:E,MATCH(J12,A:A,0))) | O12: =IF(J12="","",INDEX(F:F,MATCH(J12,A:A,0)))
G13: =IF(A13="","",IF(COUNTIF(SF_Data!C:C,E13)>0,TRUE,FALSE)) | H13: =IF(G13=TRUE,A13,"") | J13: {=IFERROR(INDEX($H$2:$H$1000,SMALL(IF($H$2:$H$1000<>"",ROW($H$2:$H$1000)-1),ROW(12:12))),"")} | K13: =IF(J13="","",INDEX(B:B,MATCH(J13,A:A,0))) | L13: =IF(J13="","",INDEX(C:C,MATCH(J13,A:A,0))) | M13: =IF(J13="","",INDEX(D:D,MATCH(J13,A:A,0))) | N13: =IF(J13="","",INDEX(E:E,MATCH(J13,A:A,0))) | O13: =IF(J13="","",INDEX(F:F,MATCH(J13,A:A,0)))
G14: =IF(A14="","",IF(COUNTIF(SF_Data!C:C,E14)>0,TRUE,FALSE)) | H14: =IF(G14=TRUE,A14,"") | J14: {=IFERROR(INDEX($H$2:$H$1000,SMALL(IF($H$2:$H$1000<>"",ROW($H$2:$H$1000)-1),ROW(13:13))),"")} | K14: =IF(J14="","",INDEX(B:B,MATCH(J14,A:A,0))) | L14: =IF(J14="","",INDEX(C:C,MATCH(J14,A:A,0))) | M14: =IF(J14="","",INDEX(D:D,MATCH(J14,A:A,0))) | N14: =IF(J14="","",INDEX(E:E,MATCH(J14,A:A,0))) | O14: =IF(J14="","",INDEX(F:F,MATCH(J14,A:A,0)))
G15: =IF(A15="","",IF(COUNTIF(SF_Data!C:C,E15)>0,TRUE,FALSE)) | H15: =IF(G15=TRUE,A15,"") | J15: {=IFERROR(INDEX($H$2:$H$1000,SMALL(IF($H$2:$H$1000<>"",ROW($H$2:$H$1000)-1),ROW(14:14))),"")} | K15: =IF(J15="","",INDEX(B:B,MATCH(J15,A:A,0))) | L15: =IF(J15="","",INDEX(C:C,MATCH(J15,A:A,0))) | M15: =IF(J15="","",INDEX(D:D,MATCH(J15,A:A,0))) | N15: =IF(J15="","",INDEX(E:E,MATCH(J15,A:A,0))) | O15: =IF(J15="","",INDEX(F:F,MATCH(J15,A:A,0)))
G16: =IF(A16="","",IF(COUNTIF(SF_Data!C:C,E16)>0,TRUE,FALSE)) | H16: =IF(G16=TRUE,A16,"") | J16: {=IFERROR(INDEX($H$2:$H$1000,SMALL(IF($H$2:$H$1000<>"",ROW($H$2:$H$1000)-1),ROW(15:15))),"")} | K16: =IF(J16="","",INDEX(B:B,MATCH(J16,A:A,0))) | L16: =IF(J16="","",INDEX(C:C,MATCH(J16,A:A,0))) | M16: =IF(J16="","",INDEX(D:D,MATCH(J16,A:A,0))) | N16: =IF(J16="","",INDEX(E:E,MATCH(J16,A:A,0))) | O16: =IF(J16="","",INDEX(F:F,MATCH(J16,A:A,0)))
G17: =IF(A17="","",IF(COUNTIF(SF_Data!C:C,E17)>0,TRUE,FALSE)) | H17: =IF(G17=TRUE,A17,"") | J17: {=IFERROR(INDEX($H$2:$H$1000,SMALL(IF($H$2:$H$1000<>"",ROW($H$2:$H$1000)-1),ROW(16:16))),"")} | K17: =IF(J17="","",INDEX(B:B,MATCH(J17,A:A,0))) | L17: =IF(J17="","",INDEX(C:C,MATCH(J17,A:A,0))) | M17: =IF(J17="","",INDEX(D:D,MATCH(J17,A:A,0))) | N17: =IF(J17="","",INDEX(E:E,MATCH(J17,A:A,0))) | O17: =IF(J17="","",INDEX(F:F,MATCH(J17,A:A,0)))
G18: =IF(A18="","",IF(COUNTIF(SF_Data!C:C,E18)>0,TRUE,FALSE)) | H18: =IF(G18=TRUE,A18,"") | J18: {=IFERROR(INDEX($H$2:$H$1000,SMALL(IF($H$2:$H$1000<>"",ROW($H$2:$H$1000)-1),ROW(17:17))),"")} | K18: =IF(J18="","",INDEX(B:B,MATCH(J18,A:A,0))) | L18: =IF(J18="","",INDEX(C:C,MATCH(J18,A:A,0))) | M18: =IF(J18="","",INDEX(D:D,MATCH(J18,A:A,0))) | N18: =IF(J18="","",INDEX(E:E,MATCH(J18,A:A,0))) | O18: =IF(J18="","",INDEX(F:F,MATCH(J18,A:A,0)))
G19: =IF(A19="","",IF(COUNTIF(SF_Data!C:C,E19)>0,TRUE,FALSE)) | H19: =IF(G19=TRUE,A19,"") | J19: {=IFERROR(INDEX($H$2:$H$1000,SMALL(IF($H$2:$H$1000<>"",ROW($H$2:$H$1000)-1),ROW(18:18))),"")} | K19: =IF(J19="","",INDEX(B:B,MATCH(J19,A:A,0))) | L19: =IF(J19="","",INDEX(C:C,MATCH(J19,A:A,0))) | M19: =IF(J19="","",INDEX(D:D,MATCH(J19,A:A,0))) | N19: =IF(J19="","",INDEX(E:E,MATCH(J19,A:A,0))) | O19: =IF(J19="","",INDEX(F:F,MATCH(J19,A:A,0)))
G20: =IF(A20="","",IF(COUNTIF(SF_Data!C:C,E20)>0,TRUE,FALSE)) | H20: =IF(G20=TRUE,A20,"") | J20: {=IFERROR(INDEX($H$2:$H$1000,SMALL(IF($H$2:$H$1000<>"",ROW($H$2:$H$1000)-1),ROW(19:19))),"")} | K20: =IF(J20="","",INDEX(B:B,MATCH(J20,A:A,0))) | L20: =IF(J20="","",INDEX(C:C,MATCH(J20,A:A,0))) | M20: =IF(J20="","",INDEX(D:D,MATCH(J20,A:A,0))) | N20: =IF(J20="","",INDEX(E:E,MATCH(J20,A:A,0))) | O20: =IF(J20="","",INDEX(F:F,MATCH(J20,A:A,0)))
G21: =IF(A21="","",IF(COUNTIF(SF_Data!C:C,E21)>0,TRUE,FALSE)) | H21: =IF(G21=TRUE,A21,"") | J21: {=IFERROR(INDEX($H$2:$H$1000,SMALL(IF($H$2:$H$1000<>"",ROW($H$2:$H$1000)-1),ROW(20:20))),"")} | K21: =IF(J21="","",INDEX(B:B,MATCH(J21,A:A,0))) | L21: =IF(J21="","",INDEX(C:C,MATCH(J21,A:A,0))) | M21: =IF(J21="","",INDEX(D:D,MATCH(J21,A:A,0))) | N21: =IF(J21="","",INDEX(E:E,MATCH(J21,A:A,0))) | O21: =IF(J21="","",INDEX(F:F,MATCH(J21,A:A,0)))
G22: =IF(A22="","",IF(COUNTIF(SF_Data!C:C,E22)>0,TRUE,FALSE)) | H22: =IF(G22=TRUE,A22,"") | J22: {=IFERROR(INDEX($H$2:$H$1000,SMALL(IF($H$2:$H$1000<>"",ROW($H$2:$H$1000)-1),ROW(21:21))),"")} | K22: =IF(J22="","",INDEX(B:B,MATCH(J22,A:A,0))) | L22: =IF(J22="","",INDEX(C:C,MATCH(J22,A:A,0))) | M22: =IF(J22="","",INDEX(D:D,MATCH(J22,A:A,0))) | N22: =IF(J22="","",INDEX(E:E,MATCH(J22,A:A,0))) | O22: =IF(J22="","",INDEX(F:F,MATCH(J22,A:A,0)))
G23: =IF(A23="","",IF(COUNTIF(SF_Data!C:C,E23)>0,TRUE,FALSE)) | H23: =IF(G23=TRUE,A23,"") | J23: {=IFERROR(INDEX($H$2:$H$1000,SMALL(IF($H$2:$H$1000<>"",ROW($H$2:$H$1000)-1),ROW(22:22))),"")} | K23: =IF(J23="","",INDEX(B:B,MATCH(J23,A:A,0))) | L23: =IF(J23="","",INDEX(C:C,MATCH(J23,A:A,0))) | M23: =IF(J23="","",INDEX(D:D,MATCH(J23,A:A,0))) | N23: =IF(J23="","",INDEX(E:E,MATCH(J23,A:A,0))) | O23: =IF(J23="","",INDEX(F:F,MATCH(J23,A:A,0)))
G24: =IF(A24="","",IF(COUNTIF(SF_Data!C:C,E24)>0,TRUE,FALSE)) | H24: =IF(G24=TRUE,A24,"") | J24: {=IFERROR(INDEX($H$2:$H$1000,SMALL(IF($H$2:$H$1000<>"",ROW($H$2:$H$1000)-1),ROW(23:23))),"")} | K24: =IF(J24="","",INDEX(B:B,MATCH(J24,A:A,0))) | L24: =IF(J24="","",INDEX(C:C,MATCH(J24,A:A,0))) | M24: =IF(J24="","",INDEX(D:D,MATCH(J24,A:A,0))) | N24: =IF(J24="","",INDEX(E:E,MATCH(J24,A:A,0))) | O24: =IF(J24="","",INDEX(F:F,MATCH(J24,A:A,0)))
G25: =IF(A25="","",IF(COUNTIF(SF_Data!C:C,E25)>0,TRUE,FALSE)) | H25: =IF(G25=TRUE,A25,"") | J25: {=IFERROR(INDEX($H$2:$H$1000,SMALL(IF($H$2:$H$1000<>"",ROW($H$2:$H$1000)-1),ROW(24:24))),"")} | K25: =IF(J25="","",INDEX(B:B,MATCH(J25,A:A,0))) | L25: =IF(J25="","",INDEX(C:C,MATCH(J25,A:A,0))) | M25: =IF(J25="","",INDEX(D:D,MATCH(J25,A:A,0))) | N25: =IF(J25="","",INDEX(E:E,MATCH(J25,A:A,0))) | O25: =IF(J25="","",INDEX(F:F,MATCH(J25,A:A,0)))
G26: =IF(A26="","",IF(COUNTIF(SF_Data!C:C,E26)>0,TRUE,FALSE)) | H26: =IF(G26=TRUE,A26,"") | J26: {=IFERROR(INDEX($H$2:$H$1000,SMALL(IF($H$2:$H$1000<>"",ROW($H$2:$H$1000)-1),ROW(25:25))),"")} | K26: =IF(J26="","",INDEX(B:B,MATCH(J26,A:A,0))) | L26: =IF(J26="","",INDEX(C:C,MATCH(J26,A:A,0))) | M26: =IF(J26="","",INDEX(D:D,MATCH(J26,A:A,0))) | N26: =IF(J26="","",INDEX(E:E,MATCH(J26,A:A,0))) | O26: =IF(J26="","",INDEX(F:F,MATCH(J26,A:A,0)))
G27: =IF(A27="","",IF(COUNTIF(SF_Data!C:C,E27)>0,TRUE,FALSE)) | H27: =IF(G27=TRUE,A27,"") | J27: {=IFERROR(INDEX($H$2:$H$1000,SMALL(IF($H$2:$H$1000<>"",ROW($H$2:$H$1000)-1),ROW(26:26))),"")} | K27: =IF(J27="","",INDEX(B:B,MATCH(J27,A:A,0))) | L27: =IF(J27="","",INDEX(C:C,MATCH(J27,A:A,0))) | M27: =IF(J27="","",INDEX(D:D,MATCH(J27,A:A,0))) | N27: =IF(J27="","",INDEX(E:E,MATCH(J27,A:A,0))) | O27: =IF(J27="","",INDEX(F:F,MATCH(J27,A:A,0)))
G28: =IF(A28="","",IF(COUNTIF(SF_Data!C:C,E28)>0,TRUE,FALSE)) | H28: =IF(G28=TRUE,A28,"") | J28: {=IFERROR(INDEX($H$2:$H$1000,SMALL(IF($H$2:$H$1000<>"",ROW($H$2:$H$1000)-1),ROW(27:27))),"")} | K28: =IF(J28="","",INDEX(B:B,MATCH(J28,A:A,0))) | L28: =IF(J28="","",INDEX(C:C,MATCH(J28,A:A,0))) | M28: =IF(J28="","",INDEX(D:D,MATCH(J28,A:A,0))) | N28: =IF(J28="","",INDEX(E:E,MATCH(J28,A:A,0))) | O28: =IF(J28="","",INDEX(F:F,MATCH(J28,A:A,0)))
G29: =IF(A29="","",IF(COUNTIF(SF_Data!C:C,E29)>0,TRUE,FALSE)) | H29: =IF(G29=TRUE,A29,"") | J29: {=IFERROR(INDEX($H$2:$H$1000,SMALL(IF($H$2:$H$1000<>"",ROW($H$2:$H$1000)-1),ROW(28:28))),"")} | K29: =IF(J29="","",INDEX(B:B,MATCH(J29,A:A,0))) | L29: =IF(J29="","",INDEX(C:C,MATCH(J29,A:A,0))) | M29: =IF(J29="","",INDEX(D:D,MATCH(J29,A:A,0))) | N29: =IF(J29="","",INDEX(E:E,MATCH(J29,A:A,0))) | O29: =IF(J29="","",INDEX(F:F,MATCH(J29,A:A,0)))
G30: =IF(A30="","",IF(COUNTIF(SF_Data!C:C,E30)>0,TRUE,FALSE)) | H30: =IF(G30=TRUE,A30,"") | J30: {=IFERROR(INDEX($H$2:$H$1000,SMALL(IF($H$2:$H$1000<>"",ROW($H$2:$H$1000)-1),ROW(29:29))),"")} | K30: =IF(J30="","",INDEX(B:B,MATCH(J30,A:A,0))) | L30: =IF(J30="","",INDEX(C:C,MATCH(J30,A:A,0))) | M30: =IF(J30="","",INDEX(D:D,MATCH(J30,A:A,0))) | N30: =IF(J30="","",INDEX(E:E,MATCH(J30,A:A,0))) | O30: =IF(J30="","",INDEX(F:F,MATCH(J30,A:A,0)))
G31: =IF(A31="","",IF(COUNTIF(SF_Data!C:C,E31)>0,TRUE,FALSE)) | H31: =IF(G31=TRUE,A31,"") | J31: {=IFERROR(INDEX($H$2:$H$1000,SMALL(IF($H$2:$H$1000<>"",ROW($H$2:$H$1000)-1),ROW(30:30))),"")} | K31: =IF(J31="","",INDEX(B:B,MATCH(J31,A:A,0))) | L31: =IF(J31="","",INDEX(C:C,MATCH(J31,A:A,0))) | M31: =IF(J31="","",INDEX(D:D,MATCH(J31,A:A,0))) | N31: =IF(J31="","",INDEX(E:E,MATCH(J31,A:A,0))) | O31: =IF(J31="","",INDEX(F:F,MATCH(J31,A:A,0)))
G32: =IF(A32="","",IF(COUNTIF(SF_Data!C:C,E32)>0,TRUE,FALSE)) | H32: =IF(G32=TRUE,A32,"") | J32: {=IFERROR(INDEX($H$2:$H$1000,SMALL(IF($H$2:$H$1000<>"",ROW($H$2:$H$1000)-1),ROW(31:31))),"")} | K32: =IF(J32="","",INDEX(B:B,MATCH(J32,A:A,0))) | L32: =IF(J32="","",INDEX(C:C,MATCH(J32,A:A,0))) | M32: =IF(J32="","",INDEX(D:D,MATCH(J32,A:A,0))) | N32: =IF(J32="","",INDEX(E:E,MATCH(J32,A:A,0))) | O32: =IF(J32="","",INDEX(F:F,MATCH(J32,A:A,0)))
G33: =IF(A33="","",IF(COUNTIF(SF_Data!C:C,E33)>0,TRUE,FALSE)) | H33: =IF(G33=TRUE,A33,"") | J33: {=IFERROR(INDEX($H$2:$H$1000,SMALL(IF($H$2:$H$1000<>"",ROW($H$2:$H$1000)-1),ROW(32:32))),"")} | K33: =IF(J33="","",INDEX(B:B,MATCH(J33,A:A,0))) | L33: =IF(J33="","",INDEX(C:C,MATCH(J33,A:A,0))) | M33: =IF(J33="","",INDEX(D:D,MATCH(J33,A:A,0))) | N33: =IF(J33="","",INDEX(E:E,MATCH(J33,A:A,0))) | O33: =IF(J33="","",INDEX(F:F,MATCH(J33,A:A,0)))
G34: =IF(A34="","",IF(COUNTIF(SF_Data!C:C,E34)>0,TRUE,FALSE)) | H34: =IF(G34=TRUE,A34,"") | J34: {=IFERROR(INDEX($H$2:$H$1000,SMALL(IF($H$2:$H$1000<>"",ROW($H$2:$H$1000)-1),ROW(33:33))),"")} | K34: =IF(J34="","",INDEX(B:B,MATCH(J34,A:A,0))) | L34: =IF(J34="","",INDEX(C:C,MATCH(J34,A:A,0))) | M34: =IF(J34="","",INDEX(D:D,MATCH(J34,A:A,0))) | N34: =IF(J34="","",INDEX(E:E,MATCH(J34,A:A,0))) | O34: =IF(J34="","",INDEX(F:F,MATCH(J34,A:A,0)))
G35: =IF(A35="","",IF(COUNTIF(SF_Data!C:C,E35)>0,TRUE,FALSE)) | H35: =IF(G35=TRUE,A35,"") | J35: {=IFERROR(INDEX($H$2:$H$1000,SMALL(IF($H$2:$H$1000<>"",ROW($H$2:$H$1000)-1),ROW(34:34))),"")} | K35: =IF(J35="","",INDEX(B:B,MATCH(J35,A:A,0))) | L35: =IF(J35="","",INDEX(C:C,MATCH(J35,A:A,0))) | M35: =IF(J35="","",INDEX(D:D,MATCH(J35,A:A,0))) | N35: =IF(J35="","",INDEX(E:E,MATCH(J35,A:A,0))) | O35: =IF(J35="","",INDEX(F:F,MATCH(J35,A:A,0)))
G36: =IF(A36="","",IF(COUNTIF(SF_Data!C:C,E36)>0,TRUE,FALSE)) | H36: =IF(G36=TRUE,A36,"") | J36: {=IFERROR(INDEX($H$2:$H$1000,SMALL(IF($H$2:$H$1000<>"",ROW($H$2:$H$1000)-1),ROW(35:35))),"")} | K36: =IF(J36="","",INDEX(B:B,MATCH(J36,A:A,0))) | L36: =IF(J36="","",INDEX(C:C,MATCH(J36,A:A,0))) | M36: =IF(J36="","",INDEX(D:D,MATCH(J36,A:A,0))) | N36: =IF(J36="","",INDEX(E:E,MATCH(J36,A:A,0))) | O36: =IF(J36="","",INDEX(F:F,MATCH(J36,A:A,0)))
G37: =IF(A37="","",IF(COUNTIF(SF_Data!C:C,E37)>0,TRUE,FALSE)) | H37: =IF(G37=TRUE,A37,"") | J37: {=IFERROR(INDEX($H$2:$H$1000,SMALL(IF($H$2:$H$1000<>"",ROW($H$2:$H$1000)-1),ROW(36:36))),"")} | K37: =IF(J37="","",INDEX(B:B,MATCH(J37,A:A,0))) | L37: =IF(J37="","",INDEX(C:C,MATCH(J37,A:A,0))) | M37: =IF(J37="","",INDEX(D:D,MATCH(J37,A:A,0))) | N37: =IF(J37="","",INDEX(E:E,MATCH(J37,A:A,0))) | O37: =IF(J37="","",INDEX(F:F,MATCH(J37,A:A,0)))
G38: =IF(A38="","",IF(COUNTIF(SF_Data!C:C,E38)>0,TRUE,FALSE)) | H38: =IF(G38=TRUE,A38,"") | J38: {=IFERROR(INDEX($H$2:$H$1000,SMALL(IF($H$2:$H$1000<>"",ROW($H$2:$H$1000)-1),ROW(37:37))),"")} | K38: =IF(J38="","",INDEX(B:B,MATCH(J38,A:A,0))) | L38: =IF(J38="","",INDEX(C:C,MATCH(J38,A:A,0))) | M38: =IF(J38="","",INDEX(D:D,MATCH(J38,A:A,0))) | N38: =IF(J38="","",INDEX(E:E,MATCH(J38,A:A,0))) | O38: =IF(J38="","",INDEX(F:F,MATCH(J38,A:A,0)))
G39: =IF(A39="","",IF(COUNTIF(SF_Data!C:C,E39)>0,TRUE,FALSE)) | H39: =IF(G39=TRUE,A39,"") | J39: {=IFERROR(INDEX($H$2:$H$1000,SMALL(IF($H$2:$H$1000<>"",ROW($H$2:$H$1000)-1),ROW(38:38))),"")} | K39: =IF(J39="","",INDEX(B:B,MATCH(J39,A:A,0))) | L39: =IF(J39="","",INDEX(C:C,MATCH(J39,A:A,0))) | M39: =IF(J39="","",INDEX(D:D,MATCH(J39,A:A,0))) | N39: =IF(J39="","",INDEX(E:E,MATCH(J39,A:A,0))) | O39: =IF(J39="","",INDEX(F:F,MATCH(J39,A:A,0)))
G40: =IF(A40="","",IF(COUNTIF(SF_Data!C:C,E40)>0,TRUE,FALSE)) | H40: =IF(G40=TRUE,A40,"") | J40: {=IFERROR(INDEX($H$2:$H$1000,SMALL(IF($H$2:$H$1000<>"",ROW($H$2:$H$1000)-1),ROW(39:39))),"")} | K40: =IF(J40="","",INDEX(B:B,MATCH(J40,A:A,0))) | L40: =IF(J40="","",INDEX(C:C,MATCH(J40,A:A,0))) | M40: =IF(J40="","",INDEX(D:D,MATCH(J40,A:A,0))) | N40: =IF(J40="","",INDEX(E:E,MATCH(J40,A:A,0))) | O40: =IF(J40="","",INDEX(F:F,MATCH(J40,A:A,0)))
...

Sheet PBH_RR
A1: ID | B1: Name | C1: Assembly Name | D1: Assembly | E1: Rate Basis | F1: Selection | G1: From (FH) | H1: From (FC) | I1: PBH (FH) | J1: PBH (FC) | K1: Rent Schedule | L1: Unit Type | M1: Utilization Unit | N1: Local Currency | O1: ILI Cnvrt Amt | P1: Final Amount | Q1: Total Amount
P2: =IF(A2="","",IF(N2="",Q2,O2))
P3: =IF(A3="","",IF(N3="",Q3,O3))
P4: =IF(A4="","",IF(N4="",Q4,O4))
P5: =IF(A5="","",IF(N5="",Q5,O5))
P6: =IF(A6="","",IF(N6="",Q6,O6))
P7: =IF(A7="","",IF(N7="",Q7,O7))
P8: =IF(A8="","",IF(N8="",Q8,O8))
P9: =IF(A9="","",IF(N9="",Q9,O9))
P10: =IF(A10="","",IF(N10="",Q10,O10))
P11: =IF(A11="","",IF(N11="",Q11,O11))
P12: =IF(A12="","",IF(N12="",Q12,O12))
P13: =IF(A13="","",IF(N13="",Q13,O13))
... P200: =IF(A200="","",IF(N200="",Q200,O200))

Sheet Sheet1
A1: Name | B1: FH | C1: FC | D1: Utilization (FH) | E1: Utilization (FC) | F1: Rate(FH) | G1: Rate(FC) | H1: Total Amount | J1: Name | K1: FH | L1: FC | M1: Utilization (FH) | N1: Utilization (FC) | O1: Rate(FH) | P1: Rate(FC) | Q1: Total Amount
A2: =IF(PBH_RR!A2="","",IF(OR(PBH_RR!E2="FH Matrix", PBH_RR!E2="FC Matrix"),PBH_RR!C2,INDEX(SF_Data!D:D, MATCH(PBH_RR!D2, SF_Data!B:B, 0)))) | B2: =IF(PBH_RR!A2="","",IF(OR(PBH_RR!E2="FH Matrix",PBH_RR!E2="FC Matrix"),PBH_RR!G2,IF(INDEX(SF_Data!F:F,MATCH(PBH_RR!D2,SF_Data!B:B,0))="Greater(FH/FC)",IF(INDEX(SF_Data!M:M,MATCH(PBH_RR!D2,SF_Data!B:B,0))="FH",INDEX(SF_Data!Q:Q,MATCH(PBH_RR!D2,SF_Data!B:B,0)),""),IF(PBH_RR!E2="Both(FH+FC)",IF(PBH_RR!L2="FH",PBH_RR!G2,""),INDEX(SF_Data!Q:Q,MATCH(PBH_RR!D2,SF_Data!B:B,0)))))) | C2: =IF(PBH_RR!A2="","",IF(OR(PBH_RR!E2="FH Matrix",PBH_RR!E2="FC Matrix"),PBH_RR!H2,IF(INDEX(SF_Data!F:F,MATCH(PBH_RR!D2,SF_Data!B:B,0))="Greater(FH/FC)",IF(INDEX(SF_Data!M:M,MATCH(PBH_RR!D2,SF_Data!B:B,0))="FC",INDEX(SF_Data!R:R,MATCH(PBH_RR!D2,SF_Data!B:B,0)),""),IF(PBH_RR!E2="Both(FH+FC)",IF(PBH_RR!L2="FC",PBH_RR!H2,""),INDEX(SF_Data!R:R,MATCH(PBH_RR!D2,SF_Data!B:B,0)))))) | D2: =IF(PBH_RR!A2="","",IF(OR(PBH_RR!E2="Hourly",PBH_RR!E2="Cycle"),IF(INDEX(SF_Data!M:M,MATCH(PBH_RR!D2,SF_Data!B:B,0))="FH",INDEX(SF_Data!G:G,MATCH(PBH_RR!D2,SF_Data!B:B,0)),""),IF(PBH_RR!E2="Both(FH+FC)",IF(PBH_RR!L2="FH",PBH_RR!M2-PBH_RR!G2,""),IF(PBH_RR!E2="Greater(FH/FC)",IF(INDEX(SF_Data!M:M,MATCH(PBH_RR!D2,SF_Data!B:B,0))="FH",INDEX(SF_Data!G:G,MATCH(PBH_RR!D2,SF_Data!B:B,0))-INDEX(SF_Data!Q:Q,MATCH(PBH_RR!D2,SF_Data!B:B,0)),""),IF(INDEX(SF_Data!M:M,MATCH(PBH_RR!D2,SF_Data!B:B,0))="FH",INDEX(PBH_Lines!K:K,MATCH(PBH_RR!A2,PBH_Lines!M:M,0)),""))))) | E2: =IF(PBH_RR!A2="","",IF(OR(PBH_RR!E2="Hourly",PBH_RR!E2="Cycle"),IF(INDEX(SF_Data!M:M,MATCH(PBH_RR!D2,SF_Data!B:B,0))="FC",INDEX(SF_Data!G:G,MATCH(PBH_RR!D2,SF_Data!B:B,0)),""),IF(PBH_RR!E2="Both(FH+FC)",IF(PBH_RR!L2="FC",PBH_RR!M2-PBH_RR!H2,""),IF(PBH_RR!E2="Greater(FH/FC)",IF(INDEX(SF_Data!M:M,MATCH(PBH_RR!D2,SF_Data!B:B,0))="FC",INDEX(SF_Data!G:G,MATCH(PBH_RR!D2,SF_Data!B:B,0))-INDEX(SF_Data!R:R,MATCH(PBH_RR!D2,SF_Data!B:B,0)),""),IF(INDEX(SF_Data!M:M,MATCH(PBH_RR!D2,SF_Data!B:B,0))="FC",INDEX(PBH_Lines!K:K,MATCH(PBH_RR!A2,PBH_Lines!M:M,0)),""))))) | F2: =IF(PBH_RR!A2="","",IF(OR(PBH_RR!E2="FH Matrix",PBH_RR!E2="FC Matrix"),PBH_RR!I2,IF(INDEX(SF_Data!F:F,MATCH(PBH_RR!D2,SF_Data!B:B,0))="Greater(FH/FC)",IF(INDEX(SF_Data!M:M,MATCH(PBH_RR!D2,SF_Data!B:B,0))="FH",INDEX(SF_Data!S:S,MATCH(PBH_RR!D2,SF_Data!B:B,0)),""),IF(PBH_RR!E2="Both(FH+FC)",IF(PBH_RR!L2="FH",PBH_RR!I2,""),INDEX(SF_Data!S:S,MATCH(PBH_RR!D2,SF_Data!B:B,0)))))) | G2: =IF(PBH_RR!A2="","",IF(OR(PBH_RR!E2="FH Matrix",PBH_RR!E2="FC Matrix"),PBH_RR!J2,IF(INDEX(SF_Data!F:F,MATCH(PBH_RR!D2,SF_Data!B:B,0))="Greater(FH/FC)",IF(INDEX(SF_Data!M:M,MATCH(PBH_RR!D2,SF_Data!B:B,0))="FC",INDEX(SF_Data!T:T,MATCH(PBH_RR!D2,SF_Data!B:B,0)),""),IF(PBH_RR!E2="Both(FH+FC)",IF(PBH_RR!L2="FC",PBH_RR!J2,""),INDEX(SF_Data!T:T,MATCH(PBH_RR!D2,SF_Data!B:B,0)))))) | H2: =IF(PBH_RR!A2="","",IF(PBH_RR!E2="Both(FH+FC)",PBH_RR!P2,IF(OR(PBH_RR!E2="FH Matrix",PBH_RR!E2="FC Matrix"),INDEX(PBH_Lines!O:O,MATCH(PBH_RR!A2,PBH_Lines!M:M,0)),INDEX(SF_Data!U:U,MATCH(PBH_RR!D2,SF_Data!B:B,0))))) | J2: =IF(A2="","",A2) | K2: =IF(B2="","",B2) | L2: =IF(C2="","",C2) | M2: =IF(D2="","",D2) | N2: =IF(E2="","",E2) | O2: =IF(F2="","",F2) | P2: =IF(G2="","",G2) | Q2: =IF(H2=H1,"",H2)
A3: =IF(PBH_RR!A3="","",IF(OR(PBH_RR!E3="FH Matrix", PBH_RR!E3="FC Matrix"),PBH_RR!C3,INDEX(SF_Data!D:D, MATCH(PBH_RR!D3, SF_Data!B:B, 0)))) | B3: =IF(PBH_RR!A3="","",IF(OR(PBH_RR!E3="FH Matrix",PBH_RR!E3="FC Matrix"),PBH_RR!G3,IF(INDEX(SF_Data!F:F,MATCH(PBH_RR!D3,SF_Data!B:B,0))="Greater(FH/FC)",IF(INDEX(SF_Data!M:M,MATCH(PBH_RR!D3,SF_Data!B:B,0))="FH",INDEX(SF_Data!Q:Q,MATCH(PBH_RR!D3,SF_Data!B:B,0)),""),IF(PBH_RR!E3="Both(FH+FC)",IF(PBH_RR!L3="FH",PBH_RR!G3,""),INDEX(SF_Data!Q:Q,MATCH(PBH_RR!D3,SF_Data!B:B,0)))))) | C3: =IF(PBH_RR!A3="","",IF(OR(PBH_RR!E3="FH Matrix",PBH_RR!E3="FC Matrix"),PBH_RR!H3,IF(INDEX(SF_Data!F:F,MATCH(PBH_RR!D3,SF_Data!B:B,0))="Greater(FH/FC)",IF(INDEX(SF_Data!M:M,MATCH(PBH_RR!D3,SF_Data!B:B,0))="FC",INDEX(SF_Data!R:R,MATCH(PBH_RR!D3,SF_Data!B:B,0)),""),IF(PBH_RR!E3="Both(FH+FC)",IF(PBH_RR!L3="FC",PBH_RR!H3,""),INDEX(SF_Data!R:R,MATCH(PBH_RR!D3,SF_Data!B:B,0)))))) | D3: =IF(PBH_RR!A3="","",IF(OR(PBH_RR!E3="Hourly",PBH_RR!E3="Cycle"),IF(INDEX(SF_Data!M:M,MATCH(PBH_RR!D3,SF_Data!B:B,0))="FH",INDEX(SF_Data!G:G,MATCH(PBH_RR!D3,SF_Data!B:B,0)),""),IF(PBH_RR!E3="Both(FH+FC)",IF(PBH_RR!L3="FH",PBH_RR!M3-PBH_RR!G3,""),IF(PBH_RR!E3="Greater(FH/FC)",IF(INDEX(SF_Data!M:M,MATCH(PBH_RR!D3,SF_Data!B:B,0))="FH",INDEX(SF_Data!G:G,MATCH(PBH_RR!D3,SF_Data!B:B,0))-INDEX(SF_Data!Q:Q,MATCH(PBH_RR!D3,SF_Data!B:B,0)),""),IF(INDEX(SF_Data!M:M,MATCH(PBH_RR!D3,SF_Data!B:B,0))="FH",INDEX(PBH_Lines!K:K,MATCH(PBH_RR!A3,PBH_Lines!M:M,0)),""))))) | E3: =IF(PBH_RR!A3="","",IF(OR(PBH_RR!E3="Hourly",PBH_RR!E3="Cycle"),IF(INDEX(SF_Data!M:M,MATCH(PBH_RR!D3,SF_Data!B:B,0))="FC",INDEX(SF_Data!G:G,MATCH(PBH_RR!D3,SF_Data!B:B,0)),""),IF(PBH_RR!E3="Both(FH+FC)",IF(PBH_RR!L3="FC",PBH_RR!M3-PBH_RR!H3,""),IF(PBH_RR!E3="Greater(FH/FC)",IF(INDEX(SF_Data!M:M,MATCH(PBH_RR!D3,SF_Data!B:B,0))="FC",INDEX(SF_Data!G:G,MATCH(PBH_RR!D3,SF_Data!B:B,0))-INDEX(SF_Data!R:R,MATCH(PBH_RR!D3,SF_Data!B:B,0)),""),IF(INDEX(SF_Data!M:M,MATCH(PBH_RR!D3,SF_Data!B:B,0))="FC",INDEX(PBH_Lines!K:K,MATCH(PBH_RR!A3,PBH_Lines!M:M,0)),""))))) | F3: =IF(PBH_RR!A3="","",IF(OR(PBH_RR!E3="FH Matrix",PBH_RR!E3="FC Matrix"),PBH_RR!I3,IF(INDEX(SF_Data!F:F,MATCH(PBH_RR!D3,SF_Data!B:B,0))="Greater(FH/FC)",IF(INDEX(SF_Data!M:M,MATCH(PBH_RR!D3,SF_Data!B:B,0))="FH",INDEX(SF_Data!S:S,MATCH(PBH_RR!D3,SF_Data!B:B,0)),""),IF(PBH_RR!E3="Both(FH+FC)",IF(PBH_RR!L3="FH",PBH_RR!I3,""),INDEX(SF_Data!S:S,MATCH(PBH_RR!D3,SF_Data!B:B,0)))))) | G3: =IF(PBH_RR!A3="","",IF(OR(PBH_RR!E3="FH Matrix",PBH_RR!E3="FC Matrix"),PBH_RR!J3,IF(INDEX(SF_Data!F:F,MATCH(PBH_RR!D3,SF_Data!B:B,0))="Greater(FH/FC)",IF(INDEX(SF_Data!M:M,MATCH(PBH_RR!D3,SF_Data!B:B,0))="FC",INDEX(SF_Data!T:T,MATCH(PBH_RR!D3,SF_Data!B:B,0)),""),IF(PBH_RR!E3="Both(FH+FC)",IF(PBH_RR!L3="FC",PBH_RR!J3,""),INDEX(SF_Data!T:T,MATCH(PBH_RR!D3,SF_Data!B:B,0)))))) | H3: =IF(PBH_RR!A3="","",IF(PBH_RR!E3="Both(FH+FC)",PBH_RR!P3,IF(OR(PBH_RR!E3="FH Matrix",PBH_RR!E3="FC Matrix"),INDEX(PBH_Lines!O:O,MATCH(PBH_RR!A3,PBH_Lines!M:M,0)),INDEX(SF_Data!U:U,MATCH(PBH_RR!D3,SF_Data!B:B,0))))) | J3: =IF(A3="","",A3) | K3: =IF(B3="","",B3) | L3: =IF(C3="","",C3) | M3: =IF(D3="","",D3) | N3: =IF(E3="","",E3) | O3: =IF(F3="","",F3) | P3: =IF(G3="","",G3) | Q3: =IF(H3=H2,"",H3)
A4: =IF(PBH_RR!A4="","",IF(OR(PBH_RR!E4="FH Matrix", PBH_RR!E4="FC Matrix"),PBH_RR!C4,INDEX(SF_Data!D:D, MATCH(PBH_RR!D4, SF_Data!B:B, 0)))) | B4: =IF(PBH_RR!A4="","",IF(OR(PBH_RR!E4="FH Matrix",PBH_RR!E4="FC Matrix"),PBH_RR!G4,IF(INDEX(SF_Data!F:F,MATCH(PBH_RR!D4,SF_Data!B:B,0))="Greater(FH/FC)",IF(INDEX(SF_Data!M:M,MATCH(PBH_RR!D4,SF_Data!B:B,0))="FH",INDEX(SF_Data!Q:Q,MATCH(PBH_RR!D4,SF_Data!B:B,0)),""),IF(PBH_RR!E4="Both(FH+FC)",IF(PBH_RR!L4="FH",PBH_RR!G4,""),INDEX(SF_Data!Q:Q,MATCH(PBH_RR!D4,SF_Data!B:B,0)))))) | C4: =IF(PBH_RR!A4="","",IF(OR(PBH_RR!E4="FH Matrix",PBH_RR!E4="FC Matrix"),PBH_RR!H4,IF(INDEX(SF_Data!F:F,MATCH(PBH_RR!D4,SF_Data!B:B,0))="Greater(FH/FC)",IF(INDEX(SF_Data!M:M,MATCH(PBH_RR!D4,SF_Data!B:B,0))="FC",INDEX(SF_Data!R:R,MATCH(PBH_RR!D4,SF_Data!B:B,0)),""),IF(PBH_RR!E4="Both(FH+FC)",IF(PBH_RR!L4="FC",PBH_RR!H4,""),INDEX(SF_Data!R:R,MATCH(PBH_RR!D4,SF_Data!B:B,0)))))) | D4: =IF(PBH_RR!A4="","",IF(OR(PBH_RR!E4="Hourly",PBH_RR!E4="Cycle"),IF(INDEX(SF_Data!M:M,MATCH(PBH_RR!D4,SF_Data!B:B,0))="FH",INDEX(SF_Data!G:G,MATCH(PBH_RR!D4,SF_Data!B:B,0)),""),IF(PBH_RR!E4="Both(FH+FC)",IF(PBH_RR!L4="FH",PBH_RR!M4-PBH_RR!G4,""),IF(PBH_RR!E4="Greater(FH/FC)",IF(INDEX(SF_Data!M:M,MATCH(PBH_RR!D4,SF_Data!B:B,0))="FH",INDEX(SF_Data!G:G,MATCH(PBH_RR!D4,SF_Data!B:B,0))-INDEX(SF_Data!Q:Q,MATCH(PBH_RR!D4,SF_Data!B:B,0)),""),IF(INDEX(SF_Data!M:M,MATCH(PBH_RR!D4,SF_Data!B:B,0))="FH",INDEX(PBH_Lines!K:K,MATCH(PBH_RR!A4,PBH_Lines!M:M,0)),""))))) | E4: =IF(PBH_RR!A4="","",IF(OR(PBH_RR!E4="Hourly",PBH_RR!E4="Cycle"),IF(INDEX(SF_Data!M:M,MATCH(PBH_RR!D4,SF_Data!B:B,0))="FC",INDEX(SF_Data!G:G,MATCH(PBH_RR!D4,SF_Data!B:B,0)),""),IF(PBH_RR!E4="Both(FH+FC)",IF(PBH_RR!L4="FC",PBH_RR!M4-PBH_RR!H4,""),IF(PBH_RR!E4="Greater(FH/FC)",IF(INDEX(SF_Data!M:M,MATCH(PBH_RR!D4,SF_Data!B:B,0))="FC",INDEX(SF_Data!G:G,MATCH(PBH_RR!D4,SF_Data!B:B,0))-INDEX(SF_Data!R:R,MATCH(PBH_RR!D4,SF_Data!B:B,0)),""),IF(INDEX(SF_Data!M:M,MATCH(PBH_RR!D4,SF_Data!B:B,0))="FC",INDEX(PBH_Lines!K:K,MATCH(PBH_RR!A4,PBH_Lines!M:M,0)),""))))) | F4: =IF(PBH_RR!A4="","",IF(OR(PBH_RR!E4="FH Matrix",PBH_RR!E4="FC Matrix"),PBH_RR!I4,IF(INDEX(SF_Data!F:F,MATCH(PBH_RR!D4,SF_Data!B:B,0))="Greater(FH/FC)",IF(INDEX(SF_Data!M:M,MATCH(PBH_RR!D4,SF_Data!B:B,0))="FH",INDEX(SF_Data!S:S,MATCH(PBH_RR!D4,SF_Data!B:B,0)),""),IF(PBH_RR!E4="Both(FH+FC)",IF(PBH_RR!L4="FH",PBH_RR!I4,""),INDEX(SF_Data!S:S,MATCH(PBH_RR!D4,SF_Data!B:B,0)))))) | G4: =IF(PBH_RR!A4="","",IF(OR(PBH_RR!E4="FH Matrix",PBH_RR!E4="FC Matrix"),PBH_RR!J4,IF(INDEX(SF_Data!F:F,MATCH(PBH_RR!D4,SF_Data!B:B,0))="Greater(FH/FC)",IF(INDEX(SF_Data!M:M,MATCH(PBH_RR!D4,SF_Data!B:B,0))="FC",INDEX(SF_Data!T:T,MATCH(PBH_RR!D4,SF_Data!B:B,0)),""),IF(PBH_RR!E4="Both(FH+FC)",IF(PBH_RR!L4="FC",PBH_RR!J4,""),INDEX(SF_Data!T:T,MATCH(PBH_RR!D4,SF_Data!B:B,0)))))) | H4: =IF(PBH_RR!A4="","",IF(PBH_RR!E4="Both(FH+FC)",PBH_RR!P4,IF(OR(PBH_RR!E4="FH Matrix",PBH_RR!E4="FC Matrix"),INDEX(PBH_Lines!O:O,MATCH(PBH_RR!A4,PBH_Lines!M:M,0)),INDEX(SF_Data!U:U,MATCH(PBH_RR!D4,SF_Data!B:B,0))))) | J4: =IF(A4="","",A4) | K4: =IF(B4="","",B4) | L4: =IF(C4="","",C4) | M4: =IF(D4="","",D4) | N4: =IF(E4="","",E4) | O4: =IF(F4="","",F4) | P4: =IF(G4="","",G4) | Q4: =IF(H4=H3,"",H4)
A5: =IF(PBH_RR!A5="","",IF(OR(PBH_RR!E5="FH Matrix", PBH_RR!E5="FC Matrix"),PBH_RR!C5,INDEX(SF_Data!D:D, MATCH(PBH_RR!D5, SF_Data!B:B, 0)))) | B5: =IF(PBH_RR!A5="","",IF(OR(PBH_RR!E5="FH Matrix",PBH_RR!E5="FC Matrix"),PBH_RR!G5,IF(INDEX(SF_Data!F:F,MATCH(PBH_RR!D5,SF_Data!B:B,0))="Greater(FH/FC)",IF(INDEX(SF_Data!M:M,MATCH(PBH_RR!D5,SF_Data!B:B,0))="FH",INDEX(SF_Data!Q:Q,MATCH(PBH_RR!D5,SF_Data!B:B,0)),""),IF(PBH_RR!E5="Both(FH+FC)",IF(PBH_RR!L5="FH",PBH_RR!G5,""),INDEX(SF_Data!Q:Q,MATCH(PBH_RR!D5,SF_Data!B:B,0)))))) | C5: =IF(PBH_RR!A5="","",IF(OR(PBH_RR!E5="FH Matrix",PBH_RR!E5="FC Matrix"),PBH_RR!H5,IF(INDEX(SF_Data!F:F,MATCH(PBH_RR!D5,SF_Data!B:B,0))="Greater(FH/FC)",IF(INDEX(SF_Data!M:M,MATCH(PBH_RR!D5,SF_Data!B:B,0))="FC",INDEX(SF_Data!R:R,MATCH(PBH_RR!D5,SF_Data!B:B,0)),""),IF(PBH_RR!E5="Both(FH+FC)",IF(PBH_RR!L5="FC",PBH_RR!H5,""),INDEX(SF_Data!R:R,MATCH(PBH_RR!D5,SF_Data!B:B,0)))))) | D5: =IF(PBH_RR!A5="","",IF(OR(PBH_RR!E5="Hourly",PBH_RR!E5="Cycle"),IF(INDEX(SF_Data!M:M,MATCH(PBH_RR!D5,SF_Data!B:B,0))="FH",INDEX(SF_Data!G:G,MATCH(PBH_RR!D5,SF_Data!B:B,0)),""),IF(PBH_RR!E5="Both(FH+FC)",IF(PBH_RR!L5="FH",PBH_RR!M5-PBH_RR!G5,""),IF(PBH_RR!E5="Greater(FH/FC)",IF(INDEX(SF_Data!M:M,MATCH(PBH_RR!D5,SF_Data!B:B,0))="FH",INDEX(SF_Data!G:G,MATCH(PBH_RR!D5,SF_Data!B:B,0))-INDEX(SF_Data!Q:Q,MATCH(PBH_RR!D5,SF_Data!B:B,0)),""),IF(INDEX(SF_Data!M:M,MATCH(PBH_RR!D5,SF_Data!B:B,0))="FH",INDEX(PBH_Lines!K:K,MATCH(PBH_RR!A5,PBH_Lines!M:M,0)),""))))) | E5: =IF(PBH_RR!A5="","",IF(OR(PBH_RR!E5="Hourly",PBH_RR!E5="Cycle"),IF(INDEX(SF_Data!M:M,MATCH(PBH_RR!D5,SF_Data!B:B,0))="FC",INDEX(SF_Data!G:G,MATCH(PBH_RR!D5,SF_Data!B:B,0)),""),IF(PBH_RR!E5="Both(FH+FC)",IF(PBH_RR!L5="FC",PBH_RR!M5-PBH_RR!H5,""),IF(PBH_RR!E5="Greater(FH/FC)",IF(INDEX(SF_Data!M:M,MATCH(PBH_RR!D5,SF_Data!B:B,0))="FC",INDEX(SF_Data!G:G,MATCH(PBH_RR!D5,SF_Data!B:B,0))-INDEX(SF_Data!R:R,MATCH(PBH_RR!D5,SF_Data!B:B,0)),""),IF(INDEX(SF_Data!M:M,MATCH(PBH_RR!D5,SF_Data!B:B,0))="FC",INDEX(PBH_Lines!K:K,MATCH(PBH_RR!A5,PBH_Lines!M:M,0)),""))))) | F5: =IF(PBH_RR!A5="","",IF(OR(PBH_RR!E5="FH Matrix",PBH_RR!E5="FC Matrix"),PBH_RR!I5,IF(INDEX(SF_Data!F:F,MATCH(PBH_RR!D5,SF_Data!B:B,0))="Greater(FH/FC)",IF(INDEX(SF_Data!M:M,MATCH(PBH_RR!D5,SF_Data!B:B,0))="FH",INDEX(SF_Data!S:S,MATCH(PBH_RR!D5,SF_Data!B:B,0)),""),IF(PBH_RR!E5="Both(FH+FC)",IF(PBH_RR!L5="FH",PBH_RR!I5,""),INDEX(SF_Data!S:S,MATCH(PBH_RR!D5,SF_Data!B:B,0)))))) | G5: =IF(PBH_RR!A5="","",IF(OR(PBH_RR!E5="FH Matrix",PBH_RR!E5="FC Matrix"),PBH_RR!J5,IF(INDEX(SF_Data!F:F,MATCH(PBH_RR!D5,SF_Data!B:B,0))="Greater(FH/FC)",IF(INDEX(SF_Data!M:M,MATCH(PBH_RR!D5,SF_Data!B:B,0))="FC",INDEX(SF_Data!T:T,MATCH(PBH_RR!D5,SF_Data!B:B,0)),""),IF(PBH_RR!E5="Both(FH+FC)",IF(PBH_RR!L5="FC",PBH_RR!J5,""),INDEX(SF_Data!T:T,MATCH(PBH_RR!D5,SF_Data!B:B,0)))))) | H5: =IF(PBH_RR!A5="","",IF(PBH_RR!E5="Both(FH+FC)",PBH_RR!P5,IF(OR(PBH_RR!E5="FH Matrix",PBH_RR!E5="FC Matrix"),INDEX(PBH_Lines!O:O,MATCH(PBH_RR!A5,PBH_Lines!M:M,0)),INDEX(SF_Data!U:U,MATCH(PBH_RR!D5,SF_Data!B:B,0))))) | J5: =IF(A5="","",A5) | K5: =IF(B5="","",B5) | L5: =IF(C5="","",C5) | M5: =IF(D5="","",D5) | N5: =IF(E5="","",E5) | O5: =IF(F5="","",F5) | P5: =IF(G5="","",G5) | Q5: =IF(H5=H4,"",H5)
A6: =IF(PBH_RR!A6="","",IF(OR(PBH_RR!E6="FH Matrix", PBH_RR!E6="FC Matrix"),PBH_RR!C6,INDEX(SF_Data!D:D, MATCH(PBH_RR!D6, SF_Data!B:B, 0)))) | B6: =IF(PBH_RR!A6="","",IF(OR(PBH_RR!E6="FH Matrix",PBH_RR!E6="FC Matrix"),PBH_RR!G6,IF(INDEX(SF_Data!F:F,MATCH(PBH_RR!D6,SF_Data!B:B,0))="Greater(FH/FC)",IF(INDEX(SF_Data!M:M,MATCH(PBH_RR!D6,SF_Data!B:B,0))="FH",INDEX(SF_Data!Q:Q,MATCH(PBH_RR!D6,SF_Data!B:B,0)),""),IF(PBH_RR!E6="Both(FH+FC)",IF(PBH_RR!L6="FH",PBH_RR!G6,""),INDEX(SF_Data!Q:Q,MATCH(PBH_RR!D6,SF_Data!B:B,0)))))) | C6: =IF(PBH_RR!A6="","",IF(OR(PBH_RR!E6="FH Matrix",PBH_RR!E6="FC Matrix"),PBH_RR!H6,IF(INDEX(SF_Data!F:F,MATCH(PBH_RR!D6,SF_Data!B:B,0))="Greater(FH/FC)",IF(INDEX(SF_Data!M:M,MATCH(PBH_RR!D6,SF_Data!B:B,0))="FC",INDEX(SF_Data!R:R,MATCH(PBH_RR!D6,SF_Data!B:B,0)),""),IF(PBH_RR!E6="Both(FH+FC)",IF(PBH_RR!L6="FC",PBH_RR!H6,""),INDEX(SF_Data!R:R,MATCH(PBH_RR!D6,SF_Data!B:B,0)))))) | D6: =IF(PBH_RR!A6="","",IF(OR(PBH_RR!E6="Hourly",PBH_RR!E6="Cycle"),IF(INDEX(SF_Data!M:M,MATCH(PBH_RR!D6,SF_Data!B:B,0))="FH",INDEX(SF_Data!G:G,MATCH(PBH_RR!D6,SF_Data!B:B,0)),""),IF(PBH_RR!E6="Both(FH+FC)",IF(PBH_RR!L6="FH",PBH_RR!M6-PBH_RR!G6,""),IF(PBH_RR!E6="Greater(FH/FC)",IF(INDEX(SF_Data!M:M,MATCH(PBH_RR!D6,SF_Data!B:B,0))="FH",INDEX(SF_Data!G:G,MATCH(PBH_RR!D6,SF_Data!B:B,0))-INDEX(SF_Data!Q:Q,MATCH(PBH_RR!D6,SF_Data!B:B,0)),""),IF(INDEX(SF_Data!M:M,MATCH(PBH_RR!D6,SF_Data!B:B,0))="FH",INDEX(PBH_Lines!K:K,MATCH(PBH_RR!A6,PBH_Lines!M:M,0)),""))))) | E6: =IF(PBH_RR!A6="","",IF(OR(PBH_RR!E6="Hourly",PBH_RR!E6="Cycle"),IF(INDEX(SF_Data!M:M,MATCH(PBH_RR!D6,SF_Data!B:B,0))="FC",INDEX(SF_Data!G:G,MATCH(PBH_RR!D6,SF_Data!B:B,0)),""),IF(PBH_RR!E6="Both(FH+FC)",IF(PBH_RR!L6="FC",PBH_RR!M6-PBH_RR!H6,""),IF(PBH_RR!E6="Greater(FH/FC)",IF(INDEX(SF_Data!M:M,MATCH(PBH_RR!D6,SF_Data!B:B,0))="FC",INDEX(SF_Data!G:G,MATCH(PBH_RR!D6,SF_Data!B:B,0))-INDEX(SF_Data!R:R,MATCH(PBH_RR!D6,SF_Data!B:B,0)),""),IF(INDEX(SF_Data!M:M,MATCH(PBH_RR!D6,SF_Data!B:B,0))="FC",INDEX(PBH_Lines!K:K,MATCH(PBH_RR!A6,PBH_Lines!M:M,0)),""))))) | F6: =IF(PBH_RR!A6="","",IF(OR(PBH_RR!E6="FH Matrix",PBH_RR!E6="FC Matrix"),PBH_RR!I6,IF(INDEX(SF_Data!F:F,MATCH(PBH_RR!D6,SF_Data!B:B,0))="Greater(FH/FC)",IF(INDEX(SF_Data!M:M,MATCH(PBH_RR!D6,SF_Data!B:B,0))="FH",INDEX(SF_Data!S:S,MATCH(PBH_RR!D6,SF_Data!B:B,0)),""),IF(PBH_RR!E6="Both(FH+FC)",IF(PBH_RR!L6="FH",PBH_RR!I6,""),INDEX(SF_Data!S:S,MATCH(PBH_RR!D6,SF_Data!B:B,0)))))) | G6: =IF(PBH_RR!A6="","",IF(OR(PBH_RR!E6="FH Matrix",PBH_RR!E6="FC Matrix"),PBH_RR!J6,IF(INDEX(SF_Data!F:F,MATCH(PBH_RR!D6,SF_Data!B:B,0))="Greater(FH/FC)",IF(INDEX(SF_Data!M:M,MATCH(PBH_RR!D6,SF_Data!B:B,0))="FC",INDEX(SF_Data!T:T,MATCH(PBH_RR!D6,SF_Data!B:B,0)),""),IF(PBH_RR!E6="Both(FH+FC)",IF(PBH_RR!L6="FC",PBH_RR!J6,""),INDEX(SF_Data!T:T,MATCH(PBH_RR!D6,SF_Data!B:B,0)))))) | H6: =IF(PBH_RR!A6="","",IF(PBH_RR!E6="Both(FH+FC)",PBH_RR!P6,IF(OR(PBH_RR!E6="FH Matrix",PBH_RR!E6="FC Matrix"),INDEX(PBH_Lines!O:O,MATCH(PBH_RR!A6,PBH_Lines!M:M,0)),INDEX(SF_Data!U:U,MATCH(PBH_RR!D6,SF_Data!B:B,0))))) | J6: =IF(A6="","",A6) | K6: =IF(B6="","",B6) | L6: =IF(C6="","",C6) | M6: =IF(D6="","",D6) | N6: =IF(E6="","",E6) | O6: =IF(F6="","",F6) | P6: =IF(G6="","",G6) | Q6: =IF(H6=H5,"",H6)
A7: =IF(PBH_RR!A7="","",IF(OR(PBH_RR!E7="FH Matrix", PBH_RR!E7="FC Matrix"),PBH_RR!C7,INDEX(SF_Data!D:D, MATCH(PBH_RR!D7, SF_Data!B:B, 0)))) | B7: =IF(PBH_RR!A7="","",IF(OR(PBH_RR!E7="FH Matrix",PBH_RR!E7="FC Matrix"),PBH_RR!G7,IF(INDEX(SF_Data!F:F,MATCH(PBH_RR!D7,SF_Data!B:B,0))="Greater(FH/FC)",IF(INDEX(SF_Data!M:M,MATCH(PBH_RR!D7,SF_Data!B:B,0))="FH",INDEX(SF_Data!Q:Q,MATCH(PBH_RR!D7,SF_Data!B:B,0)),""),IF(PBH_RR!E7="Both(FH+FC)",IF(PBH_RR!L7="FH",PBH_RR!G7,""),INDEX(SF_Data!Q:Q,MATCH(PBH_RR!D7,SF_Data!B:B,0)))))) | C7: =IF(PBH_RR!A7="","",IF(OR(PBH_RR!E7="FH Matrix",PBH_RR!E7="FC Matrix"),PBH_RR!H7,IF(INDEX(SF_Data!F:F,MATCH(PBH_RR!D7,SF_Data!B:B,0))="Greater(FH/FC)",IF(INDEX(SF_Data!M:M,MATCH(PBH_RR!D7,SF_Data!B:B,0))="FC",INDEX(SF_Data!R:R,MATCH(PBH_RR!D7,SF_Data!B:B,0)),""),IF(PBH_RR!E7="Both(FH+FC)",IF(PBH_RR!L7="FC",PBH_RR!H7,""),INDEX(SF_Data!R:R,MATCH(PBH_RR!D7,SF_Data!B:B,0)))))) | D7: =IF(PBH_RR!A7="","",IF(OR(PBH_RR!E7="Hourly",PBH_RR!E7="Cycle"),IF(INDEX(SF_Data!M:M,MATCH(PBH_RR!D7,SF_Data!B:B,0))="FH",INDEX(SF_Data!G:G,MATCH(PBH_RR!D7,SF_Data!B:B,0)),""),IF(PBH_RR!E7="Both(FH+FC)",IF(PBH_RR!L7="FH",PBH_RR!M7-PBH_RR!G7,""),IF(PBH_RR!E7="Greater(FH/FC)",IF(INDEX(SF_Data!M:M,MATCH(PBH_RR!D7,SF_Data!B:B,0))="FH",INDEX(SF_Data!G:G,MATCH(PBH_RR!D7,SF_Data!B:B,0))-INDEX(SF_Data!Q:Q,MATCH(PBH_RR!D7,SF_Data!B:B,0)),""),IF(INDEX(SF_Data!M:M,MATCH(PBH_RR!D7,SF_Data!B:B,0))="FH",INDEX(PBH_Lines!K:K,MATCH(PBH_RR!A7,PBH_Lines!M:M,0)),""))))) | E7: =IF(PBH_RR!A7="","",IF(OR(PBH_RR!E7="Hourly",PBH_RR!E7="Cycle"),IF(INDEX(SF_Data!M:M,MATCH(PBH_RR!D7,SF_Data!B:B,0))="FC",INDEX(SF_Data!G:G,MATCH(PBH_RR!D7,SF_Data!B:B,0)),""),IF(PBH_RR!E7="Both(FH+FC)",IF(PBH_RR!L7="FC",PBH_RR!M7-PBH_RR!H7,""),IF(PBH_RR!E7="Greater(FH/FC)",IF(INDEX(SF_Data!M:M,MATCH(PBH_RR!D7,SF_Data!B:B,0))="FC",INDEX(SF_Data!G:G,MATCH(PBH_RR!D7,SF_Data!B:B,0))-INDEX(SF_Data!R:R,MATCH(PBH_RR!D7,SF_Data!B:B,0)),""),IF(INDEX(SF_Data!M:M,MATCH(PBH_RR!D7,SF_Data!B:B,0))="FC",INDEX(PBH_Lines!K:K,MATCH(PBH_RR!A7,PBH_Lines!M:M,0)),""))))) | F7: =IF(PBH_RR!A7="","",IF(OR(PBH_RR!E7="FH Matrix",PBH_RR!E7="FC Matrix"),PBH_RR!I7,IF(INDEX(SF_Data!F:F,MATCH(PBH_RR!D7,SF_Data!B:B,0))="Greater(FH/FC)",IF(INDEX(SF_Data!M:M,MATCH(PBH_RR!D7,SF_Data!B:B,0))="FH",INDEX(SF_Data!S:S,MATCH(PBH_RR!D7,SF_Data!B:B,0)),""),IF(PBH_RR!E7="Both(FH+FC)",IF(PBH_RR!L7="FH",PBH_RR!I7,""),INDEX(SF_Data!S:S,MATCH(PBH_RR!D7,SF_Data!B:B,0)))))) | G7: =IF(PBH_RR!A7="","",IF(OR(PBH_RR!E7="FH Matrix",PBH_RR!E7="FC Matrix"),PBH_RR!J7,IF(INDEX(SF_Data!F:F,MATCH(PBH_RR!D7,SF_Data!B:B,0))="Greater(FH/FC)",IF(INDEX(SF_Data!M:M,MATCH(PBH_RR!D7,SF_Data!B:B,0))="FC",INDEX(SF_Data!T:T,MATCH(PBH_RR!D7,SF_Data!B:B,0)),""),IF(PBH_RR!E7="Both(FH+FC)",IF(PBH_RR!L7="FC",PBH_RR!J7,""),INDEX(SF_Data!T:T,MATCH(PBH_RR!D7,SF_Data!B:B,0)))))) | H7: =IF(PBH_RR!A7="","",IF(PBH_RR!E7="Both(FH+FC)",PBH_RR!P7,IF(OR(PBH_RR!E7="FH Matrix",PBH_RR!E7="FC Matrix"),INDEX(PBH_Lines!O:O,MATCH(PBH_RR!A7,PBH_Lines!M:M,0)),INDEX(SF_Data!U:U,MATCH(PBH_RR!D7,SF_Data!B:B,0))))) | J7: =IF(A7="","",A7) | K7: =IF(B7="","",B7) | L7: =IF(C7="","",C7) | M7: =IF(D7="","",D7) | N7: =IF(E7="","",E7) | O7: =IF(F7="","",F7) | P7: =IF(G7="","",G7) | Q7: =IF(H7=H6,"",H7)
A8: =IF(PBH_RR!A8="","",IF(OR(PBH_RR!E8="FH Matrix", PBH_RR!E8="FC Matrix"),PBH_RR!C8,INDEX(SF_Data!D:D, MATCH(PBH_RR!D8, SF_Data!B:B, 0)))) | B8: =IF(PBH_RR!A8="","",IF(OR(PBH_RR!E8="FH Matrix",PBH_RR!E8="FC Matrix"),PBH_RR!G8,IF(INDEX(SF_Data!F:F,MATCH(PBH_RR!D8,SF_Data!B:B,0))="Greater(FH/FC)",IF(INDEX(SF_Data!M:M,MATCH(PBH_RR!D8,SF_Data!B:B,0))="FH",INDEX(SF_Data!Q:Q,MATCH(PBH_RR!D8,SF_Data!B:B,0)),""),IF(PBH_RR!E8="Both(FH+FC)",IF(PBH_RR!L8="FH",PBH_RR!G8,""),INDEX(SF_Data!Q:Q,MATCH(PBH_RR!D8,SF_Data!B:B,0)))))) | C8: =IF(PBH_RR!A8="","",IF(OR(PBH_RR!E8="FH Matrix",PBH_RR!E8="FC Matrix"),PBH_RR!H8,IF(INDEX(SF_Data!F:F,MATCH(PBH_RR!D8,SF_Data!B:B,0))="Greater(FH/FC)",IF(INDEX(SF_Data!M:M,MATCH(PBH_RR!D8,SF_Data!B:B,0))="FC",INDEX(SF_Data!R:R,MATCH(PBH_RR!D8,SF_Data!B:B,0)),""),IF(PBH_RR!E8="Both(FH+FC)",IF(PBH_RR!L8="FC",PBH_RR!H8,""),INDEX(SF_Data!R:R,MATCH(PBH_RR!D8,SF_Data!B:B,0)))))) | D8: =IF(PBH_RR!A8="","",IF(OR(PBH_RR!E8="Hourly",PBH_RR!E8="Cycle"),IF(INDEX(SF_Data!M:M,MATCH(PBH_RR!D8,SF_Data!B:B,0))="FH",INDEX(SF_Data!G:G,MATCH(PBH_RR!D8,SF_Data!B:B,0)),""),IF(PBH_RR!E8="Both(FH+FC)",IF(PBH_RR!L8="FH",PBH_RR!M8-PBH_RR!G8,""),IF(PBH_RR!E8="Greater(FH/FC)",IF(INDEX(SF_Data!M:M,MATCH(PBH_RR!D8,SF_Data!B:B,0))="FH",INDEX(SF_Data!G:G,MATCH(PBH_RR!D8,SF_Data!B:B,0))-INDEX(SF_Data!Q:Q,MATCH(PBH_RR!D8,SF_Data!B:B,0)),""),IF(INDEX(SF_Data!M:M,MATCH(PBH_RR!D8,SF_Data!B:B,0))="FH",INDEX(PBH_Lines!K:K,MATCH(PBH_RR!A8,PBH_Lines!M:M,0)),""))))) | E8: =IF(PBH_RR!A8="","",IF(OR(PBH_RR!E8="Hourly",PBH_RR!E8="Cycle"),IF(INDEX(SF_Data!M:M,MATCH(PBH_RR!D8,SF_Data!B:B,0))="FC",INDEX(SF_Data!G:G,MATCH(PBH_RR!D8,SF_Data!B:B,0)),""),IF(PBH_RR!E8="Both(FH+FC)",IF(PBH_RR!L8="FC",PBH_RR!M8-PBH_RR!H8,""),IF(PBH_RR!E8="Greater(FH/FC)",IF(INDEX(SF_Data!M:M,MATCH(PBH_RR!D8,SF_Data!B:B,0))="FC",INDEX(SF_Data!G:G,MATCH(PBH_RR!D8,SF_Data!B:B,0))-INDEX(SF_Data!R:R,MATCH(PBH_RR!D8,SF_Data!B:B,0)),""),IF(INDEX(SF_Data!M:M,MATCH(PBH_RR!D8,SF_Data!B:B,0))="FC",INDEX(PBH_Lines!K:K,MATCH(PBH_RR!A8,PBH_Lines!M:M,0)),""))))) | F8: =IF(PBH_RR!A8="","",IF(OR(PBH_RR!E8="FH Matrix",PBH_RR!E8="FC Matrix"),PBH_RR!I8,IF(INDEX(SF_Data!F:F,MATCH(PBH_RR!D8,SF_Data!B:B,0))="Greater(FH/FC)",IF(INDEX(SF_Data!M:M,MATCH(PBH_RR!D8,SF_Data!B:B,0))="FH",INDEX(SF_Data!S:S,MATCH(PBH_RR!D8,SF_Data!B:B,0)),""),IF(PBH_RR!E8="Both(FH+FC)",IF(PBH_RR!L8="FH",PBH_RR!I8,""),INDEX(SF_Data!S:S,MATCH(PBH_RR!D8,SF_Data!B:B,0)))))) | G8: =IF(PBH_RR!A8="","",IF(OR(PBH_RR!E8="FH Matrix",PBH_RR!E8="FC Matrix"),PBH_RR!J8,IF(INDEX(SF_Data!F:F,MATCH(PBH_RR!D8,SF_Data!B:B,0))="Greater(FH/FC)",IF(INDEX(SF_Data!M:M,MATCH(PBH_RR!D8,SF_Data!B:B,0))="FC",INDEX(SF_Data!T:T,MATCH(PBH_RR!D8,SF_Data!B:B,0)),""),IF(PBH_RR!E8="Both(FH+FC)",IF(PBH_RR!L8="FC",PBH_RR!J8,""),INDEX(SF_Data!T:T,MATCH(PBH_RR!D8,SF_Data!B:B,0)))))) | H8: =IF(PBH_RR!A8="","",IF(PBH_RR!E8="Both(FH+FC)",PBH_RR!P8,IF(OR(PBH_RR!E8="FH Matrix",PBH_RR!E8="FC Matrix"),INDEX(PBH_Lines!O:O,MATCH(PBH_RR!A8,PBH_Lines!M:M,0)),INDEX(SF_Data!U:U,MATCH(PBH_RR!D8,SF_Data!B:B,0))))) | J8: =IF(A8="","",A8) | K8: =IF(B8="","",B8) | L8: =IF(C8="","",C8) | M8: =IF(D8="","",D8) | N8: =IF(E8="","",E8) | O8: =IF(F8="","",F8) | P8: =IF(G8="","",G8) | Q8: =IF(H8=H7,"",H8)
A9: =IF(PBH_RR!A9="","",IF(OR(PBH_RR!E9="FH Matrix", PBH_RR!E9="FC Matrix"),PBH_RR!C9,INDEX(SF_Data!D:D, MATCH(PBH_RR!D9, SF_Data!B:B, 0)))) | B9: =IF(PBH_RR!A9="","",IF(OR(PBH_RR!E9="FH Matrix",PBH_RR!E9="FC Matrix"),PBH_RR!G9,IF(INDEX(SF_Data!F:F,MATCH(PBH_RR!D9,SF_Data!B:B,0))="Greater(FH/FC)",IF(INDEX(SF_Data!M:M,MATCH(PBH_RR!D9,SF_Data!B:B,0))="FH",INDEX(SF_Data!Q:Q,MATCH(PBH_RR!D9,SF_Data!B:B,0)),""),IF(PBH_RR!E9="Both(FH+FC)",IF(PBH_RR!L9="FH",PBH_RR!G9,""),INDEX(SF_Data!Q:Q,MATCH(PBH_RR!D9,SF_Data!B:B,0)))))) | C9: =IF(PBH_RR!A9="","",IF(OR(PBH_RR!E9="FH Matrix",PBH_RR!E9="FC Matrix"),PBH_RR!H9,IF(INDEX(SF_Data!F:F,MATCH(PBH_RR!D9,SF_Data!B:B,0))="Greater(FH/FC)",IF(INDEX(SF_Data!M:M,MATCH(PBH_RR!D9,SF_Data!B:B,0))="FC",INDEX(SF_Data!R:R,MATCH(PBH_RR!D9,SF_Data!B:B,0)),""),IF(PBH_RR!E9="Both(FH+FC)",IF(PBH_RR!L9="FC",PBH_RR!H9,""),INDEX(SF_Data!R:R,MATCH(PBH_RR!D9,SF_Data!B:B,0)))))) | D9: =IF(PBH_RR!A9="","",IF(OR(PBH_RR!E9="Hourly",PBH_RR!E9="Cycle"),IF(INDEX(SF_Data!M:M,MATCH(PBH_RR!D9,SF_Data!B:B,0))="FH",INDEX(SF_Data!G:G,MATCH(PBH_RR!D9,SF_Data!B:B,0)),""),IF(PBH_RR!E9="Both(FH+FC)",IF(PBH_RR!L9="FH",PBH_RR!M9-PBH_RR!G9,""),IF(PBH_RR!E9="Greater(FH/FC)",IF(INDEX(SF_Data!M:M,MATCH(PBH_RR!D9,SF_Data!B:B,0))="FH",INDEX(SF_Data!G:G,MATCH(PBH_RR!D9,SF_Data!B:B,0))-INDEX(SF_Data!Q:Q,MATCH(PBH_RR!D9,SF_Data!B:B,0)),""),IF(INDEX(SF_Data!M:M,MATCH(PBH_RR!D9,SF_Data!B:B,0))="FH",INDEX(PBH_Lines!K:K,MATCH(PBH_RR!A9,PBH_Lines!M:M,0)),""))))) | E9: =IF(PBH_RR!A9="","",IF(OR(PBH_RR!E9="Hourly",PBH_RR!E9="Cycle"),IF(INDEX(SF_Data!M:M,MATCH(PBH_RR!D9,SF_Data!B:B,0))="FC",INDEX(SF_Data!G:G,MATCH(PBH_RR!D9,SF_Data!B:B,0)),""),IF(PBH_RR!E9="Both(FH+FC)",IF(PBH_RR!L9="FC",PBH_RR!M9-PBH_RR!H9,""),IF(PBH_RR!E9="Greater(FH/FC)",IF(INDEX(SF_Data!M:M,MATCH(PBH_RR!D9,SF_Data!B:B,0))="FC",INDEX(SF_Data!G:G,MATCH(PBH_RR!D9,SF_Data!B:B,0))-INDEX(SF_Data!R:R,MATCH(PBH_RR!D9,SF_Data!B:B,0)),""),IF(INDEX(SF_Data!M:M,MATCH(PBH_RR!D9,SF_Data!B:B,0))="FC",INDEX(PBH_Lines!K:K,MATCH(PBH_RR!A9,PBH_Lines!M:M,0)),""))))) | F9: =IF(PBH_RR!A9="","",IF(OR(PBH_RR!E9="FH Matrix",PBH_RR!E9="FC Matrix"),PBH_RR!I9,IF(INDEX(SF_Data!F:F,MATCH(PBH_RR!D9,SF_Data!B:B,0))="Greater(FH/FC)",IF(INDEX(SF_Data!M:M,MATCH(PBH_RR!D9,SF_Data!B:B,0))="FH",INDEX(SF_Data!S:S,MATCH(PBH_RR!D9,SF_Data!B:B,0)),""),IF(PBH_RR!E9="Both(FH+FC)",IF(PBH_RR!L9="FH",PBH_RR!I9,""),INDEX(SF_Data!S:S,MATCH(PBH_RR!D9,SF_Data!B:B,0)))))) | G9: =IF(PBH_RR!A9="","",IF(OR(PBH_RR!E9="FH Matrix",PBH_RR!E9="FC Matrix"),PBH_RR!J9,IF(INDEX(SF_Data!F:F,MATCH(PBH_RR!D9,SF_Data!B:B,0))="Greater(FH/FC)",IF(INDEX(SF_Data!M:M,MATCH(PBH_RR!D9,SF_Data!B:B,0))="FC",INDEX(SF_Data!T:T,MATCH(PBH_RR!D9,SF_Data!B:B,0)),""),IF(PBH_RR!E9="Both(FH+FC)",IF(PBH_RR!L9="FC",PBH_RR!J9,""),INDEX(SF_Data!T:T,MATCH(PBH_RR!D9,SF_Data!B:B,0)))))) | H9: =IF(PBH_RR!A9="","",IF(PBH_RR!E9="Both(FH+FC)",PBH_RR!P9,IF(OR(PBH_RR!E9="FH Matrix",PBH_RR!E9="FC Matrix"),INDEX(PBH_Lines!O:O,MATCH(PBH_RR!A9,PBH_Lines!M:M,0)),INDEX(SF_Data!U:U,MATCH(PBH_RR!D9,SF_Data!B:B,0))))) | J9: =IF(A9="","",A9) | K9: =IF(B9="","",B9) | L9: =IF(C9="","",C9) | M9: =IF(D9="","",D9) | N9: =IF(E9="","",E9) | O9: =IF(F9="","",F9) | P9: =IF(G9="","",G9) | Q9: =IF(H9=H8,"",H9)
A10: =IF(PBH_RR!A10="","",IF(OR(PBH_RR!E10="FH Matrix", PBH_RR!E10="FC Matrix"),PBH_RR!C10,INDEX(SF_Data!D:D, MATCH(PBH_RR!D10, SF_Data!B:B, 0)))) | B10: =IF(PBH_RR!A10="","",IF(OR(PBH_RR!E10="FH Matrix",PBH_RR!E10="FC Matrix"),PBH_RR!G10,IF(INDEX(SF_Data!F:F,MATCH(PBH_RR!D10,SF_Data!B:B,0))="Greater(FH/FC)",IF(INDEX(SF_Data!M:M,MATCH(PBH_RR!D10,SF_Data!B:B,0))="FH",INDEX(SF_Data!Q:Q,MATCH(PBH_RR!D10,SF_Data!B:B,0)),""),IF(PBH_RR!E10="Both(FH+FC)",IF(PBH_RR!L10="FH",PBH_RR!G10,""),INDEX(SF_Data!Q:Q,MATCH(PBH_RR!D10,SF_Data!B:B,0)))))) | C10: =IF(PBH_RR!A10="","",IF(OR(PBH_RR!E10="FH Matrix",PBH_RR!E10="FC Matrix"),PBH_RR!H10,IF(INDEX(SF_Data!F:F,MATCH(PBH_RR!D10,SF_Data!B:B,0))="Greater(FH/FC)",IF(INDEX(SF_Data!M:M,MATCH(PBH_RR!D10,SF_Data!B:B,0))="FC",INDEX(SF_Data!R:R,MATCH(PBH_RR!D10,SF_Data!B:B,0)),""),IF(PBH_RR!E10="Both(FH+FC)",IF(PBH_RR!L10="FC",PBH_RR!H10,""),INDEX(SF_Data!R:R,MATCH(PBH_RR!D10,SF_Data!B:B,0)))))) | D10: =IF(PBH_RR!A10="","",IF(OR(PBH_RR!E10="Hourly",PBH_RR!E10="Cycle"),IF(INDEX(SF_Data!M:M,MATCH(PBH_RR!D10,SF_Data!B:B,0))="FH",INDEX(SF_Data!G:G,MATCH(PBH_RR!D10,SF_Data!B:B,0)),""),IF(PBH_RR!E10="Both(FH+FC)",IF(PBH_RR!L10="FH",PBH_RR!M10-PBH_RR!G10,""),IF(PBH_RR!E10="Greater(FH/FC)",IF(INDEX(SF_Data!M:M,MATCH(PBH_RR!D10,SF_Data!B:B,0))="FH",INDEX(SF_Data!G:G,MATCH(PBH_RR!D10,SF_Data!B:B,0))-INDEX(SF_Data!Q:Q,MATCH(PBH_RR!D10,SF_Data!B:B,0)),""),IF(INDEX(SF_Data!M:M,MATCH(PBH_RR!D10,SF_Data!B:B,0))="FH",INDEX(PBH_Lines!K:K,MATCH(PBH_RR!A10,PBH_Lines!M:M,0)),""))))) | E10: =IF(PBH_RR!A10="","",IF(OR(PBH_RR!E10="Hourly",PBH_RR!E10="Cycle"),IF(INDEX(SF_Data!M:M,MATCH(PBH_RR!D10,SF_Data!B:B,0))="FC",INDEX(SF_Data!G:G,MATCH(PBH_RR!D10,SF_Data!B:B,0)),""),IF(PBH_RR!E10="Both(FH+FC)",IF(PBH_RR!L10="FC",PBH_RR!M10-PBH_RR!H10,""),IF(PBH_RR!E10="Greater(FH/FC)",IF(INDEX(SF_Data!M:M,MATCH(PBH_RR!D10,SF_Data!B:B,0))="FC",INDEX(SF_Data!G:G,MATCH(PBH_RR!D10,SF_Data!B:B,0))-INDEX(SF_Data!R:R,MATCH(PBH_RR!D10,SF_Data!B:B,0)),""),IF(INDEX(SF_Data!M:M,MATCH(PBH_RR!D10,SF_Data!B:B,0))="FC",INDEX(PBH_Lines!K:K,MATCH(PBH_RR!A10,PBH_Lines!M:M,0)),""))))) | F10: =IF(PBH_RR!A10="","",IF(OR(PBH_RR!E10="FH Matrix",PBH_RR!E10="FC Matrix"),PBH_RR!I10,IF(INDEX(SF_Data!F:F,MATCH(PBH_RR!D10,SF_Data!B:B,0))="Greater(FH/FC)",IF(INDEX(SF_Data!M:M,MATCH(PBH_RR!D10,SF_Data!B:B,0))="FH",INDEX(SF_Data!S:S,MATCH(PBH_RR!D10,SF_Data!B:B,0)),""),IF(PBH_RR!E10="Both(FH+FC)",IF(PBH_RR!L10="FH",PBH_RR!I10,""),INDEX(SF_Data!S:S,MATCH(PBH_RR!D10,SF_Data!B:B,0)))))) | G10: =IF(PBH_RR!A10="","",IF(OR(PBH_RR!E10="FH Matrix",PBH_RR!E10="FC Matrix"),PBH_RR!J10,IF(INDEX(SF_Data!F:F,MATCH(PBH_RR!D10,SF_Data!B:B,0))="Greater(FH/FC)",IF(INDEX(SF_Data!M:M,MATCH(PBH_RR!D10,SF_Data!B:B,0))="FC",INDEX(SF_Data!T:T,MATCH(PBH_RR!D10,SF_Data!B:B,0)),""),IF(PBH_RR!E10="Both(FH+FC)",IF(PBH_RR!L10="FC",PBH_RR!J10,""),INDEX(SF_Data!T:T,MATCH(PBH_RR!D10,SF_Data!B:B,0)))))) | H10: =IF(PBH_RR!A10="","",IF(PBH_RR!E10="Both(FH+FC)",PBH_RR!P10,IF(OR(PBH_RR!E10="FH Matrix",PBH_RR!E10="FC Matrix"),INDEX(PBH_Lines!O:O,MATCH(PBH_RR!A10,PBH_Lines!M:M,0)),INDEX(SF_Data!U:U,MATCH(PBH_RR!D10,SF_Data!B:B,0))))) | J10: =IF(A10="","",A10) | K10: =IF(B10="","",B10) | L10: =IF(C10="","",C10) | M10: =IF(D10="","",D10) | N10: =IF(E10="","",E10) | O10: =IF(F10="","",F10) | P10: =IF(G10="","",G10) | Q10: =IF(H10=H9,"",H10)
A11: =IF(PBH_RR!A11="","",IF(OR(PBH_RR!E11="FH Matrix", PBH_RR!E11="FC Matrix"),PBH_RR!C11,INDEX(SF_Data!D:D, MATCH(PBH_RR!D11, SF_Data!B:B, 0)))) | B11: =IF(PBH_RR!A11="","",IF(OR(PBH_RR!E11="FH Matrix",PBH_RR!E11="FC Matrix"),PBH_RR!G11,IF(INDEX(SF_Data!F:F,MATCH(PBH_RR!D11,SF_Data!B:B,0))="Greater(FH/FC)",IF(INDEX(SF_Data!M:M,MATCH(PBH_RR!D11,SF_Data!B:B,0))="FH",INDEX(SF_Data!Q:Q,MATCH(PBH_RR!D11,SF_Data!B:B,0)),""),IF(PBH_RR!E11="Both(FH+FC)",IF(PBH_RR!L11="FH",PBH_RR!G11,""),INDEX(SF_Data!Q:Q,MATCH(PBH_RR!D11,SF_Data!B:B,0)))))) | C11: =IF(PBH_RR!A11="","",IF(OR(PBH_RR!E11="FH Matrix",PBH_RR!E11="FC Matrix"),PBH_RR!H11,IF(INDEX(SF_Data!F:F,MATCH(PBH_RR!D11,SF_Data!B:B,0))="Greater(FH/FC)",IF(INDEX(SF_Data!M:M,MATCH(PBH_RR!D11,SF_Data!B:B,0))="FC",INDEX(SF_Data!R:R,MATCH(PBH_RR!D11,SF_Data!B:B,0)),""),IF(PBH_RR!E11="Both(FH+FC)",IF(PBH_RR!L11="FC",PBH_RR!H11,""),INDEX(SF_Data!R:R,MATCH(PBH_RR!D11,SF_Data!B:B,0)))))) | D11: =IF(PBH_RR!A11="","",IF(OR(PBH_RR!E11="Hourly",PBH_RR!E11="Cycle"),IF(INDEX(SF_Data!M:M,MATCH(PBH_RR!D11,SF_Data!B:B,0))="FH",INDEX(SF_Data!G:G,MATCH(PBH_RR!D11,SF_Data!B:B,0)),""),IF(PBH_RR!E11="Both(FH+FC)",IF(PBH_RR!L11="FH",PBH_RR!M11-PBH_RR!G11,""),IF(PBH_RR!E11="Greater(FH/FC)",IF(INDEX(SF_Data!M:M,MATCH(PBH_RR!D11,SF_Data!B:B,0))="FH",INDEX(SF_Data!G:G,MATCH(PBH_RR!D11,SF_Data!B:B,0))-INDEX(SF_Data!Q:Q,MATCH(PBH_RR!D11,SF_Data!B:B,0)),""),IF(INDEX(SF_Data!M:M,MATCH(PBH_RR!D11,SF_Data!B:B,0))="FH",INDEX(PBH_Lines!K:K,MATCH(PBH_RR!A11,PBH_Lines!M:M,0)),""))))) | E11: =IF(PBH_RR!A11="","",IF(OR(PBH_RR!E11="Hourly",PBH_RR!E11="Cycle"),IF(INDEX(SF_Data!M:M,MATCH(PBH_RR!D11,SF_Data!B:B,0))="FC",INDEX(SF_Data!G:G,MATCH(PBH_RR!D11,SF_Data!B:B,0)),""),IF(PBH_RR!E11="Both(FH+FC)",IF(PBH_RR!L11="FC",PBH_RR!M11-PBH_RR!H11,""),IF(PBH_RR!E11="Greater(FH/FC)",IF(INDEX(SF_Data!M:M,MATCH(PBH_RR!D11,SF_Data!B:B,0))="FC",INDEX(SF_Data!G:G,MATCH(PBH_RR!D11,SF_Data!B:B,0))-INDEX(SF_Data!R:R,MATCH(PBH_RR!D11,SF_Data!B:B,0)),""),IF(INDEX(SF_Data!M:M,MATCH(PBH_RR!D11,SF_Data!B:B,0))="FC",INDEX(PBH_Lines!K:K,MATCH(PBH_RR!A11,PBH_Lines!M:M,0)),""))))) | F11: =IF(PBH_RR!A11="","",IF(OR(PBH_RR!E11="FH Matrix",PBH_RR!E11="FC Matrix"),PBH_RR!I11,IF(INDEX(SF_Data!F:F,MATCH(PBH_RR!D11,SF_Data!B:B,0))="Greater(FH/FC)",IF(INDEX(SF_Data!M:M,MATCH(PBH_RR!D11,SF_Data!B:B,0))="FH",INDEX(SF_Data!S:S,MATCH(PBH_RR!D11,SF_Data!B:B,0)),""),IF(PBH_RR!E11="Both(FH+FC)",IF(PBH_RR!L11="FH",PBH_RR!I11,""),INDEX(SF_Data!S:S,MATCH(PBH_RR!D11,SF_Data!B:B,0)))))) | G11: =IF(PBH_RR!A11="","",IF(OR(PBH_RR!E11="FH Matrix",PBH_RR!E11="FC Matrix"),PBH_RR!J11,IF(INDEX(SF_Data!F:F,MATCH(PBH_RR!D11,SF_Data!B:B,0))="Greater(FH/FC)",IF(INDEX(SF_Data!M:M,MATCH(PBH_RR!D11,SF_Data!B:B,0))="FC",INDEX(SF_Data!T:T,MATCH(PBH_RR!D11,SF_Data!B:B,0)),""),IF(PBH_RR!E11="Both(FH+FC)",IF(PBH_RR!L11="FC",PBH_RR!J11,""),INDEX(SF_Data!T:T,MATCH(PBH_RR!D11,SF_Data!B:B,0)))))) | H11: =IF(PBH_RR!A11="","",IF(PBH_RR!E11="Both(FH+FC)",PBH_RR!P11,IF(OR(PBH_RR!E11="FH Matrix",PBH_RR!E11="FC Matrix"),INDEX(PBH_Lines!O:O,MATCH(PBH_RR!A11,PBH_Lines!M:M,0)),INDEX(SF_Data!U:U,MATCH(PBH_RR!D11,SF_Data!B:B,0))))) | J11: =IF(A11="","",A11) | K11: =IF(B11="","",B11) | L11: =IF(C11="","",C11) | M11: =IF(D11="","",D11) | N11: =IF(E11="","",E11) | O11: =IF(F11="","",F11) | P11: =IF(G11="","",G11) | Q11: =IF(H11=H10,"",H11)
A12: =IF(PBH_RR!A12="","",IF(OR(PBH_RR!E12="FH Matrix", PBH_RR!E12="FC Matrix"),PBH_RR!C12,INDEX(SF_Data!D:D, MATCH(PBH_RR!D12, SF_Data!B:B, 0)))) | B12: =IF(PBH_RR!A12="","",IF(OR(PBH_RR!E12="FH Matrix",PBH_RR!E12="FC Matrix"),PBH_RR!G12,IF(INDEX(SF_Data!F:F,MATCH(PBH_RR!D12,SF_Data!B:B,0))="Greater(FH/FC)",IF(INDEX(SF_Data!M:M,MATCH(PBH_RR!D12,SF_Data!B:B,0))="FH",INDEX(SF_Data!Q:Q,MATCH(PBH_RR!D12,SF_Data!B:B,0)),""),IF(PBH_RR!E12="Both(FH+FC)",IF(PBH_RR!L12="FH",PBH_RR!G12,""),INDEX(SF_Data!Q:Q,MATCH(PBH_RR!D12,SF_Data!B:B,0)))))) | C12: =IF(PBH_RR!A12="","",IF(OR(PBH_RR!E12="FH Matrix",PBH_RR!E12="FC Matrix"),PBH_RR!H12,IF(INDEX(SF_Data!F:F,MATCH(PBH_RR!D12,SF_Data!B:B,0))="Greater(FH/FC)",IF(INDEX(SF_Data!M:M,MATCH(PBH_RR!D12,SF_Data!B:B,0))="FC",INDEX(SF_Data!R:R,MATCH(PBH_RR!D12,SF_Data!B:B,0)),""),IF(PBH_RR!E12="Both(FH+FC)",IF(PBH_RR!L12="FC",PBH_RR!H12,""),INDEX(SF_Data!R:R,MATCH(PBH_RR!D12,SF_Data!B:B,0)))))) | D12: =IF(PBH_RR!A12="","",IF(OR(PBH_RR!E12="Hourly",PBH_RR!E12="Cycle"),IF(INDEX(SF_Data!M:M,MATCH(PBH_RR!D12,SF_Data!B:B,0))="FH",INDEX(SF_Data!G:G,MATCH(PBH_RR!D12,SF_Data!B:B,0)),""),IF(PBH_RR!E12="Both(FH+FC)",IF(PBH_RR!L12="FH",PBH_RR!M12-PBH_RR!G12,""),IF(PBH_RR!E12="Greater(FH/FC)",IF(INDEX(SF_Data!M:M,MATCH(PBH_RR!D12,SF_Data!B:B,0))="FH",INDEX(SF_Data!G:G,MATCH(PBH_RR!D12,SF_Data!B:B,0))-INDEX(SF_Data!Q:Q,MATCH(PBH_RR!D12,SF_Data!B:B,0)),""),IF(INDEX(SF_Data!M:M,MATCH(PBH_RR!D12,SF_Data!B:B,0))="FH",INDEX(PBH_Lines!K:K,MATCH(PBH_RR!A12,PBH_Lines!M:M,0)),""))))) | E12: =IF(PBH_RR!A12="","",IF(OR(PBH_RR!E12="Hourly",PBH_RR!E12="Cycle"),IF(INDEX(SF_Data!M:M,MATCH(PBH_RR!D12,SF_Data!B:B,0))="FC",INDEX(SF_Data!G:G,MATCH(PBH_RR!D12,SF_Data!B:B,0)),""),IF(PBH_RR!E12="Both(FH+FC)",IF(PBH_RR!L12="FC",PBH_RR!M12-PBH_RR!H12,""),IF(PBH_RR!E12="Greater(FH/FC)",IF(INDEX(SF_Data!M:M,MATCH(PBH_RR!D12,SF_Data!B:B,0))="FC",INDEX(SF_Data!G:G,MATCH(PBH_RR!D12,SF_Data!B:B,0))-INDEX(SF_Data!R:R,MATCH(PBH_RR!D12,SF_Data!B:B,0)),""),IF(INDEX(SF_Data!M:M,MATCH(PBH_RR!D12,SF_Data!B:B,0))="FC",INDEX(PBH_Lines!K:K,MATCH(PBH_RR!A12,PBH_Lines!M:M,0)),""))))) | F12: =IF(PBH_RR!A12="","",IF(OR(PBH_RR!E12="FH Matrix",PBH_RR!E12="FC Matrix"),PBH_RR!I12,IF(INDEX(SF_Data!F:F,MATCH(PBH_RR!D12,SF_Data!B:B,0))="Greater(FH/FC)",IF(INDEX(SF_Data!M:M,MATCH(PBH_RR!D12,SF_Data!B:B,0))="FH",INDEX(SF_Data!S:S,MATCH(PBH_RR!D12,SF_Data!B:B,0)),""),IF(PBH_RR!E12="Both(FH+FC)",IF(PBH_RR!L12="FH",PBH_RR!I12,""),INDEX(SF_Data!S:S,MATCH(PBH_RR!D12,SF_Data!B:B,0)))))) | G12: =IF(PBH_RR!A12="","",IF(OR(PBH_RR!E12="FH Matrix",PBH_RR!E12="FC Matrix"),PBH_RR!J12,IF(INDEX(SF_Data!F:F,MATCH(PBH_RR!D12,SF_Data!B:B,0))="Greater(FH/FC)",IF(INDEX(SF_Data!M:M,MATCH(PBH_RR!D12,SF_Data!B:B,0))="FC",INDEX(SF_Data!T:T,MATCH(PBH_RR!D12,SF_Data!B:B,0)),""),IF(PBH_RR!E12="Both(FH+FC)",IF(PBH_RR!L12="FC",PBH_RR!J12,""),INDEX(SF_Data!T:T,MATCH(PBH_RR!D12,SF_Data!B:B,0)))))) | H12: =IF(PBH_RR!A12="","",IF(PBH_RR!E12="Both(FH+FC)",PBH_RR!P12,IF(OR(PBH_RR!E12="FH Matrix",PBH_RR!E12="FC Matrix"),INDEX(PBH_Lines!O:O,MATCH(PBH_RR!A12,PBH_Lines!M:M,0)),INDEX(SF_Data!U:U,MATCH(PBH_RR!D12,SF_Data!B:B,0))))) | J12: =IF(A12="","",A12) | K12: =IF(B12="","",B12) | L12: =IF(C12="","",C12) | M12: =IF(D12="","",D12) | N12: =IF(E12="","",E12) | O12: =IF(F12="","",F12) | P12: =IF(G12="","",G12) | Q12: =IF(H12=H11,"",H12)
